Workbook

Sheet 입력값
A1: 입력값 및 시나리오
A2: 기준시점 | B2: 45221
A3: 대상물건 기본정보 | E3: 수익방식 시나리오 가정
A4: 토지면적 (㎡) | B4: 2931.5 | E4: 보수(1) | F4: 기준(2) | G4: 낙관(3)
A5: 연면적 (㎡) | B5: 0 | D5: 월임대료 (원/㎡/월) | E5: 24000 | F5: 27000 | G5: 30000
A6: 임대가능면적 NRA (㎡) | B6: 0 | D6: 점유율 | E6: 0.88 | F6: 0.93 | G6: 0.97
A7: 건물 경과연수 (년) | B7: 0 | D7: 기타수입(연) (원) | E7: 12000000 | F7: 18000000 | G7: 24000000
A8: 경제적 내용연수 (년) | B8: 0 | D8: 운영경비율 | E8: 0.28 | F8: 0.24 | G8: 0.21
A9: 개별공시지가 (원/㎡) | B9: 66400 | D9: 임대료성장률 | E9: 0.01 | F9: 0.02 | G9: 0.03
A10: 건물 신축단가(재조달원가) (원/㎡) | B10: 1700000 | D10: 할인율 | E10: 0.09 | F10: 0.08 | G10: 0.07
A11: 간접공사비율 | B11: 0.1 | D11: 말기환원율 | E11: 0.065 | F11: 0.06 | G11: 0.055
A12: 기능적 감가율 | B12: 0.03 | D12: 직접환원율 | E12: 0.06 | F12: 0.055 | G12: 0.05
A13: 경제적 감가율 | B13: 0.05 | D13: 연간 자본적지출 Reserve (원) | E13: 18000000 | F13: 15000000 | G13: 12000000
A14: 수익방식 시나리오 가정 (1~3) | B14: 2
A15: 수익방식 내 직접환원 가중치 | B15: 0.5
A18: 활성 시나리오 값 (자동연결)
A19: 활성 월임대료 | B19: =IF($B$14=1,E5,IF($B$14=2,F5,G5)) -> 27000
A20: 활성 점유율 | B20: =IF($B$14=1,E6,IF($B$14=2,F6,G6)) -> 0.93
A21: 활성 기타수입(연) | B21: =IF($B$14=1,E7,IF($B$14=2,F7,G7)) -> 18000000
A22: 활성 운영경비율 | B22: =IF($B$14=1,E8,IF($B$14=2,F8,G8)) -> 0.24
A23: 활성 임대료성장률 | B23: =IF($B$14=1,E9,IF($B$14=2,F9,G9)) -> 0.02
A24: 활성 할인율 | B24: =IF($B$14=1,E10,IF($B$14=2,F10,G10)) -> 0.08
A25: 활성 말기환원율 | B25: =IF($B$14=1,E11,IF($B$14=2,F11,G11)) -> 0.06
A26: 활성 직접환원율 | B26: =IF($B$14=1,E12,IF($B$14=2,F12,G12)) -> 0.055
A27: 활성 연간 Reserve | B27: =IF($B$14=1,E13,IF($B$14=2,F13,G13)) -> 15000000
A29: ※ 노란색/파란색 셀은 입력값
A30: 원가방식 토지평가 입력값 (공시지가기준법 / 거래사례비교법 / 기타요인 배분법)
D31: KAPA HUB
A32: 비교표준지 공시지가 (원/㎡) | B32: =Q33 -> 61900 | D32: 선택 | E32: 공시 년도 | F32: 지역 코드 | G32: 일련 번호 | H32: 소재지 | I32: 지번 | J32: 지목 | K32: 면적 | L32: 일단구분 | M32: 이용상황 | N32: 이용상황기타 | O32: 용도지역1 | P32: 용도지역2 | Q32: 공시지가 | R32: 주위환경 | S32: 주위환경기타 | T32: 지리적위치1 | U32: 지리적위치2 | V32: 도로교통 | W32: 형상 | X32: 지세 | Y32: 방위 | Z32: 전년지가 | AA32: 2021년 | AB32: 2020년 | AC32: 2019년 | AD32: 2018년 | AE32: 계획시설 | AF32: 저촉률 | AG32: 기타제한1 | AH32: 기타제한2 | AI32: 용도지구 | AJ32: 용도지구2 | AK32: 임야구분 | AL32: 농지구분 | AM32: 유해철도 | AN32: 유해하수 | AO32: 경지정리 | AP32: 옥도구분 | AQ32: 호가 | AR32: 용도1 면적 | AS32: 용도1가격 | AT32: 용도2 면적 | AU32: 용도2가격 | AV32: 특수제한1 | AW32: 특수제한2 | AX32: 대규모 사업방식 | AY32: 대규모 사업단계 | AZ32: 기타제한 기타 | BA32: 기타제한 저촉률 | BB32: 기타제한 저촉률(제주) | BC32: A법인 | BD32: B법인 | BE32: 실거래 | BF32: 토지 등기 | BG32: 건물 등기 | BH32: 토지 대장 | BI32: 건축물 대장 | BJ32: 토지이용 계획 | BK32: 지적도 | BL32: 토이계
A33: 공시지가기준법 시점수정 | B33: =D39 -> 1.00686 | D33: Checked | E33: 2023 | F33: 36110 | G33: 719 | H33: 연동면 송용리 | I33: 1038- 5 | J33: 답 | K33: 2861.3 | L33: 0 | M33: 답 | O33: 농림지역 | P33: 없음 | Q33: 61900 | R33: 순수 경지정리지대 | T33: 송담마을 | U33: 남서측인근 | V33: 세로(가) | W33: 세장형 | X33: 평지 | Y33: 없음 | Z33: 67500 | AA33: 63000 | AB33: 58500 | AC33: 56000 | AD33: 53000 | AE33: 없음 | AG33: 기타 | AH33: 기타 | AK33: 없음 | AL33: 농업진흥구역 | AM33: 500ｍ이내 | AN33: 없음 | AO33: 경지정리 | AP33: 비옥 | AQ33: 0 | AX33: 없음 | AY33: 없음 | AZ33: 가축사육제한구역, 비행안전구역 | BA33: 0 | BB33: 0 | BC33: 이상훈(삼창충남) | BD33: 김용운(경일경기) | BE33: n | BF33: n | BG33: n | BH33: n | BI33: n | BJ33: n | BK33: n | BL33: y
A34: 공시지가기준법 지역요인비교치 | B34: 1 | D34: 시군구명 | E34: 용도지역 | F34: 지가변동률 | G34: 계산식 | I34: 비고
A35: 공시지가기준법 개별요인 - 가로조건 | B35: 1 | D35: 세종특별자치시
A36: 공시지가기준법 개별요인 - 접근조건 | B36: 1 | E36: 생산관리 | F36: 0.686 | G36: 2026-01-01 ~ 2026-02-28 : 0.427
A37: 공시지가기준법 개별요인 - 환경조건 | B37: 1.01 | D37: 2026-03-01 ~ 2026-04-01 : 0.258 | E37: ( 1 + 0.00427) *
A38: 공시지가기준법 개별요인 - 획지조건 | B38: 1 | D38: ( 1 + 0.00226 * 32/28)
A39: 공시지가기준법 개별요인 - 행정적조건 | B39: 1 | D39: 1.00686
A40: 공시지가기준법 개별요인 - 기타조건 | B40: 1.01
D41: KAPA HUB
A42: 그 밖의 요인 선례 총거래가액 (원) | B42: =N46 -> 458715000 | D42: Is Selected | E42: 평가목적 | F42: 복사 | G42: 연도 | H42: 물건 | I42: 소재지 | J42: 지번(*) | K42: 지번 | L42: 단가 | M42: 면적 | N42: 지목/ 건물용도 | O42: 용도지역 /구조 | P42: 평가액/면적 | Q42: 기준시점 | R42: 평가액 (개별) | S42: 감정평가총액 | T42: (개별) 공시연도 | U42: (개별) 공시지가 | V42: (개별) 지목 | W42: (개별) 이용상황 | X42: (개별) 용도지역 | Y42: (개별) 도로교통 | Z42: (개별) 형상 | AA42: (개별) 지세 | AB42: 등록구분 | AC42: 건명 | AD42: 감정서 | AE42: 감정서 쪽수 | AF42: 거래 사례 | AG42: 토지 등기 | AH42: 건물 등기 | AI42: 토지 대장 | AJ42: 건축물 대장 | AK42: 토지이용 계획 | AL42: 지적도 | AM42: 회원사 | AN42: 회원사명 | AO42: 비고
A43: 그 밖의 요인 선례 토지면적 (㎡) | B43: =M46 -> 2861.3 | D43: Checked | E43: 법원경매 | G43: 2023 | H43: 토지 | I43: 세종특별자치시 연동면 송용리 | J43: 960- 1* | K43: 960- 13 | L43: 250000 | M43: 5963.3 | N43: 답 | O43: 농림 | P43: 250000 | Q43: 45023 | R43: 1490825000 | S43: 1573240900 | T43: 2023 | U43: 63400 | V43: 답 | W43: 답 | X43: 농림 | Y43: 세각(가) | Z43: 세장형 | AA43: 평지 | AB43: 경매AUTO | AD43: y | AF43: y | AG43: n | AH43: n | AI43: y | AJ43: n | AK43: n | AL43: n | AM43: 400635 | AN43: 터***
...

Sheet 원가방식(개별물건기준)
A1: 원가방식 (토지: 공시지가기준법 + 거래사례비교법 / 건물: 원가법 / 최종합산)
A3: 기초정보 | O3: 가로: 폭·구조·포장·보도·계통·연속성
A4: 토지면적 (㎡) | B4: =입력값!B4 -> 2931.5 | D4: 연면적 (㎡) | E4: =입력값!B5 -> 0 | O4: 접근: 중심접근성·교통편의
O5: 환경: 상권/배후·주변환경·자연환경·공급처리시설·혐오시설·성숙도
A6: 토지가격 산정 ① 공시지가기준법 (가로형) | O6: 획지: 면적·형상·방위·고저·경사·접면상태·각지
A7: 비교표준지 공시지가 (원/㎡) | B7: 시점수정 | C7: 지역요인 비교치 | D7: 가로조건 | E7: 접근조건 | F7: 환경조건 | G7: 획지조건 | H7: 행정적조건 | I7: 기타조건 | J7: 개별요인 비교치 | K7: 그 밖의 요인 보정치 | L7: 산정단가 (원/㎡) | M7: 토지가액 (원) | N7: 비고 | O7: 행정: 용도지역·지구·구역·용적/고도·기타규제
A8: =입력값!B32 -> 61900 | B8: =입력값!B33 -> 1.00686 | C8: =입력값!B34 -> 1 | D8: =입력값!B35 -> 1 | E8: =입력값!B36 -> 1 | F8: =입력값!B37 -> 1.01 | G8: =입력값!B38 -> 1 | H8: =입력값!B39 -> 1 | I8: =입력값!B40 -> 1.01 | J8: =PRODUCT(D8:I8) -> 1.0201 | K8: =R12 -> 2.4876276 | L8: =A8*B8*C8*J8*K8 -> 158156.79 | M8: =$B$4*L8 -> 4.6363664e+08 | O8: 기타: 장래동향·특수사정
A10: 그 밖의 요인(기타요인보정치) 산정 - 배분법 포함
A11: 선례 총거래가액 (원) | B11: 배분후 건물가액 (원) | C11: 배분후 토지가액 (원) | D11: 토지면적 (㎡) | E11: 배분후 토지단가 (원/㎡) | F11: 시점수정 | G11: 지역요인 | H11: 가로 | I11: 접근 | J11: 환경 | K11: 획지 | L11: 행정 | M11: 기타 | N11: 개별요인 | O11: 선례기준 산정가격 | P11: 비교표준지 기준가격 | Q11: 격차율 | R11: 그 밖의 요인 보정치
A12: =입력값!B42 -> 458715000 | B12: =MIN(입력값!B44*(1-입력값!B45)*$E$4,A12) -> 0 | C12: =MAX(A12-B12,0) -> 458715000 | D12: =입력값!B43 -> 2861.3 | E12: =IFERROR(C12/D12,0) -> 160316.99 | F12: =입력값!B46 -> 1.00686 | G12: =입력값!B47 -> 1 | H12: =입력값!B48 -> 1 | I12: =입력값!B49 -> 0.99 | J12: =입력값!B50 -> 0.99 | K12: =입력값!B51 -> 0.98 | L12: =입력값!B52 -> 1 | M12: =입력값!B53 -> 1 | N12: =PRODUCT(H12:M12) -> 0.960498 | O12: =E12*F12*G12*N12 -> 155040.48 | P12: =A8*B8 -> 62324.634 | Q12: =IFERROR(O12/P12,0) -> 2.4876276 | R12: =Q12 -> 2.4876276
A13: 배분법 산식 | B13: 배분후 건물가액 = MIN(선례 건물 재조달원가 × (1-감가율), 총거래가액) | J13: 배분후 토지가액 = 총거래가액 - 배분후 건물가액 | O13: 기타요인보정치 = 선례기준 산정가격 ÷ 비교표준지 기준가격
A17: 토지가격 산정 ② 거래사례비교법 (사정보정 + 시점수정 + 지역요인 + 개별요인)
A18: 사례 | B18: 총거래가액 (원) | C18: 토지면적 (㎡) | D18: 거래단가 (원/㎡) | E18: 사정보정 | F18: 시점수정 | G18: 지역요인 | H18: 가로 | I18: 접근 | J18: 환경 | K18: 획지 | L18: 행정 | M18: 기타 | N18: 개별요인 비교치 | O18: 보정단가 (원/㎡) | P18: 가중치 | Q18: 가중단가
A19: 사례1 | B19: =입력값!B57 -> 5000000000 | C19: =입력값!B58 -> 331 | D19: =IFERROR(C21/C19,0) -> 14764684 | E19: =입력값!B61 -> 1 | F19: =입력값!B62 -> 1.00686 | G19: =입력값!B63 -> 1.01 | H19: =입력값!B64 -> 1 | I19: =입력값!B65 -> 1 | J19: =입력값!B66 -> 0.99 | K19: =입력값!B67 -> 1 | L19: =입력값!B68 -> 1 | M19: =입력값!B69 -> 1 | N19: =PRODUCT(H19:M19) -> 0.99 | O19: =D19*E19*F19*G19*N19 -> 14864483 | P19: =입력값!B70 -> 0.35 | Q19: =O19*P19 -> 5202569
B20: 배분후 건물가액 (원) | C20: 배분후 토지가액 (원)
B21: =MIN(입력값!B59*(1-입력값!B60),B19) -> 1.128897e+08 | C21: =MAX(B19-B21,0) -> 4887110300
A23: 사례2 | B23: =입력값!B72 -> 458715000 | C23: =입력값!B73 -> 2861.3 | D23: =IFERROR(B23/C23,0) -> 160316.99 | E23: =입력값!B76 -> 1 | F23: =입력값!B77 -> 1.00686 | G23: =입력값!B78 -> 1 | H23: =입력값!B79 -> 1 | I23: =입력값!B80 -> 1.01 | J23: =입력값!B81 -> 1.01 | K23: =입력값!B82 -> 1 | L23: =입력값!B83 -> 1 | M23: =입력값!B84 -> 1 | N23: =PRODUCT(H23:M23) -> 1.0201 | O23: =D23*E23*F23*G23*N23 -> 164661.24 | P23: =입력값!B85 -> 0.4 | Q23: =O23*P23 -> 65864.496
B24: 배분후 건물가액 (원) | C24: 배분후 토지가액 (원)
B25: =MIN(입력값!B74*(1-입력값!B75),B23) -> 458715000 | C25: =MAX(B23-B25,0) -> 0
A27: 사례3 | B27: =입력값!B87 -> 530000000 | C27: =입력값!B88 -> 3212.3 | D27: =IFERROR(B27/C27,0) -> 164990.82 | E27: =입력값!B91 -> 1 | F27: =입력값!B92 -> 1.00686 | G27: =입력값!B93 -> 0.98 | H27: =입력값!B94 -> 1.01 | I27: =입력값!B95 -> 1 | J27: =입력값!B96 -> 1 | K27: =입력값!B97 -> 1 | L27: =입력값!B98 -> 1 | M27: =입력값!B99 -> 1 | N27: =PRODUCT(H27:M27) -> 1.01 | O27: =D27*E27*F27*G27*N27 -> 164428.2 | P27: =입력값!B100 -> 0.25 | Q27: =O27*P27 -> 41107.051
B28: 배분후 건물가액 (원) | C28: 배분후 토지가액 (원)
B29: =MIN(입력값!B89*(1-입력값!B90),B27) -> 530000000 | C29: =MAX(B27-B29,0) -> 0
A31: 거래사례비교 토지단가 (원/㎡) | E31: =IFERROR(SUM(Q19:Q27)/SUM(P19:P27),0) -> 5309540.5 | G31: 거래사례비교 토지가액 (원) | K31: =$B$4*$E$31 -> 1.5564918e+10 | M31: 개별요인 비교치 = 가로 × 접근 × 환경 × 획지 × 행정 × 기타
A34: 토지가액 조정
A35: 공시지가기준법 가중치 | B35: =입력값!B54 -> 0.5 | D35: 공시지가기준법 토지가액 (원) | E35: =M8 -> 4.6363664e+08
A36: 거래사례비교법 가중치 | B36: =입력값!B55 -> 0.5 | D36: 거래사례비교법 토지가액 (원) | E36: =K31 -> 1.5564918e+10
A37: 토지 채택가액 (원) | B37: =IFERROR((M8*B35+K31*B36)/(B35+B36),0) -> 8.0142774e+09 | D37: 토지 채택가액 산식 | E37: '=(공시지가기준법 토지가액×가중치 + 거래사례비교 토지가액×가중치) ÷ 가중치 합계
A39: 건물가격 산정 (원가법)
A40: 연면적 (㎡) | B40: =입력값!B5 -> 0
A41: 건물 신축단가 (원/㎡) | B41: =입력값!B10 -> 1700000
A42: 간접공사비율 | B42: =입력값!B11 -> 0.1
A43: 건물 재조달원가 (원) | B43: =B40*B41*(1+B42) -> 0
A44: 경과연수 (년) | B44: =입력값!B7 -> 0
A45: 경제적 내용연수 (년) | B45: =입력값!B8 -> 0
A46: 물리적 감가율 | B46: =MIN(B44/B45,1) -> #DIV/0!
A47: 기능적 감가율 | B47: =입력값!B12 -> 0.03
A48: 경제적 감가율 | B48: =입력값!B13 -> 0.05
A49: 총감가율 | B49: =MIN(B46+B47+B48,0.95) -> #DIV/0!
A50: 감가후 건물가액 (원) | B50: =B43*(1-B49) -> #DIV/0!
A52: 최종가액 = 토지 채택가액 + 감가후 건물가액 | B52: =B37+B50 -> #DIV/0! | D52: 원가방식 최종 시산가액

Sheet 비교방식
A1: 비교방식 (토지+건물 일괄 거래사례 비교)
A3: 대상 연면적 (㎡) | B3: =입력값!B5 -> 0
A4: 산식 | B4: 보정단가 = 거래단가 × 시점보정 × 지역요인 × 개별요인 × 일체효용비교
A6: 사례 | B6: 총거래가액(원) | C6: 연면적(㎡) | D6: 거래단가(원/㎡) | E6: 사정보정 | F6: 시점보정 | G6: 지역요인 | H6: 개별요인 | I6: 일체효용비교 | J6: 보정단가(원/㎡) | K6: 시산가액(원) | L6: 가중치 | M6: 가중시산가액
A7: 사례1 | B7: 2450000000 | C7: 880 | D7: =IFERROR(B7/C7,0) -> 2784090.9 | E7: 1 | F7: 1.02 | G7: 1 | H7: 0.98 | I7: =I13 -> 0.97495312 | J7: =D7*E7*F7*G7*H7*I7 -> 2713272.4 | K7: =J7*$B$3 -> 0 | L7: 0.35 | M7: =K7*L7 -> 0
B9: 토지 | C9: 가로 | D9: 접근 | E9: 환경 | F9: 획지 | G9: 행정 | H9: 기타
B10: 0.48 | C10: 1 | D10: 1 | E10: 1.012 | F10: 1 | G10: 1 | H10: 1 | I10: =PRODUCT(C10:H10) -> 1.012
B11: 건물 | C11: 연식 | D11: 구조 | E11: 규모 | F11: 설비 | G11: 시공질 | H11: 주차장
B12: 0.52 | C12: 1 | D12: 1 | E12: 1 | F12: 1 | G12: 0.982 | H12: 0.958 | I12: =PRODUCT(C12:H12) -> 0.940756
B13: 합계 | I13: =B10*I10+B12*I12 -> 0.97495312
A14: 사례2 | B14: 2680000000 | C14: 930 | D14: =IFERROR(B14/C14,0) -> 2881720.4 | E14: 1 | F14: 1.01 | G14: 1.03 | H14: 1 | I14: 0.99 | J14: =D14*E14*F14*G14*H14*I14 -> 2967875.2 | K14: =J14*$B$3 -> 0 | L14: 0.4 | M14: =K14*L14 -> 0
B16: 토지 | C16: 가로 | D16: 접근 | E16: 환경 | F16: 획지 | G16: 행정 | H16: 기타
B17: 0.48 | C17: 1 | D17: 1 | E17: 1.012 | F17: 1 | G17: 1 | H17: 1 | I17: =PRODUCT(C17:H17) -> 1.012
B18: 건물 | C18: 연식 | D18: 구조 | E18: 규모 | F18: 설비 | G18: 시공질 | H18: 주차장
B19: 0.52 | C19: 1 | D19: 1 | E19: 1 | F19: 1 | G19: 0.982 | H19: 0.958 | I19: =PRODUCT(C19:H19) -> 0.940756
B20: 합계 | I20: =B17*I17+B19*I19 -> 0.97495312
A21: 사례3 | B21: 2310000000 | C21: 850 | D21: =IFERROR(B21/C21,0) -> 2717647.1 | E21: 1 | F21: 1.03 | G21: 0.97 | H21: 1.02 | I21: 1 | J21: =D21*E21*F21*G21*H21*I21 -> 2769505.2 | K21: =J21*$B$3 -> 0 | L21: 0.25 | M21: =K21*L21 -> 0
B23: 토지 | C23: 가로 | D23: 접근 | E23: 환경 | F23: 획지 | G23: 행정 | H23: 기타
B24: 0.48 | C24: 1 | D24: 1 | E24: 1.012 | F24: 1 | G24: 1 | H24: 1 | I24: =PRODUCT(C24:H24) -> 1.012
B25: 건물 | C25: 연식 | D25: 구조 | E25: 규모 | F25: 설비 | G25: 시공질 | H25: 주차장
B26: 0.52 | C26: 1 | D26: 1 | E26: 1 | F26: 1 | G26: 0.982 | H26: 0.958 | I26: =PRODUCT(C26:H26) -> 0.940756
B27: 합계 | I27: =B24*I24+B26*I26 -> 0.97495312
A29: 비교방식 최종 시산가액 | K29: =IFERROR(SUM(M7:M21)/SUM(L7:L21),0) -> 0
A30: 가중치 합계 체크 | B30: =SUM(L7:L21) -> 1

Sheet 수익방식
A1: 수익방식 (직접환원법 + 5개년 DCF)
D3: 직접환원법
A4: 임대가능면적 NRA (㎡) | B4: =입력값!B6 -> 0 | D4: 잠재총소득 PGI (원) | E4: =B4*B5*12+B7 -> 18000000
A5: 활성 월임대료 (원/㎡/월) | B5: =입력값!B19 -> 27000 | D5: 유효총소득 EGI (원) | E5: =E4*B6 -> 16740000
A6: 활성 점유율 | B6: =입력값!B20 -> 0.93 | D6: 운영경비 (원) | E6: =E5*B8 -> 4017600
A7: 활성 기타수입(연) (원) | B7: =입력값!B21 -> 18000000 | D7: Reserve (원) | E7: =B13 -> 15000000
A8: 활성 운영경비율 | B8: =입력값!B22 -> 0.24 | D8: NOI (원) | E8: =E5-E6-E7 -> -2277600
A9: 활성 임대료성장률 | B9: =입력값!B23 -> 0.02 | D9: 직접환원가액 (원) | E9: =IFERROR(E8/B12,0) -> -41410909
A10: 활성 할인율 | B10: =입력값!B24 -> 0.08
A11: 활성 말기환원율 | B11: =입력값!B25 -> 0.06
A12: 활성 직접환원율 | B12: =입력값!B26 -> 0.055
A13: 활성 연간 Reserve (원) | B13: =입력값!B27 -> 15000000
A14: 수익방식 내 직접환원 가중치 | B14: =입력값!B15 -> 0.5
A17: 5개년 DCF
C18: Year 1 | D18: Year 2 | E18: Year 3 | F18: Year 4 | G18: Year 5 | H18: Year 6
A19: 잠재총소득 PGI | C19: =($B$4*$B$5*12+$B$7) -> 18000000 | D19: =C19*(1+$B$9) -> 18360000 | E19: =D19*(1+$B$9) -> 18727200 | F19: =E19*(1+$B$9) -> 19101744 | G19: =F19*(1+$B$9) -> 19483779 | H19: =G19*(1+$B$9) -> 19873454
A20: 점유율 | C20: =$B$6 -> 0.93 | D20: =$B$6 -> 0.93 | E20: =$B$6 -> 0.93 | F20: =$B$6 -> 0.93 | G20: =$B$6 -> 0.93 | H20: =$B$6 -> 0.93
A21: 유효총소득 EGI | C21: =C19*C20 -> 16740000 | D21: =D19*D20 -> 17074800 | E21: =E19*E20 -> 17416296 | F21: =F19*F20 -> 17764622 | G21: =G19*G20 -> 18119914 | H21: =H19*H20 -> 18482313
A22: 운영경비율 | C22: =$B$8 -> 0.24 | D22: =$B$8 -> 0.24 | E22: =$B$8 -> 0.24 | F22: =$B$8 -> 0.24 | G22: =$B$8 -> 0.24 | H22: =$B$8 -> 0.24
A23: 운영경비 | C23: =C21*C22 -> 4017600 | D23: =D21*D22 -> 4097952 | E23: =E21*E22 -> 4179911 | F23: =F21*F22 -> 4263509.3 | G23: =G21*G22 -> 4348779.4 | H23: =H21*H22 -> 4435755
A24: Reserve | C24: =$B$13 -> 15000000 | D24: =$B$13 -> 15000000 | E24: =$B$13 -> 15000000 | F24: =$B$13 -> 15000000 | G24: =$B$13 -> 15000000 | H24: =$B$13 -> 15000000
A25: NOI | C25: =C21-C23-C24 -> -2277600 | D25: =D21-D23-D24 -> -2023152 | E25: =E21-E23-E24 -> -1763615 | F25: =F21-F23-F24 -> -1498887.3 | G25: =G21-G23-G24 -> -1228865.1 | H25: =H21-H23-H24 -> -953442.39
A26: 할인계수 | C26: =1/(1+$B$10)^1 -> 0.92592593 | D26: =1/(1+$B$10)^2 -> 0.85733882 | E26: =1/(1+$B$10)^3 -> 0.79383224 | F26: =1/(1+$B$10)^4 -> 0.73502985 | G26: =1/(1+$B$10)^5 -> 0.6805832
A27: NOI 현재가치 | C27: =C25*C26 -> -2108888.9 | D27: =D25*D26 -> -1734526.7 | E27: =E25*E26 -> -1400014.5 | F27: =F25*F26 -> -1101726.9 | G27: =G25*G26 -> -836344.93
A28: 말기복귀가치 | G28: =IFERROR(H25/$B$11,0) -> -15890706
A29: 복귀가치 현재가치 | G29: =G28*G26 -> -10814948
A31: DCF 가치 (원) | B31: =SUM(C27:G27)+G29 -> -17996450
A32: 수익방식 최종 시산가액 | B32: =E9*B14+B31*(1-B14) -> -29703679

Sheet 시산가액조정
A1: 시산가액 조정 및 최종가액
A3: 방식 | B3: 시산가액(원) | C3: 가중치 | D3: 가중가액
A4: 비교방식 | B4: =비교방식!K29 -> 0 | C4: 0.4 | D4: =B4*C4 -> 0
A5: 원가방식 | B5: ='원가방식(개별물건기준)'!B52 -> #DIV/0! | C5: 0.2 | D5: =B5*C5 -> #DIV/0!
A6: 수익방식 | B6: =수익방식!B32 -> -29703679 | C6: 0.4 | D6: =B6*C6 -> -11881472
A8: 가중치 합계 | B8: =SUM(C4:C6) -> 1
A10: 최종 조정가액 | B10: =IFERROR(SUM(D4:D6)/SUM(C4:C6),0) -> 0
A12: 체크 | B12: =IF(ABS(B8-1)<0.0001,"가중치 정상","가중치 확인 필요") -> 가중치 정상
