Workbook
Name 연율: '01_설정'!$B$19

Sheet 00_사용설명서
A1: 집합건물 자동평가 엑셀 템플릿 (국토부 실거래가 → 자동선정 → 요인보정 → 건물/대지권 배분)
A3: 목적 | B3: 국토부 실거래가 자료를 복사/붙여넣기 하면 유사 거래사례를 자동으로 필터링하고, 개별요인 보정 후 집합건물의 총가치·대지권가격·건물가격을 산출하는 템플릿
A5: 사용 순서
A6: 1 | B6: 1) 01_설정 시트에서 기준시점·허용오차·대지권/건물 배분용 원가 가정을 확인합니다.
A7: 2 | B7: 2) 02_대상물건입력 시트에서 시군구/법정동/건물명/전유면적/대지권면적/층/사용승인일자 등을 입력합니다.
A8: 3 | B8: 3) 04A_국토부원자료 시트의 5행부터 국토부 실거래가 원문 데이터를 붙여넣습니다. 헤더는 4행의 고정 형식을 그대로 사용합니다.
A9: 4 | B9: 4) 04B_정규화_자동필터 시트에서 1차 필터 통과 여부와 유사도 순위를 자동 산정합니다.
A10: 5 | B10: 5) 05_자동선정_유사도 시트에서 상위 사례를 확인합니다.
A11: 6 | B11: 6) 06_요인비교_보정 시트에서 사정보정/기타요인 Override가 필요한 경우만 입력합니다. 나머지는 자동값을 사용합니다.
A12: 7 | B12: 7) 07_대지권_건물배분 시트에서 총가치, 대지권가격, 건물가격을 확인합니다.
A13: 8 | B13: 8) 08_평가결론 시트에서 보고용 요약값을 확인합니다.
A16: 붙여넣기 데이터 형식 (04A_국토부원자료 / 4행 헤더 고정)
A17: A:NO
A18: B:시군구
A19: C:번지
A20: D:본번
A21: E:부번
A22: F:단지명
A23: G:전용면적(㎡)
A24: H:계약년월
A25: I:계약일
A26: J:거래금액(만원)
A27: K:층
... A39: 실거래가 원문 헤더는 현재 템플릿의 4행 형식에 맞춰 고정되어 있으므로, 5행부터 값만 붙여넣으면 됩니다.

Sheet 01_설정
A1: 설정 및 통제변수
A3: 항목 | B3: 값 | C3: 설명
A4: 기준시점 | B4: 46112 | C4: 대상물건 평가 기준시점
A5: 면적 허용오차 | B5: 0.25 | C5: 전유면적 차율 허용범위
A6: 층 허용차이 | B6: 5 | C6: 층차 허용범위
A7: 최대 경과일수 | B7: 1095 | C7: 계약일~기준시점 허용일수
A8: 건축연차 허용차이 | B8: 10 | C8: 건축년도 차이 허용범위
A9: 상위 반영 건수 | B9: 10 | C9: 요인보정에 반영할 비교사례 수
A10: 동일 시군구 필수 | B10: 0 | C10: 1이면 대상 시군구 키워드 포함 사례만 반영
A11: 동일 법정동 가점 | B11: 15 | C11: 법정동 일치 시 가점
A12: 동일건물 가점 | B12: 15 | C12: 건물명 유사 시 가점
A13: 동일도로명 가점 | B13: 8 | C13: 도로명 일치 시 가점
A14: 면적점수 가중치 | B14: 22 | C14: 유사도 배점
A15: 층점수 가중치 | B15: 12 | C15: 유사도 배점
... A30: 최대 토지비율 | B30: 0.8 | C30: 배분비율 상한

Sheet 02_대상물건입력
A1: 대상물건 입력
A3: 항목 | B3: 입력값 | C3: 설명 | D3: 비고
A4: 평가서명 | B4: 서울 송파구 가락동 99 아스티캐빈 1205호 감정평가 | C4: 입력
A5: 시군구 키워드 | B5: 서울특별시 송파구 | C5: 자동필터용 | D5: 예: 서울특별시 송파구
A6: 법정동 키워드 | B6: 가락동 | C6: 자동필터용 | D6: 예: 가락동
A7: 소재지 | B7: 서울특별시 송파구 가락동 99 | C7: 입력
A8: 건물명 | B8: 아스티캐빈 | C8: 입력
A9: 동·호 | B9: 제1동 1205호 | C9: 입력
A10: 층 | B10: 12 | C10: 입력
A11: 전유면적(㎡) | B11: 27.2428 | C11: 입력
A12: 공용면적(㎡) | B12: 17.3296 | C12: 입력
A13: 대지권면적(㎡) | B13: 4.2477 | C13: 입력
A14: 사용승인일자 | B14: 46049 | C14: 입력
A15: 도로명 키워드 | B15: 송파대로 | C15: 자동필터용 | D15: 도로명 일부 가능
A16: 용도 | B16: 오피스텔 | C16: 입력
A17: 기타요인 계수 | B17: 1 | C17: 입력 | D17: 특이사항 있을 때만 조정
A18: 비고 | B18: 예시 데이터가 입력되어 있습니다. 실제 대상물건으로 덮어쓰면 전체 시트가 연동됩니다. | C18: 입력
A21: 자동 계산
A22: 건축년도 | B22: =IFERROR(YEAR(B14),"") -> 2026 | C22: 자동
A23: 분양면적(㎡) | B23: =IFERROR(B11+B12,"") -> 44.5724 | C23: 자동
A24: 전유율 | B24: =IFERROR(B11/B23,"") -> 0.61120335 | C24: 자동
A25: 대지권 기준금액(원) | B25: =IFERROR(B13*'01_설정'!B26,"") -> 27610050 | C25: 토지단가 × 대지권면적
A26: 건물 기준금액(원) | B26: =IFERROR(B11*'01_설정'!B27*'01_설정'!B28,"") -> 57209880 | C26: 재조달원가 × 전유면적 × 잔존율
A27: 원가기준 토지비율 | B27: =IFERROR(MIN(MAX(B25/(B25+B26),'01_설정'!B29),'01_설정'!B30),"") -> 0.32551371 | C27: 배분비율
A28: 원가기준 건물비율 | B28: =IFERROR(1-B27,"") -> 0.67448629 | C28: 배분비율

Sheet 03_가치형성요인기준
A1: 가치형성요인 기준표
A3: 자동 보정 로직(기본 프록시)
A4: 구분 | B4: 기준 | C4: 자동값 | D4: 설명 | E4: 실무 Override
A5: 사정보정 | B5: 특이 거래 여부 | C5: ='01_설정'!B18 -> 1 | D5: 기본 1.00, 특이 거래면 06시트에서 직접 수정 | E5: 06시트 G열
A6: 시점수정 | B6: 기준시점 대비 계약일 경과 | C6: =(1+연율)^(경과일수/365) | D6: 기준시점 이후로 환산 | E6: 보통 자동 사용
A7: 외부요인 | B7: 법정동/도로명 일치 여부 | C7: 동일 법정동이면 1.00, 타동이면 0.98, 동일도로명이면 +1.01 | D7: 역세권/상권 차이는 수동 검토 권장 | E7: 06시트 J열
A8: 내부요인 | B8: 동일건물/건축연차 | C8: 동일건물 1.02, 건축연차 우열 1.01 또는 0.99 | D8: 브랜드/세대수/관리상태는 수동 검토 권장 | E8: 06시트 L열
A9: 호별요인 | B9: 층차 | C9: 층이 높으면 0.99~0.98, 낮으면 1.01~1.02 | D9: 향·조망은 필요 시 Override | E9: 06시트 N열
A10: 기타요인 | B10: 특이 개별요인 | C10: ='02_대상물건입력'!B17 -> 1 | D10: 특별한 권리관계/리모델링 등 | E10: 06시트 P열
A11: 대지권/건물 배분 | B11: 원가배분 방식 | C11: 토지기준금액 / (토지기준금액 + 건물기준금액) | D11: 비율 하한/상한 적용 | E11: 01/07시트

Sheet 04A_국토부원자료
A1: 국토부 실거래가 원자료 붙여넣기
A2: ※ 5행부터 값만 붙여넣으세요. 4행 헤더는 NO, 시군구, 번지, 본번, 부번, 단지명, 전용면적(㎡), 계약년월, 계약일, 거래금액(만원), 층, 매수자, 매도자, 건축년도, 도로명, 해제사유발생일, 거래유형, 중개사소재지 순서입니다.
A4: NO | B4: 시군구 | C4: 번지 | D4: 본번 | E4: 부번 | F4: 단지명 | G4: 전용면적(㎡) | H4: 계약년월 | I4: 계약일 | J4: 거래금액(만원) | K4: 층 | L4: 매수자 | M4: 매도자 | N4: 건축년도 | O4: 도로명 | P4: 해제사유발생일 | Q4: 거래유형 | R4: 중개사소재지
A5: 1 | B5: 서울특별시 송파구 가락동 | C5: 98-7 | D5: 0098 | E5: 0007 | F5: (98-7) | G5: 27.8400 | H5: 202603 | I5: 10 | J5: 10,500 | K5: 4 | L5: 개인 | M5: 개인 | N5: 1990 | O5: 송파대로28길 13 | P5: - | Q5: 중개거래 | R5: 서울 도봉구, 서울 송파구
A6: 2 | B6: 서울특별시 송파구 가락동 | C6: 98-7 | D6: 0098 | E6: 0007 | F6: (98-7) | G6: 27.8400 | H6: 202602 | I6: 20 | J6: 10,300 | K6: 4 | L6: 개인 | M6: 개인 | N6: 1990 | O6: 송파대로28길 13 | P6: - | Q6: 중개거래 | R6: 서울 도봉구, 서울 송파구
A7: 3 | B7: 서울특별시 송파구 가락동 | C7: 99-3 | D7: 0099 | E7: 0003 | F7: 제일오피스텔 | G7: 31.1400 | H7: 202602 | I7: 04 | J7: 20,800 | K7: 8 | L7: 법인 | M7: 개인 | N7: 1992 | O7: 송파대로 260 | P7: - | Q7: 중개거래 | R7: 서울 송파구
A8: 4 | B8: 서울특별시 송파구 가락동 | C8: 79-7 | D8: 0079 | E8: 0007 | F8: (79-7) | G8: 29.5200 | H8: 202601 | I8: 28 | J8: 12,500 | K8: 10 | L8: 개인 | M8: 개인 | N8: 1990 | O8: 송파대로28길 32 | P8: - | Q8: 중개거래 | R8: 서울 송파구
A9: 5 | B9: 서울특별시 송파구 가락동 | C9: 79-7 | D9: 0079 | E9: 0007 | F9: (79-7) | G9: 29.5200 | H9: 202601 | I9: 28 | J9: 13,000 | K9: 2 | L9: 개인 | M9: 개인 | N9: 1990 | O9: 송파대로28길 32 | P9: - | Q9: 직거래 | R9: -
A10: 6 | B10: 서울특별시 송파구 가락동 | C10: 79-7 | D10: 0079 | E10: 0007 | F10: (79-7) | G10: 29.5200 | H10: 202601 | I10: 28 | J10: 12,500 | K10: 10 | L10: 개인 | M10: 개인 | N10: 1990 | O10: 송파대로28길 32 | P10: - | Q10: 중개거래 | R10: 서울 송파구
A11: 7 | B11: 서울특별시 송파구 가락동 | C11: 171 | D11: 0171 | E11: 0000 | F11: 현진타워 | G11: 42.3200 | H11: 202601 | I11: 26 | J11: 32,000 | K11: 5 | L11: 개인 | M11: 개인 | N11: 2015 | O11: 오금로44가길 13 | P11: - | Q11: 중개거래 | R11: 서울 송파구
A12: 8 | B12: 서울특별시 송파구 가락동 | C12: 78-1 | D12: 0078 | E12: 0001 | F12: 한화오벨리스크 | G12: 30.3400 | H12: 202601 | I12: 26 | J12: 18,000 | K12: 11 | L12: 개인 | M12: 개인 | N12: 2004 | O12: 중대로 127 | P12: - | Q12: 중개거래 | R12: 서울 송파구
A13: 9 | B13: 서울특별시 송파구 가락동 | C13: 171 | D13: 0171 | E13: 0000 | F13: 현진타워 | G13: 42.1800 | H13: 202601 | I13: 24 | J13: 32,800 | K13: 5 | L13: 개인 | M13: 개인 | N13: 2015 | O13: 오금로44가길 13 | P13: - | Q13: 중개거래 | R13: 서울 송파구
A14: 10 | B14: 서울특별시 송파구 가락동 | C14: 98-7 | D14: 0098 | E14: 0007 | F14: (98-7) | G14: 35.2400 | H14: 202601 | I14: 22 | J14: 15,900 | K14: 4 | L14: 개인 | M14: 법인 | N14: 1990 | O14: 송파대로28길 13 | P14: - | Q14: 중개거래 | R14: 서울 도봉구, 서울 송파구
A15: 11 | B15: 서울특별시 송파구 가락동 | C15: 78-1 | D15: 0078 | E15: 0001 | F15: 한화오벨리스크 | G15: 37.9300 | H15: 202601 | I15: 19 | J15: 22,000 | K15: 12 | L15: 개인 | M15: 개인 | N15: 2004 | O15: 중대로 127 | P15: - | Q15: 중개거래 | R15: 서울 송파구
A16: 12 | B16: 서울특별시 송파구 가락동 | C16: 99-3 | D16: 0099 | E16: 0003 | F16: 제일오피스텔 | G16: 31.1400 | H16: 202601 | I16: 17 | J16: 19,000 | K16: 14 | L16: 개인 | M16: 개인 | N16: 1992 | O16: 송파대로 260 | P16: - | Q16: 중개거래 | R16: 서울 송파구
... A98: 94 | B98: 서울특별시 송파구 가락동 | C98: 77-4 | D98: 0077 | E98: 0004 | F98: 송파KCC웰츠타워 | G98: 39.4900 | H98: 202503 | I98: 21 | J98: 21,500 | K98: 7 | L98: 개인 | M98: 개인 | N98: 2011 | O98: 송파대로28길 43 | P98: - | Q98: 중개거래 | R98: 서울 송파구
A101: □ 본 서비스에서 제공하는 정보는 법적인 효력이 없으므로 참고용으로만 활용하시기 바랍니다.
A102: □ 신고정보가 실시간 변경, 해제되어 제공시점에 따라 공개건수 및 내용이 상이할 수 있는 점 참고하시기 바랍니다.
A103: □ 본 자료는 계약일 기준입니다. (※ 7월 계약, 8월 신고건 → 7월 거래건으로 제공)
A104: □ 통계자료 활용시에는 수치가 왜곡될 수 있으니 참고자료로만 활용하시기 바라며, 외부 공개시에는 반드시 신고일 기준으로 집계되는 공식통계를 이용하여 주시기 바랍니다.
A106: * 국토교통부 실거래가 공개시스템의 궁금하신 점이나 문의사항은 콜센터 1533-2949로 연락 주시기 바랍니다.
A108: □ 검색조건
A109: 계약일자 : 2025-03-17 ~ 2026-03-16 | E109: 실거래 구분 : 오피스텔(매매) | J109: 주소구분 : 지번 주소
A110: 시도 : 서울특별시 | E110: 시군구 : 송파구 | J110: 읍면동 : 문정동
A111: 단지명 : 전체 | E111: 면적 : 60㎡이하 | J111: 금액선택 : 전체
A113: NO | B113: 시군구 | C113: 번지 | D113: 본번 | E113: 부번 | F113: 단지명 | G113: 전용면적(㎡) | H113: 계약년월 | I113: 계약일 | J113: 거래금액(만원) | K113: 층 | L113: 매수자 | M113: 매도자 | N113: 건축년도 | O113: 도로명 | P113: 해제사유발생일 | Q113: 거래유형 | R113: 중개사소재지
A114: 1 | B114: 서울특별시 송파구 문정동 | C114: 622 | D114: 0622 | E114: 0000 | F114: 송파한화오벨리스크 | G114: 26.8200 | H114: 202603 | I114: 11 | J114: 18,000 | K114: 10 | L114: 개인 | M114: 개인 | N114: 2013 | O114: 충민로 5 | P114: - | Q114: 중개거래 | R114: 서울 송파구
A115: 2 | B115: 서울특별시 송파구 문정동 | C115: 622 | D115: 0622 | E115: 0000 | F115: 송파한화오벨리스크 | G115: 29.9900 | H115: 202603 | I115: 11 | J115: 21,100 | K115: 9 | L115: 개인 | M115: 법인 | N115: 2013 | O115: 충민로 5 | P115: - | Q115: 중개거래 | R115: 서울 송파구
A116: 3 | B116: 서울특별시 송파구 문정동 | C116: 622 | D116: 0622 | E116: 0000 | F116: 송파한화오벨리스크 | G116: 26.8200 | H116: 202603 | I116: 11 | J116: 18,000 | K116: 10 | L116: 개인 | M116: 개인 | N116: 2013 | O116: 충민로 5 | P116: 20260311 | Q116: 중개거래 | R116: 서울 송파구
A117: 4 | B117: 서울특별시 송파구 문정동 | C117: 622 | D117: 0622 | E117: 0000 | F117: 송파한화오벨리스크 | G117: 29.9900 | H117: 202603 | I117: 10 | J117: 21,100 | K117: 9 | L117: 개인 | M117: 법인 | N117: 2013 | O117: 충민로 5 | P117: 20260311 | Q117: 중개거래 | R117: 서울 송파구
A118: 5 | B118: 서울특별시 송파구 문정동 | C118: 618 | D118: 0618 | E118: 0000 | F118: 파크하비오 | G118: 59.7400 | H118: 202603 | I118: 10 | J118: 69,500 | K118: 15 | L118: 법인 | M118: 개인 | O118: 송파대로 111 | P118: - | Q118: 중개거래 | R118: 서울 송파구
A119: 6 | B119: 서울특별시 송파구 문정동 | C119: 639-5 | D119: 0639 | E119: 0005 | F119: 힐스테이트에코송파 | G119: 21.0640 | H119: 202603 | I119: 09 | J119: 15,500 | K119: 3 | L119: 개인 | M119: 개인 | N119: 2017 | O119: 정의로7길 13 | P119: - | Q119: 중개거래 | R119: 서울 송파구
A120: 7 | B120: 서울특별시 송파구 문정동 | C120: 652-3 | D120: 0652 | E120: 0003 | F120: 르피에드 문정 | G120: 44.8066 | H120: 202603 | I120: 09 | J120: 95,000 | K120: 5 | L120: 개인 | M120: 개인 | N120: 2022 | O120: 송파대로 141 | P120: - | Q120: 직거래 | R120: -
A121: 8 | B121: 서울특별시 송파구 문정동 | C121: 622 | D121: 0622 | E121: 0000 | F121: 송파한화오벨리스크 | G121: 24.6600 | H121: 202603 | I121: 08 | J121: 18,900 | K121: 7 | L121: 개인 | M121: 개인 | N121: 2013 | O121: 충민로 5 | P121: - | Q121: 중개거래 | R121: 서울 송파구
A122: 9 | B122: 서울특별시 송파구 문정동 | C122: 622 | D122: 0622 | E122: 0000 | F122: 송파한화오벨리스크 | G122: 26.8200 | H122: 202603 | I122: 07 | J122: 18,000 | K122: 6 | L122: 개인 | M122: 개인 | N122: 2013 | O122: 충민로 5 | P122: - | Q122: 중개거래 | R122: 서울 송파구
A123: 10 | B123: 서울특별시 송파구 문정동 | C123: 652-5 | D123: 0652 | E123: 0005 | F123: 문정 아이파크 | G123: 25.7700 | H123: 202603 | I123: 07 | J123: 23,500 | K123: 10 | L123: 개인 | M123: 개인 | N123: 2017 | O123: 법원로4길 6 | P123: - | Q123: 중개거래 | R123: 서울 송파구
A124: 11 | B124: 서울특별시 송파구 문정동 | C124: 618 | D124: 0618 | E124: 0000 | F124: 파크하비오 | G124: 50.1100 | H124: 202603 | I124: 07 | J124: 47,000 | K124: 15 | L124: 개인 | M124: 개인 | O124: 송파대로 111 | P124: - | Q124: 중개거래 | R124: 서울 송파구
A125: 12 | B125: 서울특별시 송파구 문정동 | C125: 652-4 | D125: 0652 | E125: 0004 | F125: 힐스테이트에코문정 | G125: 20.7900 | H125: 202603 | I125: 06 | J125: 20,400 | K125: 12 | L125: 개인 | M125: 개인 | N125: 2018 | O125: 법원로4길 10 | P125: - | Q125: 중개거래 | R125: 서울 송파구
A126: 13 | B126: 서울특별시 송파구 문정동 | C126: 643-1 | D126: 0643 | E126: 0001 | F126: 엠스테이트 | G126: 26.1400 | H126: 202603 | I126: 04 | J126: 22,700 | K126: 17 | L126: 법인 | M126: 개인 | N126: 2016 | O126: 법원로 114 | P126: - | Q126: 중개거래 | R126: 서울 송파구
A127: 14 | B127: 서울특별시 송파구 문정동 | C127: 618 | D127: 0618 | E127: 0000 | F127: 파크하비오 | G127: 58.8400 | H127: 202603 | I127: 04 | J127: 70,800 | K127: 14 | L127: 개인 | M127: 개인 | O127: 송파대로 111 | P127: - | Q127: 중개거래 | R127: 서울 송파구
...

Sheet 04B_정규화_자동필터
A1: 정규화·1차필터·유사도 랭킹
A3: 원본행 | B3: 시군구 | C3: 번지 | D3: 단지명 | E3: 전용면적(㎡) | F3: 계약일 | G3: 거래금액(만원) | H3: 거래금액 (원) | I3: 단가 (원/㎡) | J3: 층 | K3: 건축년도 | L3: 도로명 | M3: 거래유형 | N3: 동일시군구 | O3: 동일법정동 | P3: 동일도로명 | Q3: 동일건물 | R3: 면적차율 | S3: 층차 | T3: 경과일수 | U3: 건축연차차 | V3: 1차통과 | W3: 유사도점수 | X3: 순위
A4: =IF('04A_국토부원자료'!A5="","",ROW()-3) -> 1 | B4: =IFERROR('04A_국토부원자료'!B5,"") -> 서울특별시 송파구 가락동 | C4: =IF(B4="","",IF('04A_국토부원자료'!C5<>"",'04A_국토부원자료'!C5,TRIM('04A_국토부원자료'!D5&IF('04A_국토부원자료'!E5<>"","-"&'04A_국토부원자료'!E5,"")))) -> 98-7 | D4: =IFERROR('04A_국토부원자료'!F5,"") -> (98-7) | E4: =IFERROR(VALUE(SUBSTITUTE('04A_국토부원자료'!G5,",","")),"") -> 27.84 | F4: =IFERROR(IF(AND('04A_국토부원자료'!H5<>"",'04A_국토부원자료'!I5<>""),DATE(INT(VALUE(SUBSTITUTE('04A_국토부원자료'!H5,",",""))/100),MOD(VALUE(SUBSTITUTE('04A_국토부원자료'!H5,",","")),100),VALUE(SUBSTITUTE('04A_국토부원자료'!I5,",",""))),""),"") -> 46091 | G4: =IFERROR(VALUE(SUBSTITUTE('04A_국토부원자료'!J5,",","")),"") -> 10500 | H4: =IF(G4="","",G4*10000) -> 105000000 | I4: =IFERROR(IF(AND(H4>0,E4>0),H4/E4,""),"") -> 3771551.7 | J4: =IFERROR(VALUE(SUBSTITUTE('04A_국토부원자료'!K5,",","")),"") -> 4 | K4: =IFERROR(VALUE(SUBSTITUTE('04A_국토부원자료'!N5,",","")),"") -> 1990 | L4: =IFERROR('04A_국토부원자료'!O5,"") -> 송파대로28길 13 | M4: =IFERROR('04A_국토부원자료'!Q5,"") -> 중개거래 | N4: =IF(B4="","",IF('02_대상물건입력'!B5="",1,IF(ISNUMBER(SEARCH('02_대상물건입력'!B5,B4)),1,0))) -> 1 | O4: =IF(B4="","",IF('02_대상물건입력'!B6="",1,IF(ISNUMBER(SEARCH('02_대상물건입력'!B6,B4)),1,0))) -> 1 | P4: =IF(L4="","",IF('02_대상물건입력'!B15="",0,IF(ISNUMBER(SEARCH('02_대상물건입력'!B15,L4)),1,0))) -> 1 | Q4: =IF(D4="","",IF('02_대상물건입력'!B8="",0,IF(ISNUMBER(SEARCH('02_대상물건입력'!B8,D4)),1,0))) -> 0 | R4: =IFERROR(ABS(E4-'02_대상물건입력'!B11)/'02_대상물건입력'!B11,"") -> 0.021921388 | S4: =IFERROR(ABS(J4-'02_대상물건입력'!B10),"") -> 8 | T4: =IFERROR(ABS('01_설정'!B4-F4),"") -> 21 | U4: =IFERROR(ABS(K4-YEAR('02_대상물건입력'!B14)),"") -> 36 | V4: =IF(B4="","",IF(AND(E4>0,F4>0,H4>0,OR('04A_국토부원자료'!P5="",'04A_국토부원자료'!P5="-"),IF('01_설정'!B10=1,N4=1,TRUE),R4<='01_설정'!B5,S4<='01_설정'!B6,T4<='01_설정'!B7,U4<='01_설정'!B8),"Y","")) | W4: =IF(V4<>"Y","",MAX(0,(1-R4/'01_설정'!B5))*'01_설정'!B14+MAX(0,(1-S4/'01_설정'!B6))*'01_설정'!B15+MAX(0,(1-T4/'01_설정'!B7))*'01_설정'!B16+MAX(0,(1-U4/'01_설정'!B8))*'01_설정'!B17+O4*'01_설정'!B11+Q4*'01_설정'!B12+P4*'01_설정'!B13) | X4: =IF(W4="","",1+COUNTIFS($W$4:$W$3003,">"&W4)+COUNTIFS($W$4:W4,W4)-1)
A5: =IF('04A_국토부원자료'!A6="","",ROW()-3) -> 2 | B5: =IFERROR('04A_국토부원자료'!B6,"") -> 서울특별시 송파구 가락동 | C5: =IF(B5="","",IF('04A_국토부원자료'!C6<>"",'04A_국토부원자료'!C6,TRIM('04A_국토부원자료'!D6&IF('04A_국토부원자료'!E6<>"","-"&'04A_국토부원자료'!E6,"")))) -> 98-7 | D5: =IFERROR('04A_국토부원자료'!F6,"") -> (98-7) | E5: =IFERROR(VALUE(SUBSTITUTE('04A_국토부원자료'!G6,",","")),"") -> 27.84 | F5: =IFERROR(IF(AND('04A_국토부원자료'!H6<>"",'04A_국토부원자료'!I6<>""),DATE(INT(VALUE(SUBSTITUTE('04A_국토부원자료'!H6,",",""))/100),MOD(VALUE(SUBSTITUTE('04A_국토부원자료'!H6,",","")),100),VALUE(SUBSTITUTE('04A_국토부원자료'!I6,",",""))),""),"") -> 46073 | G5: =IFERROR(VALUE(SUBSTITUTE('04A_국토부원자료'!J6,",","")),"") -> 10300 | H5: =IF(G5="","",G5*10000) -> 103000000 | I5: =IFERROR(IF(AND(H5>0,E5>0),H5/E5,""),"") -> 3699712.6 | J5: =IFERROR(VALUE(SUBSTITUTE('04A_국토부원자료'!K6,",","")),"") -> 4 | K5: =IFERROR(VALUE(SUBSTITUTE('04A_국토부원자료'!N6,",","")),"") -> 1990 | L5: =IFERROR('04A_국토부원자료'!O6,"") -> 송파대로28길 13 | M5: =IFERROR('04A_국토부원자료'!Q6,"") -> 중개거래 | N5: =IF(B5="","",IF('02_대상물건입력'!B5="",1,IF(ISNUMBER(SEARCH('02_대상물건입력'!B5,B5)),1,0))) -> 1 | O5: =IF(B5="","",IF('02_대상물건입력'!B6="",1,IF(ISNUMBER(SEARCH('02_대상물건입력'!B6,B5)),1,0))) -> 1 | P5: =IF(L5="","",IF('02_대상물건입력'!B15="",0,IF(ISNUMBER(SEARCH('02_대상물건입력'!B15,L5)),1,0))) -> 1 | Q5: =IF(D5="","",IF('02_대상물건입력'!B8="",0,IF(ISNUMBER(SEARCH('02_대상물건입력'!B8,D5)),1,0))) -> 0 | R5: =IFERROR(ABS(E5-'02_대상물건입력'!B11)/'02_대상물건입력'!B11,"") -> 0.021921388 | S5: =IFERROR(ABS(J5-'02_대상물건입력'!B10),"") -> 8 | T5: =IFERROR(ABS('01_설정'!B4-F5),"") -> 39 | U5: =IFERROR(ABS(K5-YEAR('02_대상물건입력'!B14)),"") -> 36 | V5: =IF(B5="","",IF(AND(E5>0,F5>0,H5>0,OR('04A_국토부원자료'!P6="",'04A_국토부원자료'!P6="-"),IF('01_설정'!B10=1,N5=1,TRUE),R5<='01_설정'!B5,S5<='01_설정'!B6,T5<='01_설정'!B7,U5<='01_설정'!B8),"Y","")) | W5: =IF(V5<>"Y","",MAX(0,(1-R5/'01_설정'!B5))*'01_설정'!B14+MAX(0,(1-S5/'01_설정'!B6))*'01_설정'!B15+MAX(0,(1-T5/'01_설정'!B7))*'01_설정'!B16+MAX(0,(1-U5/'01_설정'!B8))*'01_설정'!B17+O5*'01_설정'!B11+Q5*'01_설정'!B12+P5*'01_설정'!B13) | X5: =IF(W5="","",1+COUNTIFS($W$4:$W$3003,">"&W5)+COUNTIFS($W$4:W5,W5)-1)
A6: =IF('04A_국토부원자료'!A7="","",ROW()-3) -> 3 | B6: =IFERROR('04A_국토부원자료'!B7,"") -> 서울특별시 송파구 가락동 | C6: =IF(B6="","",IF('04A_국토부원자료'!C7<>"",'04A_국토부원자료'!C7,TRIM('04A_국토부원자료'!D7&IF('04A_국토부원자료'!E7<>"","-"&'04A_국토부원자료'!E7,"")))) -> 99-3 | D6: =IFERROR('04A_국토부원자료'!F7,"") -> 제일오피스텔 | E6: =IFERROR(VALUE(SUBSTITUTE('04A_국토부원자료'!G7,",","")),"") -> 31.14 | F6: =IFERROR(IF(AND('04A_국토부원자료'!H7<>"",'04A_국토부원자료'!I7<>""),DATE(INT(VALUE(SUBSTITUTE('04A_국토부원자료'!H7,",",""))/100),MOD(VALUE(SUBSTITUTE('04A_국토부원자료'!H7,",","")),100),VALUE(SUBSTITUTE('04A_국토부원자료'!I7,",",""))),""),"") -> 46057 | G6: =IFERROR(VALUE(SUBSTITUTE('04A_국토부원자료'!J7,",","")),"") -> 20800 | H6: =IF(G6="","",G6*10000) -> 208000000 | I6: =IFERROR(IF(AND(H6>0,E6>0),H6/E6,""),"") -> 6679511.9 | J6: =IFERROR(VALUE(SUBSTITUTE('04A_국토부원자료'!K7,",","")),"") -> 8 | K6: =IFERROR(VALUE(SUBSTITUTE('04A_국토부원자료'!N7,",","")),"") -> 1992 | L6: =IFERROR('04A_국토부원자료'!O7,"") -> 송파대로 260 | M6: =IFERROR('04A_국토부원자료'!Q7,"") -> 중개거래 | N6: =IF(B6="","",IF('02_대상물건입력'!B5="",1,IF(ISNUMBER(SEARCH('02_대상물건입력'!B5,B6)),1,0))) -> 1 | O6: =IF(B6="","",IF('02_대상물건입력'!B6="",1,IF(ISNUMBER(SEARCH('02_대상물건입력'!B6,B6)),1,0))) -> 1 | P6: =IF(L6="","",IF('02_대상물건입력'!B15="",0,IF(ISNUMBER(SEARCH('02_대상물건입력'!B15,L6)),1,0))) -> 1 | Q6: =IF(D6="","",IF('02_대상물건입력'!B8="",0,IF(ISNUMBER(SEARCH('02_대상물건입력'!B8,D6)),1,0))) -> 0 | R6: =IFERROR(ABS(E6-'02_대상물건입력'!B11)/'02_대상물건입력'!B11,"") -> 0.14305431 | S6: =IFERROR(ABS(J6-'02_대상물건입력'!B10),"") -> 4 | T6: =IFERROR(ABS('01_설정'!B4-F6),"") -> 55 | U6: =IFERROR(ABS(K6-YEAR('02_대상물건입력'!B14)),"") -> 34 | V6: =IF(B6="","",IF(AND(E6>0,F6>0,H6>0,OR('04A_국토부원자료'!P7="",'04A_국토부원자료'!P7="-"),IF('01_설정'!B10=1,N6=1,TRUE),R6<='01_설정'!B5,S6<='01_설정'!B6,T6<='01_설정'!B7,U6<='01_설정'!B8),"Y","")) | W6: =IF(V6<>"Y","",MAX(0,(1-R6/'01_설정'!B5))*'01_설정'!B14+MAX(0,(1-S6/'01_설정'!B6))*'01_설정'!B15+MAX(0,(1-T6/'01_설정'!B7))*'01_설정'!B16+MAX(0,(1-U6/'01_설정'!B8))*'01_설정'!B17+O6*'01_설정'!B11+Q6*'01_설정'!B12+P6*'01_설정'!B13) | X6: =IF(W6="","",1+COUNTIFS($W$4:$W$3003,">"&W6)+COUNTIFS($W$4:W6,W6)-1)
A7: =IF('04A_국토부원자료'!A8="","",ROW()-3) -> 4 | B7: =IFERROR('04A_국토부원자료'!B8,"") -> 서울특별시 송파구 가락동 | C7: =IF(B7="","",IF('04A_국토부원자료'!C8<>"",'04A_국토부원자료'!C8,TRIM('04A_국토부원자료'!D8&IF('04A_국토부원자료'!E8<>"","-"&'04A_국토부원자료'!E8,"")))) -> 79-7 | D7: =IFERROR('04A_국토부원자료'!F8,"") -> (79-7) | E7: =IFERROR(VALUE(SUBSTITUTE('04A_국토부원자료'!G8,",","")),"") -> 29.52 | F7: =IFERROR(IF(AND('04A_국토부원자료'!H8<>"",'04A_국토부원자료'!I8<>""),DATE(INT(VALUE(SUBSTITUTE('04A_국토부원자료'!H8,",",""))/100),MOD(VALUE(SUBSTITUTE('04A_국토부원자료'!H8,",","")),100),VALUE(SUBSTITUTE('04A_국토부원자료'!I8,",",""))),""),"") -> 46050 | G7: =IFERROR(VALUE(SUBSTITUTE('04A_국토부원자료'!J8,",","")),"") -> 12500 | H7: =IF(G7="","",G7*10000) -> 125000000 | I7: =IFERROR(IF(AND(H7>0,E7>0),H7/E7,""),"") -> 4234417.3 | J7: =IFERROR(VALUE(SUBSTITUTE('04A_국토부원자료'!K8,",","")),"") -> 10 | K7: =IFERROR(VALUE(SUBSTITUTE('04A_국토부원자료'!N8,",","")),"") -> 1990 | L7: =IFERROR('04A_국토부원자료'!O8,"") -> 송파대로28길 32 | M7: =IFERROR('04A_국토부원자료'!Q8,"") -> 중개거래 | N7: =IF(B7="","",IF('02_대상물건입력'!B5="",1,IF(ISNUMBER(SEARCH('02_대상물건입력'!B5,B7)),1,0))) -> 1 | O7: =IF(B7="","",IF('02_대상물건입력'!B6="",1,IF(ISNUMBER(SEARCH('02_대상물건입력'!B6,B7)),1,0))) -> 1 | P7: =IF(L7="","",IF('02_대상물건입력'!B15="",0,IF(ISNUMBER(SEARCH('02_대상물건입력'!B15,L7)),1,0))) -> 1 | Q7: =IF(D7="","",IF('02_대상물건입력'!B8="",0,IF(ISNUMBER(SEARCH('02_대상물건입력'!B8,D7)),1,0))) -> 0 | R7: =IFERROR(ABS(E7-'02_대상물건입력'!B11)/'02_대상물건입력'!B11,"") -> 0.083589058 | S7: =IFERROR(ABS(J7-'02_대상물건입력'!B10),"") -> 2 | T7: =IFERROR(ABS('01_설정'!B4-F7),"") -> 62 | U7: =IFERROR(ABS(K7-YEAR('02_대상물건입력'!B14)),"") -> 36 | V7: =IF(B7="","",IF(AND(E7>0,F7>0,H7>0,OR('04A_국토부원자료'!P8="",'04A_국토부원자료'!P8="-"),IF('01_설정'!B10=1,N7=1,TRUE),R7<='01_설정'!B5,S7<='01_설정'!B6,T7<='01_설정'!B7,U7<='01_설정'!B8),"Y","")) | W7: =IF(V7<>"Y","",MAX(0,(1-R7/'01_설정'!B5))*'01_설정'!B14+MAX(0,(1-S7/'01_설정'!B6))*'01_설정'!B15+MAX(0,(1-T7/'01_설정'!B7))*'01_설정'!B16+MAX(0,(1-U7/'01_설정'!B8))*'01_설정'!B17+O7*'01_설정'!B11+Q7*'01_설정'!B12+P7*'01_설정'!B13) | X7: =IF(W7="","",1+COUNTIFS($W$4:$W$3003,">"&W7)+COUNTIFS($W$4:W7,W7)-1)
A8: =IF('04A_국토부원자료'!A9="","",ROW()-3) -> 5 | B8: =IFERROR('04A_국토부원자료'!B9,"") -> 서울특별시 송파구 가락동 | C8: =IF(B8="","",IF('04A_국토부원자료'!C9<>"",'04A_국토부원자료'!C9,TRIM('04A_국토부원자료'!D9&IF('04A_국토부원자료'!E9<>"","-"&'04A_국토부원자료'!E9,"")))) -> 79-7 | D8: =IFERROR('04A_국토부원자료'!F9,"") -> (79-7) | E8: =IFERROR(VALUE(SUBSTITUTE('04A_국토부원자료'!G9,",","")),"") -> 29.52 | F8: =IFERROR(IF(AND('04A_국토부원자료'!H9<>"",'04A_국토부원자료'!I9<>""),DATE(INT(VALUE(SUBSTITUTE('04A_국토부원자료'!H9,",",""))/100),MOD(VALUE(SUBSTITUTE('04A_국토부원자료'!H9,",","")),100),VALUE(SUBSTITUTE('04A_국토부원자료'!I9,",",""))),""),"") -> 46050 | G8: =IFERROR(VALUE(SUBSTITUTE('04A_국토부원자료'!J9,",","")),"") -> 13000 | H8: =IF(G8="","",G8*10000) -> 130000000 | I8: =IFERROR(IF(AND(H8>0,E8>0),H8/E8,""),"") -> 4403794 | J8: =IFERROR(VALUE(SUBSTITUTE('04A_국토부원자료'!K9,",","")),"") -> 2 | K8: =IFERROR(VALUE(SUBSTITUTE('04A_국토부원자료'!N9,",","")),"") -> 1990 | L8: =IFERROR('04A_국토부원자료'!O9,"") -> 송파대로28길 32 | M8: =IFERROR('04A_국토부원자료'!Q9,"") -> 직거래 | N8: =IF(B8="","",IF('02_대상물건입력'!B5="",1,IF(ISNUMBER(SEARCH('02_대상물건입력'!B5,B8)),1,0))) -> 1 | O8: =IF(B8="","",IF('02_대상물건입력'!B6="",1,IF(ISNUMBER(SEARCH('02_대상물건입력'!B6,B8)),1,0))) -> 1 | P8: =IF(L8="","",IF('02_대상물건입력'!B15="",0,IF(ISNUMBER(SEARCH('02_대상물건입력'!B15,L8)),1,0))) -> 1 | Q8: =IF(D8="","",IF('02_대상물건입력'!B8="",0,IF(ISNUMBER(SEARCH('02_대상물건입력'!B8,D8)),1,0))) -> 0 | R8: =IFERROR(ABS(E8-'02_대상물건입력'!B11)/'02_대상물건입력'!B11,"") -> 0.083589058 | S8: =IFERROR(ABS(J8-'02_대상물건입력'!B10),"") -> 10 | T8: =IFERROR(ABS('01_설정'!B4-F8),"") -> 62 | U8: =IFERROR(ABS(K8-YEAR('02_대상물건입력'!B14)),"") -> 36 | V8: =IF(B8="","",IF(AND(E8>0,F8>0,H8>0,OR('04A_국토부원자료'!P9="",'04A_국토부원자료'!P9="-"),IF('01_설정'!B10=1,N8=1,TRUE),R8<='01_설정'!B5,S8<='01_설정'!B6,T8<='01_설정'!B7,U8<='01_설정'!B8),"Y","")) | W8: =IF(V8<>"Y","",MAX(0,(1-R8/'01_설정'!B5))*'01_설정'!B14+MAX(0,(1-S8/'01_설정'!B6))*'01_설정'!B15+MAX(0,(1-T8/'01_설정'!B7))*'01_설정'!B16+MAX(0,(1-U8/'01_설정'!B8))*'01_설정'!B17+O8*'01_설정'!B11+Q8*'01_설정'!B12+P8*'01_설정'!B13) | X8: =IF(W8="","",1+COUNTIFS($W$4:$W$3003,">"&W8)+COUNTIFS($W$4:W8,W8)-1)
A9: =IF('04A_국토부원자료'!A10="","",ROW()-3) -> 6 | B9: =IFERROR('04A_국토부원자료'!B10,"") -> 서울특별시 송파구 가락동 | C9: =IF(B9="","",IF('04A_국토부원자료'!C10<>"",'04A_국토부원자료'!C10,TRIM('04A_국토부원자료'!D10&IF('04A_국토부원자료'!E10<>"","-"&'04A_국토부원자료'!E10,"")))) -> 79-7 | D9: =IFERROR('04A_국토부원자료'!F10,"") -> (79-7) | E9: =IFERROR(VALUE(SUBSTITUTE('04A_국토부원자료'!G10,",","")),"") -> 29.52 | F9: =IFERROR(IF(AND('04A_국토부원자료'!H10<>"",'04A_국토부원자료'!I10<>""),DATE(INT(VALUE(SUBSTITUTE('04A_국토부원자료'!H10,",",""))/100),MOD(VALUE(SUBSTITUTE('04A_국토부원자료'!H10,",","")),100),VALUE(SUBSTITUTE('04A_국토부원자료'!I10,",",""))),""),"") -> 46050 | G9: =IFERROR(VALUE(SUBSTITUTE('04A_국토부원자료'!J10,",","")),"") -> 12500 | H9: =IF(G9="","",G9*10000) -> 125000000 | I9: =IFERROR(IF(AND(H9>0,E9>0),H9/E9,""),"") -> 4234417.3 | J9: =IFERROR(VALUE(SUBSTITUTE('04A_국토부원자료'!K10,",","")),"") -> 10 | K9: =IFERROR(VALUE(SUBSTITUTE('04A_국토부원자료'!N10,",","")),"") -> 1990 | L9: =IFERROR('04A_국토부원자료'!O10,"") -> 송파대로28길 32 | M9: =IFERROR('04A_국토부원자료'!Q10,"") -> 중개거래 | N9: =IF(B9="","",IF('02_대상물건입력'!B5="",1,IF(ISNUMBER(SEARCH('02_대상물건입력'!B5,B9)),1,0))) -> 1 | O9: =IF(B9="","",IF('02_대상물건입력'!B6="",1,IF(ISNUMBER(SEARCH('02_대상물건입력'!B6,B9)),1,0))) -> 1 | P9: =IF(L9="","",IF('02_대상물건입력'!B15="",0,IF(ISNUMBER(SEARCH('02_대상물건입력'!B15,L9)),1,0))) -> 1 | Q9: =IF(D9="","",IF('02_대상물건입력'!B8="",0,IF(ISNUMBER(SEARCH('02_대상물건입력'!B8,D9)),1,0))) -> 0 | R9: =IFERROR(ABS(E9-'02_대상물건입력'!B11)/'02_대상물건입력'!B11,"") -> 0.083589058 | S9: =IFERROR(ABS(J9-'02_대상물건입력'!B10),"") -> 2 | T9: =IFERROR(ABS('01_설정'!B4-F9),"") -> 62 | U9: =IFERROR(ABS(K9-YEAR('02_대상물건입력'!B14)),"") -> 36 | V9: =IF(B9="","",IF(AND(E9>0,F9>0,H9>0,OR('04A_국토부원자료'!P10="",'04A_국토부원자료'!P10="-"),IF('01_설정'!B10=1,N9=1,TRUE),R9<='01_설정'!B5,S9<='01_설정'!B6,T9<='01_설정'!B7,U9<='01_설정'!B8),"Y","")) | W9: =IF(V9<>"Y","",MAX(0,(1-R9/'01_설정'!B5))*'01_설정'!B14+MAX(0,(1-S9/'01_설정'!B6))*'01_설정'!B15+MAX(0,(1-T9/'01_설정'!B7))*'01_설정'!B16+MAX(0,(1-U9/'01_설정'!B8))*'01_설정'!B17+O9*'01_설정'!B11+Q9*'01_설정'!B12+P9*'01_설정'!B13) | X9: =IF(W9="","",1+COUNTIFS($W$4:$W$3003,">"&W9)+COUNTIFS($W$4:W9,W9)-1)
A10: =IF('04A_국토부원자료'!A11="","",ROW()-3) -> 7 | B10: =IFERROR('04A_국토부원자료'!B11,"") -> 서울특별시 송파구 가락동 | C10: =IF(B10="","",IF('04A_국토부원자료'!C11<>"",'04A_국토부원자료'!C11,TRIM('04A_국토부원자료'!D11&IF('04A_국토부원자료'!E11<>"","-"&'04A_국토부원자료'!E11,"")))) -> 171 | D10: =IFERROR('04A_국토부원자료'!F11,"") -> 현진타워 | E10: =IFERROR(VALUE(SUBSTITUTE('04A_국토부원자료'!G11,",","")),"") -> 42.32 | F10: =IFERROR(IF(AND('04A_국토부원자료'!H11<>"",'04A_국토부원자료'!I11<>""),DATE(INT(VALUE(SUBSTITUTE('04A_국토부원자료'!H11,",",""))/100),MOD(VALUE(SUBSTITUTE('04A_국토부원자료'!H11,",","")),100),VALUE(SUBSTITUTE('04A_국토부원자료'!I11,",",""))),""),"") -> 46048 | G10: =IFERROR(VALUE(SUBSTITUTE('04A_국토부원자료'!J11,",","")),"") -> 32000 | H10: =IF(G10="","",G10*10000) -> 320000000 | I10: =IFERROR(IF(AND(H10>0,E10>0),H10/E10,""),"") -> 7561436.7 | J10: =IFERROR(VALUE(SUBSTITUTE('04A_국토부원자료'!K11,",","")),"") -> 5 | K10: =IFERROR(VALUE(SUBSTITUTE('04A_국토부원자료'!N11,",","")),"") -> 2015 | L10: =IFERROR('04A_국토부원자료'!O11,"") -> 오금로44가길 13 | M10: =IFERROR('04A_국토부원자료'!Q11,"") -> 중개거래 | N10: =IF(B10="","",IF('02_대상물건입력'!B5="",1,IF(ISNUMBER(SEARCH('02_대상물건입력'!B5,B10)),1,0))) -> 1 | O10: =IF(B10="","",IF('02_대상물건입력'!B6="",1,IF(ISNUMBER(SEARCH('02_대상물건입력'!B6,B10)),1,0))) -> 1 | P10: =IF(L10="","",IF('02_대상물건입력'!B15="",0,IF(ISNUMBER(SEARCH('02_대상물건입력'!B15,L10)),1,0))) -> 0 | Q10: =IF(D10="","",IF('02_대상물건입력'!B8="",0,IF(ISNUMBER(SEARCH('02_대상물건입력'!B8,D10)),1,0))) -> 0 | R10: =IFERROR(ABS(E10-'02_대상물건입력'!B11)/'02_대상물건입력'!B11,"") -> 0.55343797 | S10: =IFERROR(ABS(J10-'02_대상물건입력'!B10),"") -> 7 | T10: =IFERROR(ABS('01_설정'!B4-F10),"") -> 64 | U10: =IFERROR(ABS(K10-YEAR('02_대상물건입력'!B14)),"") -> 11 | V10: =IF(B10="","",IF(AND(E10>0,F10>0,H10>0,OR('04A_국토부원자료'!P11="",'04A_국토부원자료'!P11="-"),IF('01_설정'!B10=1,N10=1,TRUE),R10<='01_설정'!B5,S10<='01_설정'!B6,T10<='01_설정'!B7,U10<='01_설정'!B8),"Y","")) | W10: =IF(V10<>"Y","",MAX(0,(1-R10/'01_설정'!B5))*'01_설정'!B14+MAX(0,(1-S10/'01_설정'!B6))*'01_설정'!B15+MAX(0,(1-T10/'01_설정'!B7))*'01_설정'!B16+MAX(0,(1-U10/'01_설정'!B8))*'01_설정'!B17+O10*'01_설정'!B11+Q10*'01_설정'!B12+P10*'01_설정'!B13) | X10: =IF(W10="","",1+COUNTIFS($W$4:$W$3003,">"&W10)+COUNTIFS($W$4:W10,W10)-1)
A11: =IF('04A_국토부원자료'!A12="","",ROW()-3) -> 8 | B11: =IFERROR('04A_국토부원자료'!B12,"") -> 서울특별시 송파구 가락동 | C11: =IF(B11="","",IF('04A_국토부원자료'!C12<>"",'04A_국토부원자료'!C12,TRIM('04A_국토부원자료'!D12&IF('04A_국토부원자료'!E12<>"","-"&'04A_국토부원자료'!E12,"")))) -> 78-1 | D11: =IFERROR('04A_국토부원자료'!F12,"") -> 한화오벨리스크 | E11: =IFERROR(VALUE(SUBSTITUTE('04A_국토부원자료'!G12,",","")),"") -> 30.34 | F11: =IFERROR(IF(AND('04A_국토부원자료'!H12<>"",'04A_국토부원자료'!I12<>""),DATE(INT(VALUE(SUBSTITUTE('04A_국토부원자료'!H12,",",""))/100),MOD(VALUE(SUBSTITUTE('04A_국토부원자료'!H12,",","")),100),VALUE(SUBSTITUTE('04A_국토부원자료'!I12,",",""))),""),"") -> 46048 | G11: =IFERROR(VALUE(SUBSTITUTE('04A_국토부원자료'!J12,",","")),"") -> 18000 | H11: =IF(G11="","",G11*10000) -> 180000000 | I11: =IFERROR(IF(AND(H11>0,E11>0),H11/E11,""),"") -> 5932762 | J11: =IFERROR(VALUE(SUBSTITUTE('04A_국토부원자료'!K12,",","")),"") -> 11 | K11: =IFERROR(VALUE(SUBSTITUTE('04A_국토부원자료'!N12,",","")),"") -> 2004 | L11: =IFERROR('04A_국토부원자료'!O12,"") -> 중대로 127 | M11: =IFERROR('04A_국토부원자료'!Q12,"") -> 중개거래 | N11: =IF(B11="","",IF('02_대상물건입력'!B5="",1,IF(ISNUMBER(SEARCH('02_대상물건입력'!B5,B11)),1,0))) -> 1 | O11: =IF(B11="","",IF('02_대상물건입력'!B6="",1,IF(ISNUMBER(SEARCH('02_대상물건입력'!B6,B11)),1,0))) -> 1 | P11: =IF(L11="","",IF('02_대상물건입력'!B15="",0,IF(ISNUMBER(SEARCH('02_대상물건입력'!B15,L11)),1,0))) -> 0 | Q11: =IF(D11="","",IF('02_대상물건입력'!B8="",0,IF(ISNUMBER(SEARCH('02_대상물건입력'!B8,D11)),1,0))) -> 0 | R11: =IFERROR(ABS(E11-'02_대상물건입력'!B11)/'02_대상물건입력'!B11,"") -> 0.11368875 | S11: =IFERROR(ABS(J11-'02_대상물건입력'!B10),"") -> 1 | T11: =IFERROR(ABS('01_설정'!B4-F11),"") -> 64 | U11: =IFERROR(ABS(K11-YEAR('02_대상물건입력'!B14)),"") -> 22 | V11: =IF(B11="","",IF(AND(E11>0,F11>0,H11>0,OR('04A_국토부원자료'!P12="",'04A_국토부원자료'!P12="-"),IF('01_설정'!B10=1,N11=1,TRUE),R11<='01_설정'!B5,S11<='01_설정'!B6,T11<='01_설정'!B7,U11<='01_설정'!B8),"Y","")) | W11: =IF(V11<>"Y","",MAX(0,(1-R11/'01_설정'!B5))*'01_설정'!B14+MAX(0,(1-S11/'01_설정'!B6))*'01_설정'!B15+MAX(0,(1-T11/'01_설정'!B7))*'01_설정'!B16+MAX(0,(1-U11/'01_설정'!B8))*'01_설정'!B17+O11*'01_설정'!B11+Q11*'01_설정'!B12+P11*'01_설정'!B13) | X11: =IF(W11="","",1+COUNTIFS($W$4:$W$3003,">"&W11)+COUNTIFS($W$4:W11,W11)-1)
A12: =IF('04A_국토부원자료'!A13="","",ROW()-3) -> 9 | B12: =IFERROR('04A_국토부원자료'!B13,"") -> 서울특별시 송파구 가락동 | C12: =IF(B12="","",IF('04A_국토부원자료'!C13<>"",'04A_국토부원자료'!C13,TRIM('04A_국토부원자료'!D13&IF('04A_국토부원자료'!E13<>"","-"&'04A_국토부원자료'!E13,"")))) -> 171 | D12: =IFERROR('04A_국토부원자료'!F13,"") -> 현진타워 | E12: =IFERROR(VALUE(SUBSTITUTE('04A_국토부원자료'!G13,",","")),"") -> 42.18 | F12: =IFERROR(IF(AND('04A_국토부원자료'!H13<>"",'04A_국토부원자료'!I13<>""),DATE(INT(VALUE(SUBSTITUTE('04A_국토부원자료'!H13,",",""))/100),MOD(VALUE(SUBSTITUTE('04A_국토부원자료'!H13,",","")),100),VALUE(SUBSTITUTE('04A_국토부원자료'!I13,",",""))),""),"") -> 46046 | G12: =IFERROR(VALUE(SUBSTITUTE('04A_국토부원자료'!J13,",","")),"") -> 32800 | H12: =IF(G12="","",G12*10000) -> 328000000 | I12: =IFERROR(IF(AND(H12>0,E12>0),H12/E12,""),"") -> 7776197.2 | J12: =IFERROR(VALUE(SUBSTITUTE('04A_국토부원자료'!K13,",","")),"") -> 5 | K12: =IFERROR(VALUE(SUBSTITUTE('04A_국토부원자료'!N13,",","")),"") -> 2015 | L12: =IFERROR('04A_국토부원자료'!O13,"") -> 오금로44가길 13 | M12: =IFERROR('04A_국토부원자료'!Q13,"") -> 중개거래 | N12: =IF(B12="","",IF('02_대상물건입력'!B5="",1,IF(ISNUMBER(SEARCH('02_대상물건입력'!B5,B12)),1,0))) -> 1 | O12: =IF(B12="","",IF('02_대상물건입력'!B6="",1,IF(ISNUMBER(SEARCH('02_대상물건입력'!B6,B12)),1,0))) -> 1 | P12: =IF(L12="","",IF('02_대상물건입력'!B15="",0,IF(ISNUMBER(SEARCH('02_대상물건입력'!B15,L12)),1,0))) -> 0 | Q12: =IF(D12="","",IF('02_대상물건입력'!B8="",0,IF(ISNUMBER(SEARCH('02_대상물건입력'!B8,D12)),1,0))) -> 0 | R12: =IFERROR(ABS(E12-'02_대상물건입력'!B11)/'02_대상물건입력'!B11,"") -> 0.548299 | S12: =IFERROR(ABS(J12-'02_대상물건입력'!B10),"") -> 7 | T12: =IFERROR(ABS('01_설정'!B4-F12),"") -> 66 | U12: =IFERROR(ABS(K12-YEAR('02_대상물건입력'!B14)),"") -> 11 | V12: =IF(B12="","",IF(AND(E12>0,F12>0,H12>0,OR('04A_국토부원자료'!P13="",'04A_국토부원자료'!P13="-"),IF('01_설정'!B10=1,N12=1,TRUE),R12<='01_설정'!B5,S12<='01_설정'!B6,T12<='01_설정'!B7,U12<='01_설정'!B8),"Y","")) | W12: =IF(V12<>"Y","",MAX(0,(1-R12/'01_설정'!B5))*'01_설정'!B14+MAX(0,(1-S12/'01_설정'!B6))*'01_설정'!B15+MAX(0,(1-T12/'01_설정'!B7))*'01_설정'!B16+MAX(0,(1-U12/'01_설정'!B8))*'01_설정'!B17+O12*'01_설정'!B11+Q12*'01_설정'!B12+P12*'01_설정'!B13) | X12: =IF(W12="","",1+COUNTIFS($W$4:$W$3003,">"&W12)+COUNTIFS($W$4:W12,W12)-1)
A13: =IF('04A_국토부원자료'!A14="","",ROW()-3) -> 10 | B13: =IFERROR('04A_국토부원자료'!B14,"") -> 서울특별시 송파구 가락동 | C13: =IF(B13="","",IF('04A_국토부원자료'!C14<>"",'04A_국토부원자료'!C14,TRIM('04A_국토부원자료'!D14&IF('04A_국토부원자료'!E14<>"","-"&'04A_국토부원자료'!E14,"")))) -> 98-7 | D13: =IFERROR('04A_국토부원자료'!F14,"") -> (98-7) | E13: =IFERROR(VALUE(SUBSTITUTE('04A_국토부원자료'!G14,",","")),"") -> 35.24 | F13: =IFERROR(IF(AND('04A_국토부원자료'!H14<>"",'04A_국토부원자료'!I14<>""),DATE(INT(VALUE(SUBSTITUTE('04A_국토부원자료'!H14,",",""))/100),MOD(VALUE(SUBSTITUTE('04A_국토부원자료'!H14,",","")),100),VALUE(SUBSTITUTE('04A_국토부원자료'!I14,",",""))),""),"") -> 46044 | G13: =IFERROR(VALUE(SUBSTITUTE('04A_국토부원자료'!J14,",","")),"") -> 15900 | H13: =IF(G13="","",G13*10000) -> 159000000 | I13: =IFERROR(IF(AND(H13>0,E13>0),H13/E13,""),"") -> 4511918.3 | J13: =IFERROR(VALUE(SUBSTITUTE('04A_국토부원자료'!K14,",","")),"") -> 4 | K13: =IFERROR(VALUE(SUBSTITUTE('04A_국토부원자료'!N14,",","")),"") -> 1990 | L13: =IFERROR('04A_국토부원자료'!O14,"") -> 송파대로28길 13 | M13: =IFERROR('04A_국토부원자료'!Q14,"") -> 중개거래 | N13: =IF(B13="","",IF('02_대상물건입력'!B5="",1,IF(ISNUMBER(SEARCH('02_대상물건입력'!B5,B13)),1,0))) -> 1 | O13: =IF(B13="","",IF('02_대상물건입력'!B6="",1,IF(ISNUMBER(SEARCH('02_대상물건입력'!B6,B13)),1,0))) -> 1 | P13: =IF(L13="","",IF('02_대상물건입력'!B15="",0,IF(ISNUMBER(SEARCH('02_대상물건입력'!B15,L13)),1,0))) -> 1 | Q13: =IF(D13="","",IF('02_대상물건입력'!B8="",0,IF(ISNUMBER(SEARCH('02_대상물건입력'!B8,D13)),1,0))) -> 0 | R13: =IFERROR(ABS(E13-'02_대상물건입력'!B11)/'02_대상물건입력'!B11,"") -> 0.29355279 | S13: =IFERROR(ABS(J13-'02_대상물건입력'!B10),"") -> 8 | T13: =IFERROR(ABS('01_설정'!B4-F13),"") -> 68 | U13: =IFERROR(ABS(K13-YEAR('02_대상물건입력'!B14)),"") -> 36 | V13: =IF(B13="","",IF(AND(E13>0,F13>0,H13>0,OR('04A_국토부원자료'!P14="",'04A_국토부원자료'!P14="-"),IF('01_설정'!B10=1,N13=1,TRUE),R13<='01_설정'!B5,S13<='01_설정'!B6,T13<='01_설정'!B7,U13<='01_설정'!B8),"Y","")) | W13: =IF(V13<>"Y","",MAX(0,(1-R13/'01_설정'!B5))*'01_설정'!B14+MAX(0,(1-S13/'01_설정'!B6))*'01_설정'!B15+MAX(0,(1-T13/'01_설정'!B7))*'01_설정'!B16+MAX(0,(1-U13/'01_설정'!B8))*'01_설정'!B17+O13*'01_설정'!B11+Q13*'01_설정'!B12+P13*'01_설정'!B13) | X13: =IF(W13="","",1+COUNTIFS($W$4:$W$3003,">"&W13)+COUNTIFS($W$4:W13,W13)-1)
A14: =IF('04A_국토부원자료'!A15="","",ROW()-3) -> 11 | B14: =IFERROR('04A_국토부원자료'!B15,"") -> 서울특별시 송파구 가락동 | C14: =IF(B14="","",IF('04A_국토부원자료'!C15<>"",'04A_국토부원자료'!C15,TRIM('04A_국토부원자료'!D15&IF('04A_국토부원자료'!E15<>"","-"&'04A_국토부원자료'!E15,"")))) -> 78-1 | D14: =IFERROR('04A_국토부원자료'!F15,"") -> 한화오벨리스크 | E14: =IFERROR(VALUE(SUBSTITUTE('04A_국토부원자료'!G15,",","")),"") -> 37.93 | F14: =IFERROR(IF(AND('04A_국토부원자료'!H15<>"",'04A_국토부원자료'!I15<>""),DATE(INT(VALUE(SUBSTITUTE('04A_국토부원자료'!H15,",",""))/100),MOD(VALUE(SUBSTITUTE('04A_국토부원자료'!H15,",","")),100),VALUE(SUBSTITUTE('04A_국토부원자료'!I15,",",""))),""),"") -> 46041 | G14: =IFERROR(VALUE(SUBSTITUTE('04A_국토부원자료'!J15,",","")),"") -> 22000 | H14: =IF(G14="","",G14*10000) -> 220000000 | I14: =IFERROR(IF(AND(H14>0,E14>0),H14/E14,""),"") -> 5800158.2 | J14: =IFERROR(VALUE(SUBSTITUTE('04A_국토부원자료'!K15,",","")),"") -> 12 | K14: =IFERROR(VALUE(SUBSTITUTE('04A_국토부원자료'!N15,",","")),"") -> 2004 | L14: =IFERROR('04A_국토부원자료'!O15,"") -> 중대로 127 | M14: =IFERROR('04A_국토부원자료'!Q15,"") -> 중개거래 | N14: =IF(B14="","",IF('02_대상물건입력'!B5="",1,IF(ISNUMBER(SEARCH('02_대상물건입력'!B5,B14)),1,0))) -> 1 | O14: =IF(B14="","",IF('02_대상물건입력'!B6="",1,IF(ISNUMBER(SEARCH('02_대상물건입력'!B6,B14)),1,0))) -> 1 | P14: =IF(L14="","",IF('02_대상물건입력'!B15="",0,IF(ISNUMBER(SEARCH('02_대상물건입력'!B15,L14)),1,0))) -> 0 | Q14: =IF(D14="","",IF('02_대상물건입력'!B8="",0,IF(ISNUMBER(SEARCH('02_대상물건입력'!B8,D14)),1,0))) -> 0 | R14: =IFERROR(ABS(E14-'02_대상물건입력'!B11)/'02_대상물건입력'!B11,"") -> 0.39229448 | S14: =IFERROR(ABS(J14-'02_대상물건입력'!B10),"") -> 0 | T14: =IFERROR(ABS('01_설정'!B4-F14),"") -> 71 | U14: =IFERROR(ABS(K14-YEAR('02_대상물건입력'!B14)),"") -> 22 | V14: =IF(B14="","",IF(AND(E14>0,F14>0,H14>0,OR('04A_국토부원자료'!P15="",'04A_국토부원자료'!P15="-"),IF('01_설정'!B10=1,N14=1,TRUE),R14<='01_설정'!B5,S14<='01_설정'!B6,T14<='01_설정'!B7,U14<='01_설정'!B8),"Y","")) | W14: =IF(V14<>"Y","",MAX(0,(1-R14/'01_설정'!B5))*'01_설정'!B14+MAX(0,(1-S14/'01_설정'!B6))*'01_설정'!B15+MAX(0,(1-T14/'01_설정'!B7))*'01_설정'!B16+MAX(0,(1-U14/'01_설정'!B8))*'01_설정'!B17+O14*'01_설정'!B11+Q14*'01_설정'!B12+P14*'01_설정'!B13) | X14: =IF(W14="","",1+COUNTIFS($W$4:$W$3003,">"&W14)+COUNTIFS($W$4:W14,W14)-1)
A15: =IF('04A_국토부원자료'!A16="","",ROW()-3) -> 12 | B15: =IFERROR('04A_국토부원자료'!B16,"") -> 서울특별시 송파구 가락동 | C15: =IF(B15="","",IF('04A_국토부원자료'!C16<>"",'04A_국토부원자료'!C16,TRIM('04A_국토부원자료'!D16&IF('04A_국토부원자료'!E16<>"","-"&'04A_국토부원자료'!E16,"")))) -> 99-3 | D15: =IFERROR('04A_국토부원자료'!F16,"") -> 제일오피스텔 | E15: =IFERROR(VALUE(SUBSTITUTE('04A_국토부원자료'!G16,",","")),"") -> 31.14 | F15: =IFERROR(IF(AND('04A_국토부원자료'!H16<>"",'04A_국토부원자료'!I16<>""),DATE(INT(VALUE(SUBSTITUTE('04A_국토부원자료'!H16,",",""))/100),MOD(VALUE(SUBSTITUTE('04A_국토부원자료'!H16,",","")),100),VALUE(SUBSTITUTE('04A_국토부원자료'!I16,",",""))),""),"") -> 46039 | G15: =IFERROR(VALUE(SUBSTITUTE('04A_국토부원자료'!J16,",","")),"") -> 19000 | H15: =IF(G15="","",G15*10000) -> 190000000 | I15: =IFERROR(IF(AND(H15>0,E15>0),H15/E15,""),"") -> 6101477.2 | J15: =IFERROR(VALUE(SUBSTITUTE('04A_국토부원자료'!K16,",","")),"") -> 14 | K15: =IFERROR(VALUE(SUBSTITUTE('04A_국토부원자료'!N16,",","")),"") -> 1992 | L15: =IFERROR('04A_국토부원자료'!O16,"") -> 송파대로 260 | M15: =IFERROR('04A_국토부원자료'!Q16,"") -> 중개거래 | N15: =IF(B15="","",IF('02_대상물건입력'!B5="",1,IF(ISNUMBER(SEARCH('02_대상물건입력'!B5,B15)),1,0))) -> 1 | O15: =IF(B15="","",IF('02_대상물건입력'!B6="",1,IF(ISNUMBER(SEARCH('02_대상물건입력'!B6,B15)),1,0))) -> 1 | P15: =IF(L15="","",IF('02_대상물건입력'!B15="",0,IF(ISNUMBER(SEARCH('02_대상물건입력'!B15,L15)),1,0))) -> 1 | Q15: =IF(D15="","",IF('02_대상물건입력'!B8="",0,IF(ISNUMBER(SEARCH('02_대상물건입력'!B8,D15)),1,0))) -> 0 | R15: =IFERROR(ABS(E15-'02_대상물건입력'!B11)/'02_대상물건입력'!B11,"") -> 0.14305431 | S15: =IFERROR(ABS(J15-'02_대상물건입력'!B10),"") -> 2 | T15: =IFERROR(ABS('01_설정'!B4-F15),"") -> 73 | U15: =IFERROR(ABS(K15-YEAR('02_대상물건입력'!B14)),"") -> 34 | V15: =IF(B15="","",IF(AND(E15>0,F15>0,H15>0,OR('04A_국토부원자료'!P16="",'04A_국토부원자료'!P16="-"),IF('01_설정'!B10=1,N15=1,TRUE),R15<='01_설정'!B5,S15<='01_설정'!B6,T15<='01_설정'!B7,U15<='01_설정'!B8),"Y","")) | W15: =IF(V15<>"Y","",MAX(0,(1-R15/'01_설정'!B5))*'01_설정'!B14+MAX(0,(1-S15/'01_설정'!B6))*'01_설정'!B15+MAX(0,(1-T15/'01_설정'!B7))*'01_설정'!B16+MAX(0,(1-U15/'01_설정'!B8))*'01_설정'!B17+O15*'01_설정'!B11+Q15*'01_설정'!B12+P15*'01_설정'!B13) | X15: =IF(W15="","",1+COUNTIFS($W$4:$W$3003,">"&W15)+COUNTIFS($W$4:W15,W15)-1)
A16: =IF('04A_국토부원자료'!A17="","",ROW()-3) -> 13 | B16: =IFERROR('04A_국토부원자료'!B17,"") -> 서울특별시 송파구 가락동 | C16: =IF(B16="","",IF('04A_국토부원자료'!C17<>"",'04A_국토부원자료'!C17,TRIM('04A_국토부원자료'!D17&IF('04A_국토부원자료'!E17<>"","-"&'04A_국토부원자료'!E17,"")))) -> 98-2 | D16: =IFERROR('04A_국토부원자료'!F17,"") -> (98-2) | E16: =IFERROR(VALUE(SUBSTITUTE('04A_국토부원자료'!G17,",","")),"") -> 33.2 | F16: =IFERROR(IF(AND('04A_국토부원자료'!H17<>"",'04A_국토부원자료'!I17<>""),DATE(INT(VALUE(SUBSTITUTE('04A_국토부원자료'!H17,",",""))/100),MOD(VALUE(SUBSTITUTE('04A_국토부원자료'!H17,",","")),100),VALUE(SUBSTITUTE('04A_국토부원자료'!I17,",",""))),""),"") -> 46036 | G16: =IFERROR(VALUE(SUBSTITUTE('04A_국토부원자료'!J17,",","")),"") -> 11300 | H16: =IF(G16="","",G16*10000) -> 113000000 | I16: =IFERROR(IF(AND(H16>0,E16>0),H16/E16,""),"") -> 3403614.5 | J16: =IFERROR(VALUE(SUBSTITUTE('04A_국토부원자료'!K17,",","")),"") -> 5 | K16: =IFERROR(VALUE(SUBSTITUTE('04A_국토부원자료'!N17,",","")),"") -> 1990 | L16: =IFERROR('04A_국토부원자료'!O17,"") -> 송파대로30길 8 | M16: =IFERROR('04A_국토부원자료'!Q17,"") -> 중개거래 | N16: =IF(B16="","",IF('02_대상물건입력'!B5="",1,IF(ISNUMBER(SEARCH('02_대상물건입력'!B5,B16)),1,0))) -> 1 | O16: =IF(B16="","",IF('02_대상물건입력'!B6="",1,IF(ISNUMBER(SEARCH('02_대상물건입력'!B6,B16)),1,0))) -> 1 | P16: =IF(L16="","",IF('02_대상물건입력'!B15="",0,IF(ISNUMBER(SEARCH('02_대상물건입력'!B15,L16)),1,0))) -> 1 | Q16: =IF(D16="","",IF('02_대상물건입력'!B8="",0,IF(ISNUMBER(SEARCH('02_대상물건입력'!B8,D16)),1,0))) -> 0 | R16: =IFERROR(ABS(E16-'02_대상물건입력'!B11)/'02_대상물건입력'!B11,"") -> 0.21867062 | S16: =IFERROR(ABS(J16-'02_대상물건입력'!B10),"") -> 7 | T16: =IFERROR(ABS('01_설정'!B4-F16),"") -> 76 | U16: =IFERROR(ABS(K16-YEAR('02_대상물건입력'!B14)),"") -> 36 | V16: =IF(B16="","",IF(AND(E16>0,F16>0,H16>0,OR('04A_국토부원자료'!P17="",'04A_국토부원자료'!P17="-"),IF('01_설정'!B10=1,N16=1,TRUE),R16<='01_설정'!B5,S16<='01_설정'!B6,T16<='01_설정'!B7,U16<='01_설정'!B8),"Y","")) | W16: =IF(V16<>"Y","",MAX(0,(1-R16/'01_설정'!B5))*'01_설정'!B14+MAX(0,(1-S16/'01_설정'!B6))*'01_설정'!B15+MAX(0,(1-T16/'01_설정'!B7))*'01_설정'!B16+MAX(0,(1-U16/'01_설정'!B8))*'01_설정'!B17+O16*'01_설정'!B11+Q16*'01_설정'!B12+P16*'01_설정'!B13) | X16: =IF(W16="","",1+COUNTIFS($W$4:$W$3003,">"&W16)+COUNTIFS($W$4:W16,W16)-1)
A17: =IF('04A_국토부원자료'!A18="","",ROW()-3) -> 14 | B17: =IFERROR('04A_국토부원자료'!B18,"") -> 서울특별시 송파구 가락동 | C17: =IF(B17="","",IF('04A_국토부원자료'!C18<>"",'04A_국토부원자료'!C18,TRIM('04A_국토부원자료'!D18&IF('04A_국토부원자료'!E18<>"","-"&'04A_국토부원자료'!E18,"")))) -> 98-7 | D17: =IFERROR('04A_국토부원자료'!F18,"") -> (98-7) | E17: =IFERROR(VALUE(SUBSTITUTE('04A_국토부원자료'!G18,",","")),"") -> 35.24 | F17: =IFERROR(IF(AND('04A_국토부원자료'!H18<>"",'04A_국토부원자료'!I18<>""),DATE(INT(VALUE(SUBSTITUTE('04A_국토부원자료'!H18,",",""))/100),MOD(VALUE(SUBSTITUTE('04A_국토부원자료'!H18,",","")),100),VALUE(SUBSTITUTE('04A_국토부원자료'!I18,",",""))),""),"") -> 46029 | G17: =IFERROR(VALUE(SUBSTITUTE('04A_국토부원자료'!J18,",","")),"") -> 15900 | H17: =IF(G17="","",G17*10000) -> 159000000 | I17: =IFERROR(IF(AND(H17>0,E17>0),H17/E17,""),"") -> 4511918.3 | J17: =IFERROR(VALUE(SUBSTITUTE('04A_국토부원자료'!K18,",","")),"") -> 4 | K17: =IFERROR(VALUE(SUBSTITUTE('04A_국토부원자료'!N18,",","")),"") -> 1990 | L17: =IFERROR('04A_국토부원자료'!O18,"") -> 송파대로28길 13 | M17: =IFERROR('04A_국토부원자료'!Q18,"") -> 중개거래 | N17: =IF(B17="","",IF('02_대상물건입력'!B5="",1,IF(ISNUMBER(SEARCH('02_대상물건입력'!B5,B17)),1,0))) -> 1 | O17: =IF(B17="","",IF('02_대상물건입력'!B6="",1,IF(ISNUMBER(SEARCH('02_대상물건입력'!B6,B17)),1,0))) -> 1 | P17: =IF(L17="","",IF('02_대상물건입력'!B15="",0,IF(ISNUMBER(SEARCH('02_대상물건입력'!B15,L17)),1,0))) -> 1 | Q17: =IF(D17="","",IF('02_대상물건입력'!B8="",0,IF(ISNUMBER(SEARCH('02_대상물건입력'!B8,D17)),1,0))) -> 0 | R17: =IFERROR(ABS(E17-'02_대상물건입력'!B11)/'02_대상물건입력'!B11,"") -> 0.29355279 | S17: =IFERROR(ABS(J17-'02_대상물건입력'!B10),"") -> 8 | T17: =IFERROR(ABS('01_설정'!B4-F17),"") -> 83 | U17: =IFERROR(ABS(K17-YEAR('02_대상물건입력'!B14)),"") -> 36 | V17: =IF(B17="","",IF(AND(E17>0,F17>0,H17>0,OR('04A_국토부원자료'!P18="",'04A_국토부원자료'!P18="-"),IF('01_설정'!B10=1,N17=1,TRUE),R17<='01_설정'!B5,S17<='01_설정'!B6,T17<='01_설정'!B7,U17<='01_설정'!B8),"Y","")) | W17: =IF(V17<>"Y","",MAX(0,(1-R17/'01_설정'!B5))*'01_설정'!B14+MAX(0,(1-S17/'01_설정'!B6))*'01_설정'!B15+MAX(0,(1-T17/'01_설정'!B7))*'01_설정'!B16+MAX(0,(1-U17/'01_설정'!B8))*'01_설정'!B17+O17*'01_설정'!B11+Q17*'01_설정'!B12+P17*'01_설정'!B13) | X17: =IF(W17="","",1+COUNTIFS($W$4:$W$3003,">"&W17)+COUNTIFS($W$4:W17,W17)-1)
A18: =IF('04A_국토부원자료'!A19="","",ROW()-3) -> 15 | B18: =IFERROR('04A_국토부원자료'!B19,"") -> 서울특별시 송파구 가락동 | C18: =IF(B18="","",IF('04A_국토부원자료'!C19<>"",'04A_국토부원자료'!C19,TRIM('04A_국토부원자료'!D19&IF('04A_국토부원자료'!E19<>"","-"&'04A_국토부원자료'!E19,"")))) -> 98-7 | D18: =IFERROR('04A_국토부원자료'!F19,"") -> (98-7) | E18: =IFERROR(VALUE(SUBSTITUTE('04A_국토부원자료'!G19,",","")),"") -> 23.47 | F18: =IFERROR(IF(AND('04A_국토부원자료'!H19<>"",'04A_국토부원자료'!I19<>""),DATE(INT(VALUE(SUBSTITUTE('04A_국토부원자료'!H19,",",""))/100),MOD(VALUE(SUBSTITUTE('04A_국토부원자료'!H19,",","")),100),VALUE(SUBSTITUTE('04A_국토부원자료'!I19,",",""))),""),"") -> 46028 | G18: =IFERROR(VALUE(SUBSTITUTE('04A_국토부원자료'!J19,",","")),"") -> 9500 | H18: =IF(G18="","",G18*10000) -> 95000000 | I18: =IFERROR(IF(AND(H18>0,E18>0),H18/E18,""),"") -> 4047720.5 | J18: =IFERROR(VALUE(SUBSTITUTE('04A_국토부원자료'!K19,",","")),"") -> 10 | K18: =IFERROR(VALUE(SUBSTITUTE('04A_국토부원자료'!N19,",","")),"") -> 1990 | L18: =IFERROR('04A_국토부원자료'!O19,"") -> 송파대로28길 13 | M18: =IFERROR('04A_국토부원자료'!Q19,"") -> 중개거래 | N18: =IF(B18="","",IF('02_대상물건입력'!B5="",1,IF(ISNUMBER(SEARCH('02_대상물건입력'!B5,B18)),1,0))) -> 1 | O18: =IF(B18="","",IF('02_대상물건입력'!B6="",1,IF(ISNUMBER(SEARCH('02_대상물건입력'!B6,B18)),1,0))) -> 1 | P18: =IF(L18="","",IF('02_대상물건입력'!B15="",0,IF(ISNUMBER(SEARCH('02_대상물건입력'!B15,L18)),1,0))) -> 1 | Q18: =IF(D18="","",IF('02_대상물건입력'!B8="",0,IF(ISNUMBER(SEARCH('02_대상물건입력'!B8,D18)),1,0))) -> 0 | R18: =IFERROR(ABS(E18-'02_대상물건입력'!B11)/'02_대상물건입력'!B11,"") -> 0.13848797 | S18: =IFERROR(ABS(J18-'02_대상물건입력'!B10),"") -> 2 | T18: =IFERROR(ABS('01_설정'!B4-F18),"") -> 84 | U18: =IFERROR(ABS(K18-YEAR('02_대상물건입력'!B14)),"") -> 36 | V18: =IF(B18="","",IF(AND(E18>0,F18>0,H18>0,OR('04A_국토부원자료'!P19="",'04A_국토부원자료'!P19="-"),IF('01_설정'!B10=1,N18=1,TRUE),R18<='01_설정'!B5,S18<='01_설정'!B6,T18<='01_설정'!B7,U18<='01_설정'!B8),"Y","")) | W18: =IF(V18<>"Y","",MAX(0,(1-R18/'01_설정'!B5))*'01_설정'!B14+MAX(0,(1-S18/'01_설정'!B6))*'01_설정'!B15+MAX(0,(1-T18/'01_설정'!B7))*'01_설정'!B16+MAX(0,(1-U18/'01_설정'!B8))*'01_설정'!B17+O18*'01_설정'!B11+Q18*'01_설정'!B12+P18*'01_설정'!B13) | X18: =IF(W18="","",1+COUNTIFS($W$4:$W$3003,">"&W18)+COUNTIFS($W$4:W18,W18)-1)
A19: =IF('04A_국토부원자료'!A20="","",ROW()-3) -> 16 | B19: =IFERROR('04A_국토부원자료'!B20,"") -> 서울특별시 송파구 가락동 | C19: =IF(B19="","",IF('04A_국토부원자료'!C20<>"",'04A_국토부원자료'!C20,TRIM('04A_국토부원자료'!D20&IF('04A_국토부원자료'!E20<>"","-"&'04A_국토부원자료'!E20,"")))) -> 99-3 | D19: =IFERROR('04A_국토부원자료'!F20,"") -> 제일오피스텔 | E19: =IFERROR(VALUE(SUBSTITUTE('04A_국토부원자료'!G20,",","")),"") -> 25.39 | F19: =IFERROR(IF(AND('04A_국토부원자료'!H20<>"",'04A_국토부원자료'!I20<>""),DATE(INT(VALUE(SUBSTITUTE('04A_국토부원자료'!H20,",",""))/100),MOD(VALUE(SUBSTITUTE('04A_국토부원자료'!H20,",","")),100),VALUE(SUBSTITUTE('04A_국토부원자료'!I20,",",""))),""),"") -> 46022 | G19: =IFERROR(VALUE(SUBSTITUTE('04A_국토부원자료'!J20,",","")),"") -> 15000 | H19: =IF(G19="","",G19*10000) -> 150000000 | I19: =IFERROR(IF(AND(H19>0,E19>0),H19/E19,""),"") -> 5907837.7 | J19: =IFERROR(VALUE(SUBSTITUTE('04A_국토부원자료'!K20,",","")),"") -> 16 | K19: =IFERROR(VALUE(SUBSTITUTE('04A_국토부원자료'!N20,",","")),"") -> 1992 | L19: =IFERROR('04A_국토부원자료'!O20,"") -> 송파대로 260 | M19: =IFERROR('04A_국토부원자료'!Q20,"") -> 중개거래 | N19: =IF(B19="","",IF('02_대상물건입력'!B5="",1,IF(ISNUMBER(SEARCH('02_대상물건입력'!B5,B19)),1,0))) -> 1 | O19: =IF(B19="","",IF('02_대상물건입력'!B6="",1,IF(ISNUMBER(SEARCH('02_대상물건입력'!B6,B19)),1,0))) -> 1 | P19: =IF(L19="","",IF('02_대상물건입력'!B15="",0,IF(ISNUMBER(SEARCH('02_대상물건입력'!B15,L19)),1,0))) -> 1 | Q19: =IF(D19="","",IF('02_대상물건입력'!B8="",0,IF(ISNUMBER(SEARCH('02_대상물건입력'!B8,D19)),1,0))) -> 0 | R19: =IFERROR(ABS(E19-'02_대상물건입력'!B11)/'02_대상물건입력'!B11,"") -> 0.06801063 | S19: =IFERROR(ABS(J19-'02_대상물건입력'!B10),"") -> 4 | T19: =IFERROR(ABS('01_설정'!B4-F19),"") -> 90 | U19: =IFERROR(ABS(K19-YEAR('02_대상물건입력'!B14)),"") -> 34 | V19: =IF(B19="","",IF(AND(E19>0,F19>0,H19>0,OR('04A_국토부원자료'!P20="",'04A_국토부원자료'!P20="-"),IF('01_설정'!B10=1,N19=1,TRUE),R19<='01_설정'!B5,S19<='01_설정'!B6,T19<='01_설정'!B7,U19<='01_설정'!B8),"Y","")) | W19: =IF(V19<>"Y","",MAX(0,(1-R19/'01_설정'!B5))*'01_설정'!B14+MAX(0,(1-S19/'01_설정'!B6))*'01_설정'!B15+MAX(0,(1-T19/'01_설정'!B7))*'01_설정'!B16+MAX(0,(1-U19/'01_설정'!B8))*'01_설정'!B17+O19*'01_설정'!B11+Q19*'01_설정'!B12+P19*'01_설정'!B13) | X19: =IF(W19="","",1+COUNTIFS($W$4:$W$3003,">"&W19)+COUNTIFS($W$4:W19,W19)-1)
A20: =IF('04A_국토부원자료'!A21="","",ROW()-3) -> 17 | B20: =IFERROR('04A_국토부원자료'!B21,"") -> 서울특별시 송파구 가락동 | C20: =IF(B20="","",IF('04A_국토부원자료'!C21<>"",'04A_국토부원자료'!C21,TRIM('04A_국토부원자료'!D21&IF('04A_국토부원자료'!E21<>"","-"&'04A_국토부원자료'!E21,"")))) -> 78-1 | D20: =IFERROR('04A_국토부원자료'!F21,"") -> 한화오벨리스크 | E20: =IFERROR(VALUE(SUBSTITUTE('04A_국토부원자료'!G21,",","")),"") -> 37.93 | F20: =IFERROR(IF(AND('04A_국토부원자료'!H21<>"",'04A_국토부원자료'!I21<>""),DATE(INT(VALUE(SUBSTITUTE('04A_국토부원자료'!H21,",",""))/100),MOD(VALUE(SUBSTITUTE('04A_국토부원자료'!H21,",","")),100),VALUE(SUBSTITUTE('04A_국토부원자료'!I21,",",""))),""),"") -> 46011 | G20: =IFERROR(VALUE(SUBSTITUTE('04A_국토부원자료'!J21,",","")),"") -> 20200 | H20: =IF(G20="","",G20*10000) -> 202000000 | I20: =IFERROR(IF(AND(H20>0,E20>0),H20/E20,""),"") -> 5325599.8 | J20: =IFERROR(VALUE(SUBSTITUTE('04A_국토부원자료'!K21,",","")),"") -> 4 | K20: =IFERROR(VALUE(SUBSTITUTE('04A_국토부원자료'!N21,",","")),"") -> 2004 | L20: =IFERROR('04A_국토부원자료'!O21,"") -> 중대로 127 | M20: =IFERROR('04A_국토부원자료'!Q21,"") -> 중개거래 | N20: =IF(B20="","",IF('02_대상물건입력'!B5="",1,IF(ISNUMBER(SEARCH('02_대상물건입력'!B5,B20)),1,0))) -> 1 | O20: =IF(B20="","",IF('02_대상물건입력'!B6="",1,IF(ISNUMBER(SEARCH('02_대상물건입력'!B6,B20)),1,0))) -> 1 | P20: =IF(L20="","",IF('02_대상물건입력'!B15="",0,IF(ISNUMBER(SEARCH('02_대상물건입력'!B15,L20)),1,0))) -> 0 | Q20: =IF(D20="","",IF('02_대상물건입력'!B8="",0,IF(ISNUMBER(SEARCH('02_대상물건입력'!B8,D20)),1,0))) -> 0 | R20: =IFERROR(ABS(E20-'02_대상물건입력'!B11)/'02_대상물건입력'!B11,"") -> 0.39229448 | S20: =IFERROR(ABS(J20-'02_대상물건입력'!B10),"") -> 8 | T20: =IFERROR(ABS('01_설정'!B4-F20),"") -> 101 | U20: =IFERROR(ABS(K20-YEAR('02_대상물건입력'!B14)),"") -> 22 | V20: =IF(B20="","",IF(AND(E20>0,F20>0,H20>0,OR('04A_국토부원자료'!P21="",'04A_국토부원자료'!P21="-"),IF('01_설정'!B10=1,N20=1,TRUE),R20<='01_설정'!B5,S20<='01_설정'!B6,T20<='01_설정'!B7,U20<='01_설정'!B8),"Y","")) | W20: =IF(V20<>"Y","",MAX(0,(1-R20/'01_설정'!B5))*'01_설정'!B14+MAX(0,(1-S20/'01_설정'!B6))*'01_설정'!B15+MAX(0,(1-T20/'01_설정'!B7))*'01_설정'!B16+MAX(0,(1-U20/'01_설정'!B8))*'01_설정'!B17+O20*'01_설정'!B11+Q20*'01_설정'!B12+P20*'01_설정'!B13) | X20: =IF(W20="","",1+COUNTIFS($W$4:$W$3003,">"&W20)+COUNTIFS($W$4:W20,W20)-1)
A21: =IF('04A_국토부원자료'!A22="","",ROW()-3) -> 18 | B21: =IFERROR('04A_국토부원자료'!B22,"") -> 서울특별시 송파구 가락동 | C21: =IF(B21="","",IF('04A_국토부원자료'!C22<>"",'04A_국토부원자료'!C22,TRIM('04A_국토부원자료'!D22&IF('04A_국토부원자료'!E22<>"","-"&'04A_국토부원자료'!E22,"")))) -> 180-5 | D21: =IFERROR('04A_국토부원자료'!F22,"") -> (180-5) | E21: =IFERROR(VALUE(SUBSTITUTE('04A_국토부원자료'!G22,",","")),"") -> 38.58 | F21: =IFERROR(IF(AND('04A_국토부원자료'!H22<>"",'04A_국토부원자료'!I22<>""),DATE(INT(VALUE(SUBSTITUTE('04A_국토부원자료'!H22,",",""))/100),MOD(VALUE(SUBSTITUTE('04A_국토부원자료'!H22,",","")),100),VALUE(SUBSTITUTE('04A_국토부원자료'!I22,",",""))),""),"") -> 46008 | G21: =IFERROR(VALUE(SUBSTITUTE('04A_국토부원자료'!J22,",","")),"") -> 13500 | H21: =IF(G21="","",G21*10000) -> 135000000 | I21: =IFERROR(IF(AND(H21>0,E21>0),H21/E21,""),"") -> 3499222.4 | J21: =IFERROR(VALUE(SUBSTITUTE('04A_국토부원자료'!K22,",","")),"") -> 8 | K21: =IFERROR(VALUE(SUBSTITUTE('04A_국토부원자료'!N22,",","")),"") -> 2002 | L21: =IFERROR('04A_국토부원자료'!O22,"") -> 문정로 151 | M21: =IFERROR('04A_국토부원자료'!Q22,"") -> 중개거래 | N21: =IF(B21="","",IF('02_대상물건입력'!B5="",1,IF(ISNUMBER(SEARCH('02_대상물건입력'!B5,B21)),1,0))) -> 1 | O21: =IF(B21="","",IF('02_대상물건입력'!B6="",1,IF(ISNUMBER(SEARCH('02_대상물건입력'!B6,B21)),1,0))) -> 1 | P21: =IF(L21="","",IF('02_대상물건입력'!B15="",0,IF(ISNUMBER(SEARCH('02_대상물건입력'!B15,L21)),1,0))) -> 0 | Q21: =IF(D21="","",IF('02_대상물건입력'!B8="",0,IF(ISNUMBER(SEARCH('02_대상물건입력'!B8,D21)),1,0))) -> 0 | R21: =IFERROR(ABS(E21-'02_대상물건입력'!B11)/'02_대상물건입력'!B11,"") -> 0.41615399 | S21: =IFERROR(ABS(J21-'02_대상물건입력'!B10),"") -> 4 | T21: =IFERROR(ABS('01_설정'!B4-F21),"") -> 104 | U21: =IFERROR(ABS(K21-YEAR('02_대상물건입력'!B14)),"") -> 24 | V21: =IF(B21="","",IF(AND(E21>0,F21>0,H21>0,OR('04A_국토부원자료'!P22="",'04A_국토부원자료'!P22="-"),IF('01_설정'!B10=1,N21=1,TRUE),R21<='01_설정'!B5,S21<='01_설정'!B6,T21<='01_설정'!B7,U21<='01_설정'!B8),"Y","")) | W21: =IF(V21<>"Y","",MAX(0,(1-R21/'01_설정'!B5))*'01_설정'!B14+MAX(0,(1-S21/'01_설정'!B6))*'01_설정'!B15+MAX(0,(1-T21/'01_설정'!B7))*'01_설정'!B16+MAX(0,(1-U21/'01_설정'!B8))*'01_설정'!B17+O21*'01_설정'!B11+Q21*'01_설정'!B12+P21*'01_설정'!B13) | X21: =IF(W21="","",1+COUNTIFS($W$4:$W$3003,">"&W21)+COUNTIFS($W$4:W21,W21)-1)
A22: =IF('04A_국토부원자료'!A23="","",ROW()-3) -> 19 | B22: =IFERROR('04A_국토부원자료'!B23,"") -> 서울특별시 송파구 가락동 | C22: =IF(B22="","",IF('04A_국토부원자료'!C23<>"",'04A_국토부원자료'!C23,TRIM('04A_국토부원자료'!D23&IF('04A_국토부원자료'!E23<>"","-"&'04A_국토부원자료'!E23,"")))) -> 79-7 | D22: =IFERROR('04A_국토부원자료'!F23,"") -> (79-7) | E22: =IFERROR(VALUE(SUBSTITUTE('04A_국토부원자료'!G23,",","")),"") -> 29.52 | F22: =IFERROR(IF(AND('04A_국토부원자료'!H23<>"",'04A_국토부원자료'!I23<>""),DATE(INT(VALUE(SUBSTITUTE('04A_국토부원자료'!H23,",",""))/100),MOD(VALUE(SUBSTITUTE('04A_국토부원자료'!H23,",","")),100),VALUE(SUBSTITUTE('04A_국토부원자료'!I23,",",""))),""),"") -> 46007 | G22: =IFERROR(VALUE(SUBSTITUTE('04A_국토부원자료'!J23,",","")),"") -> 13000 | H22: =IF(G22="","",G22*10000) -> 130000000 | I22: =IFERROR(IF(AND(H22>0,E22>0),H22/E22,""),"") -> 4403794 | J22: =IFERROR(VALUE(SUBSTITUTE('04A_국토부원자료'!K23,",","")),"") -> 4 | K22: =IFERROR(VALUE(SUBSTITUTE('04A_국토부원자료'!N23,",","")),"") -> 1990 | L22: =IFERROR('04A_국토부원자료'!O23,"") -> 송파대로28길 32 | M22: =IFERROR('04A_국토부원자료'!Q23,"") -> 직거래 | N22: =IF(B22="","",IF('02_대상물건입력'!B5="",1,IF(ISNUMBER(SEARCH('02_대상물건입력'!B5,B22)),1,0))) -> 1 | O22: =IF(B22="","",IF('02_대상물건입력'!B6="",1,IF(ISNUMBER(SEARCH('02_대상물건입력'!B6,B22)),1,0))) -> 1 | P22: =IF(L22="","",IF('02_대상물건입력'!B15="",0,IF(ISNUMBER(SEARCH('02_대상물건입력'!B15,L22)),1,0))) -> 1 | Q22: =IF(D22="","",IF('02_대상물건입력'!B8="",0,IF(ISNUMBER(SEARCH('02_대상물건입력'!B8,D22)),1,0))) -> 0 | R22: =IFERROR(ABS(E22-'02_대상물건입력'!B11)/'02_대상물건입력'!B11,"") -> 0.083589058 | S22: =IFERROR(ABS(J22-'02_대상물건입력'!B10),"") -> 8 | T22: =IFERROR(ABS('01_설정'!B4-F22),"") -> 105 | U22: =IFERROR(ABS(K22-YEAR('02_대상물건입력'!B14)),"") -> 36 | V22: =IF(B22="","",IF(AND(E22>0,F22>0,H22>0,OR('04A_국토부원자료'!P23="",'04A_국토부원자료'!P23="-"),IF('01_설정'!B10=1,N22=1,TRUE),R22<='01_설정'!B5,S22<='01_설정'!B6,T22<='01_설정'!B7,U22<='01_설정'!B8),"Y","")) | W22: =IF(V22<>"Y","",MAX(0,(1-R22/'01_설정'!B5))*'01_설정'!B14+MAX(0,(1-S22/'01_설정'!B6))*'01_설정'!B15+MAX(0,(1-T22/'01_설정'!B7))*'01_설정'!B16+MAX(0,(1-U22/'01_설정'!B8))*'01_설정'!B17+O22*'01_설정'!B11+Q22*'01_설정'!B12+P22*'01_설정'!B13) | X22: =IF(W22="","",1+COUNTIFS($W$4:$W$3003,">"&W22)+COUNTIFS($W$4:W22,W22)-1)
A23: =IF('04A_국토부원자료'!A24="","",ROW()-3) -> 20 | B23: =IFERROR('04A_국토부원자료'!B24,"") -> 서울특별시 송파구 가락동 | C23: =IF(B23="","",IF('04A_국토부원자료'!C24<>"",'04A_국토부원자료'!C24,TRIM('04A_국토부원자료'!D24&IF('04A_국토부원자료'!E24<>"","-"&'04A_국토부원자료'!E24,"")))) -> 79-7 | D23: =IFERROR('04A_국토부원자료'!F24,"") -> (79-7) | E23: =IFERROR(VALUE(SUBSTITUTE('04A_국토부원자료'!G24,",","")),"") -> 34.44 | F23: =IFERROR(IF(AND('04A_국토부원자료'!H24<>"",'04A_국토부원자료'!I24<>""),DATE(INT(VALUE(SUBSTITUTE('04A_국토부원자료'!H24,",",""))/100),MOD(VALUE(SUBSTITUTE('04A_국토부원자료'!H24,",","")),100),VALUE(SUBSTITUTE('04A_국토부원자료'!I24,",",""))),""),"") -> 46007 | G23: =IFERROR(VALUE(SUBSTITUTE('04A_국토부원자료'!J24,",","")),"") -> 16000 | H23: =IF(G23="","",G23*10000) -> 160000000 | I23: =IFERROR(IF(AND(H23>0,E23>0),H23/E23,""),"") -> 4645760.7 | J23: =IFERROR(VALUE(SUBSTITUTE('04A_국토부원자료'!K24,",","")),"") -> 5 | K23: =IFERROR(VALUE(SUBSTITUTE('04A_국토부원자료'!N24,",","")),"") -> 1990 | L23: =IFERROR('04A_국토부원자료'!O24,"") -> 송파대로28길 32 | M23: =IFERROR('04A_국토부원자료'!Q24,"") -> 직거래 | N23: =IF(B23="","",IF('02_대상물건입력'!B5="",1,IF(ISNUMBER(SEARCH('02_대상물건입력'!B5,B23)),1,0))) -> 1 | O23: =IF(B23="","",IF('02_대상물건입력'!B6="",1,IF(ISNUMBER(SEARCH('02_대상물건입력'!B6,B23)),1,0))) -> 1 | P23: =IF(L23="","",IF('02_대상물건입력'!B15="",0,IF(ISNUMBER(SEARCH('02_대상물건입력'!B15,L23)),1,0))) -> 1 | Q23: =IF(D23="","",IF('02_대상물건입력'!B8="",0,IF(ISNUMBER(SEARCH('02_대상물건입력'!B8,D23)),1,0))) -> 0 | R23: =IFERROR(ABS(E23-'02_대상물건입력'!B11)/'02_대상물건입력'!B11,"") -> 0.26418723 | S23: =IFERROR(ABS(J23-'02_대상물건입력'!B10),"") -> 7 | T23: =IFERROR(ABS('01_설정'!B4-F23),"") -> 105 | U23: =IFERROR(ABS(K23-YEAR('02_대상물건입력'!B14)),"") -> 36 | V23: =IF(B23="","",IF(AND(E23>0,F23>0,H23>0,OR('04A_국토부원자료'!P24="",'04A_국토부원자료'!P24="-"),IF('01_설정'!B10=1,N23=1,TRUE),R23<='01_설정'!B5,S23<='01_설정'!B6,T23<='01_설정'!B7,U23<='01_설정'!B8),"Y","")) | W23: =IF(V23<>"Y","",MAX(0,(1-R23/'01_설정'!B5))*'01_설정'!B14+MAX(0,(1-S23/'01_설정'!B6))*'01_설정'!B15+MAX(0,(1-T23/'01_설정'!B7))*'01_설정'!B16+MAX(0,(1-U23/'01_설정'!B8))*'01_설정'!B17+O23*'01_설정'!B11+Q23*'01_설정'!B12+P23*'01_설정'!B13) | X23: =IF(W23="","",1+COUNTIFS($W$4:$W$3003,">"&W23)+COUNTIFS($W$4:W23,W23)-1)
A24: =IF('04A_국토부원자료'!A25="","",ROW()-3) -> 21 | B24: =IFERROR('04A_국토부원자료'!B25,"") -> 서울특별시 송파구 가락동 | C24: =IF(B24="","",IF('04A_국토부원자료'!C25<>"",'04A_국토부원자료'!C25,TRIM('04A_국토부원자료'!D25&IF('04A_국토부원자료'!E25<>"","-"&'04A_국토부원자료'!E25,"")))) -> 79-7 | D24: =IFERROR('04A_국토부원자료'!F25,"") -> (79-7) | E24: =IFERROR(VALUE(SUBSTITUTE('04A_국토부원자료'!G25,",","")),"") -> 29.52 | F24: =IFERROR(IF(AND('04A_국토부원자료'!H25<>"",'04A_국토부원자료'!I25<>""),DATE(INT(VALUE(SUBSTITUTE('04A_국토부원자료'!H25,",",""))/100),MOD(VALUE(SUBSTITUTE('04A_국토부원자료'!H25,",","")),100),VALUE(SUBSTITUTE('04A_국토부원자료'!I25,",",""))),""),"") -> 46007 | G24: =IFERROR(VALUE(SUBSTITUTE('04A_국토부원자료'!J25,",","")),"") -> 13000 | H24: =IF(G24="","",G24*10000) -> 130000000 | I24: =IFERROR(IF(AND(H24>0,E24>0),H24/E24,""),"") -> 4403794 | J24: =IFERROR(VALUE(SUBSTITUTE('04A_국토부원자료'!K25,",","")),"") -> 3 | K24: =IFERROR(VALUE(SUBSTITUTE('04A_국토부원자료'!N25,",","")),"") -> 1990 | L24: =IFERROR('04A_국토부원자료'!O25,"") -> 송파대로28길 32 | M24: =IFERROR('04A_국토부원자료'!Q25,"") -> 직거래 | N24: =IF(B24="","",IF('02_대상물건입력'!B5="",1,IF(ISNUMBER(SEARCH('02_대상물건입력'!B5,B24)),1,0))) -> 1 | O24: =IF(B24="","",IF('02_대상물건입력'!B6="",1,IF(ISNUMBER(SEARCH('02_대상물건입력'!B6,B24)),1,0))) -> 1 | P24: =IF(L24="","",IF('02_대상물건입력'!B15="",0,IF(ISNUMBER(SEARCH('02_대상물건입력'!B15,L24)),1,0))) -> 1 | Q24: =IF(D24="","",IF('02_대상물건입력'!B8="",0,IF(ISNUMBER(SEARCH('02_대상물건입력'!B8,D24)),1,0))) -> 0 | R24: =IFERROR(ABS(E24-'02_대상물건입력'!B11)/'02_대상물건입력'!B11,"") -> 0.083589058 | S24: =IFERROR(ABS(J24-'02_대상물건입력'!B10),"") -> 9 | T24: =IFERROR(ABS('01_설정'!B4-F24),"") -> 105 | U24: =IFERROR(ABS(K24-YEAR('02_대상물건입력'!B14)),"") -> 36 | V24: =IF(B24="","",IF(AND(E24>0,F24>0,H24>0,OR('04A_국토부원자료'!P25="",'04A_국토부원자료'!P25="-"),IF('01_설정'!B10=1,N24=1,TRUE),R24<='01_설정'!B5,S24<='01_설정'!B6,T24<='01_설정'!B7,U24<='01_설정'!B8),"Y","")) | W24: =IF(V24<>"Y","",MAX(0,(1-R24/'01_설정'!B5))*'01_설정'!B14+MAX(0,(1-S24/'01_설정'!B6))*'01_설정'!B15+MAX(0,(1-T24/'01_설정'!B7))*'01_설정'!B16+MAX(0,(1-U24/'01_설정'!B8))*'01_설정'!B17+O24*'01_설정'!B11+Q24*'01_설정'!B12+P24*'01_설정'!B13) | X24: =IF(W24="","",1+COUNTIFS($W$4:$W$3003,">"&W24)+COUNTIFS($W$4:W24,W24)-1)
A25: =IF('04A_국토부원자료'!A26="","",ROW()-3) -> 22 | B25: =IFERROR('04A_국토부원자료'!B26,"") -> 서울특별시 송파구 가락동 | C25: =IF(B25="","",IF('04A_국토부원자료'!C26<>"",'04A_국토부원자료'!C26,TRIM('04A_국토부원자료'!D26&IF('04A_국토부원자료'!E26<>"","-"&'04A_국토부원자료'!E26,"")))) -> 79-7 | D25: =IFERROR('04A_국토부원자료'!F26,"") -> (79-7) | E25: =IFERROR(VALUE(SUBSTITUTE('04A_국토부원자료'!G26,",","")),"") -> 29.52 | F25: =IFERROR(IF(AND('04A_국토부원자료'!H26<>"",'04A_국토부원자료'!I26<>""),DATE(INT(VALUE(SUBSTITUTE('04A_국토부원자료'!H26,",",""))/100),MOD(VALUE(SUBSTITUTE('04A_국토부원자료'!H26,",","")),100),VALUE(SUBSTITUTE('04A_국토부원자료'!I26,",",""))),""),"") -> 46007 | G25: =IFERROR(VALUE(SUBSTITUTE('04A_국토부원자료'!J26,",","")),"") -> 13000 | H25: =IF(G25="","",G25*10000) -> 130000000 | I25: =IFERROR(IF(AND(H25>0,E25>0),H25/E25,""),"") -> 4403794 | J25: =IFERROR(VALUE(SUBSTITUTE('04A_국토부원자료'!K26,",","")),"") -> 3 | K25: =IFERROR(VALUE(SUBSTITUTE('04A_국토부원자료'!N26,",","")),"") -> 1990 | L25: =IFERROR('04A_국토부원자료'!O26,"") -> 송파대로28길 32 | M25: =IFERROR('04A_국토부원자료'!Q26,"") -> 직거래 | N25: =IF(B25="","",IF('02_대상물건입력'!B5="",1,IF(ISNUMBER(SEARCH('02_대상물건입력'!B5,B25)),1,0))) -> 1 | O25: =IF(B25="","",IF('02_대상물건입력'!B6="",1,IF(ISNUMBER(SEARCH('02_대상물건입력'!B6,B25)),1,0))) -> 1 | P25: =IF(L25="","",IF('02_대상물건입력'!B15="",0,IF(ISNUMBER(SEARCH('02_대상물건입력'!B15,L25)),1,0))) -> 1 | Q25: =IF(D25="","",IF('02_대상물건입력'!B8="",0,IF(ISNUMBER(SEARCH('02_대상물건입력'!B8,D25)),1,0))) -> 0 | R25: =IFERROR(ABS(E25-'02_대상물건입력'!B11)/'02_대상물건입력'!B11,"") -> 0.083589058 | S25: =IFERROR(ABS(J25-'02_대상물건입력'!B10),"") -> 9 | T25: =IFERROR(ABS('01_설정'!B4-F25),"") -> 105 | U25: =IFERROR(ABS(K25-YEAR('02_대상물건입력'!B14)),"") -> 36 | V25: =IF(B25="","",IF(AND(E25>0,F25>0,H25>0,OR('04A_국토부원자료'!P26="",'04A_국토부원자료'!P26="-"),IF('01_설정'!B10=1,N25=1,TRUE),R25<='01_설정'!B5,S25<='01_설정'!B6,T25<='01_설정'!B7,U25<='01_설정'!B8),"Y","")) | W25: =IF(V25<>"Y","",MAX(0,(1-R25/'01_설정'!B5))*'01_설정'!B14+MAX(0,(1-S25/'01_설정'!B6))*'01_설정'!B15+MAX(0,(1-T25/'01_설정'!B7))*'01_설정'!B16+MAX(0,(1-U25/'01_설정'!B8))*'01_설정'!B17+O25*'01_설정'!B11+Q25*'01_설정'!B12+P25*'01_설정'!B13) | X25: =IF(W25="","",1+COUNTIFS($W$4:$W$3003,">"&W25)+COUNTIFS($W$4:W25,W25)-1)
A26: =IF('04A_국토부원자료'!A27="","",ROW()-3) -> 23 | B26: =IFERROR('04A_국토부원자료'!B27,"") -> 서울특별시 송파구 가락동 | C26: =IF(B26="","",IF('04A_국토부원자료'!C27<>"",'04A_국토부원자료'!C27,TRIM('04A_국토부원자료'!D27&IF('04A_국토부원자료'!E27<>"","-"&'04A_국토부원자료'!E27,"")))) -> 78-1 | D26: =IFERROR('04A_국토부원자료'!F27,"") -> 한화오벨리스크 | E26: =IFERROR(VALUE(SUBSTITUTE('04A_국토부원자료'!G27,",","")),"") -> 30.34 | F26: =IFERROR(IF(AND('04A_국토부원자료'!H27<>"",'04A_국토부원자료'!I27<>""),DATE(INT(VALUE(SUBSTITUTE('04A_국토부원자료'!H27,",",""))/100),MOD(VALUE(SUBSTITUTE('04A_국토부원자료'!H27,",","")),100),VALUE(SUBSTITUTE('04A_국토부원자료'!I27,",",""))),""),"") -> 45993 | G26: =IFERROR(VALUE(SUBSTITUTE('04A_국토부원자료'!J27,",","")),"") -> 12000 | H26: =IF(G26="","",G26*10000) -> 120000000 | I26: =IFERROR(IF(AND(H26>0,E26>0),H26/E26,""),"") -> 3955174.7 | J26: =IFERROR(VALUE(SUBSTITUTE('04A_국토부원자료'!K27,",","")),"") -> 14 | K26: =IFERROR(VALUE(SUBSTITUTE('04A_국토부원자료'!N27,",","")),"") -> 2004 | L26: =IFERROR('04A_국토부원자료'!O27,"") -> 중대로 127 | M26: =IFERROR('04A_국토부원자료'!Q27,"") -> 직거래 | N26: =IF(B26="","",IF('02_대상물건입력'!B5="",1,IF(ISNUMBER(SEARCH('02_대상물건입력'!B5,B26)),1,0))) -> 1 | O26: =IF(B26="","",IF('02_대상물건입력'!B6="",1,IF(ISNUMBER(SEARCH('02_대상물건입력'!B6,B26)),1,0))) -> 1 | P26: =IF(L26="","",IF('02_대상물건입력'!B15="",0,IF(ISNUMBER(SEARCH('02_대상물건입력'!B15,L26)),1,0))) -> 0 | Q26: =IF(D26="","",IF('02_대상물건입력'!B8="",0,IF(ISNUMBER(SEARCH('02_대상물건입력'!B8,D26)),1,0))) -> 0 | R26: =IFERROR(ABS(E26-'02_대상물건입력'!B11)/'02_대상물건입력'!B11,"") -> 0.11368875 | S26: =IFERROR(ABS(J26-'02_대상물건입력'!B10),"") -> 2 | T26: =IFERROR(ABS('01_설정'!B4-F26),"") -> 119 | U26: =IFERROR(ABS(K26-YEAR('02_대상물건입력'!B14)),"") -> 22 | V26: =IF(B26="","",IF(AND(E26>0,F26>0,H26>0,OR('04A_국토부원자료'!P27="",'04A_국토부원자료'!P27="-"),IF('01_설정'!B10=1,N26=1,TRUE),R26<='01_설정'!B5,S26<='01_설정'!B6,T26<='01_설정'!B7,U26<='01_설정'!B8),"Y","")) | W26: =IF(V26<>"Y","",MAX(0,(1-R26/'01_설정'!B5))*'01_설정'!B14+MAX(0,(1-S26/'01_설정'!B6))*'01_설정'!B15+MAX(0,(1-T26/'01_설정'!B7))*'01_설정'!B16+MAX(0,(1-U26/'01_설정'!B8))*'01_설정'!B17+O26*'01_설정'!B11+Q26*'01_설정'!B12+P26*'01_설정'!B13) | X26: =IF(W26="","",1+COUNTIFS($W$4:$W$3003,">"&W26)+COUNTIFS($W$4:W26,W26)-1)
