Workbook
Name 연율: '01_설정'!$B$19

Sheet 00_사용설명서
A1: 집합건물 자동평가 엑셀 템플릿 (국토부 실거래가 → 자동선정 → 요인보정 → 건물/대지권 배분)
A3: 목적 | B3: 국토부 실거래가 자료를 복사/붙여넣기 하면 유사 거래사례를 자동으로 필터링하고, 개별요인 보정 후 집합건물의 총가치·대지권가격·건물가격을 산출하는 템플릿
A5: 사용 순서
A6: 1 | B6: 1) 01_설정 시트에서 기준시점·허용오차·대지권/건물 배분용 원가 가정을 확인합니다.
A7: 2 | B7: 2) 02_대상물건입력 시트에서 시군구/법정동/건물명/전유면적/대지권면적/층/사용승인일자 등을 입력합니다.
A8: 3 | B8: 3) 04A_국토부원자료 시트의 5행부터 국토부 실거래가 원문 데이터를 붙여넣습니다. 헤더는 4행의 고정 형식을 그대로 사용합니다.
A9: 4 | B9: 4) 04B_정규화_자동필터 시트에서 1차 필터 통과 여부와 유사도 순위를 자동 산정합니다.
A10: 5 | B10: 5) 05_자동선정_유사도 시트에서 상위 사례를 확인합니다.
A11: 6 | B11: 6) 06_요인비교_보정 시트에서 사정보정/기타요인 Override가 필요한 경우만 입력합니다. 나머지는 자동값을 사용합니다.
A12: 7 | B12: 7) 07_대지권_건물배분 시트에서 총가치, 대지권가격, 건물가격을 확인합니다.
A13: 8 | B13: 8) 08_평가결론 시트에서 보고용 요약값을 확인합니다.
A14: 9 | B14: 9) 05B_KAIS_사례선정 시트에서 KAIS 거래사례 상위 유사건을 자동 확인합니다.
A15: 10 | B15: 10) 05C_KAPA_선례선정 시트에서 KAPA 선례 상위 유사건을 자동 확인합니다.
A16: 붙여넣기 데이터 형식 (04A_국토부원자료 / 4행 헤더 고정)
A17: A:NO
A18: B:시군구
A19: C:번지
A20: D:본번
A21: E:부번
A22: F:단지명
A23: G:전용면적(㎡)
A24: H:계약년월
A25: I:계약일
A26: J:거래금액(만원)
A27: K:층
... A39: 실거래가 원문 헤더는 현재 템플릿의 4행 형식에 맞춰 고정되어 있으므로, 5행부터 값만 붙여넣으면 됩니다.

Sheet 01_설정
A1: 설정 및 통제변수
A3: 항목 | B3: 값 | C3: 설명
A4: 기준시점 | B4: 46122 | C4: 대상물건 평가 기준시점
A5: 면적 허용오차 | B5: 0.3 | C5: 전유면적 차율 허용범위
A6: 층 허용차이 | B6: 4 | C6: 층차 허용범위
A7: 최대 경과일수 | B7: 450 | C7: 계약일~기준시점 허용일수
A8: 건축연차 허용차이 | B8: 5 | C8: 건축년도 차이 허용범위
A9: 상위 반영 건수 | B9: 30 | C9: 요인보정에 반영할 비교사례 수
A10: 동일 시군구 필수 | B10: 1 | C10: 1이면 대상 시군구 키워드 포함 사례만 반영
A11: 동일 법정동 가점 | B11: 15 | C11: 법정동 일치 시 가점
A12: 동일건물 가점 | B12: 15 | C12: 건물명 유사 시 가점
A13: 동일도로명 가점 | B13: 5 | C13: 도로명 일치 시 가점
A14: 면적점수 가중치 | B14: 0 | C14: 유사도 배점
A15: 층점수 가중치 | B15: 20 | C15: 유사도 배점
... A32: 예상단가 허용오차 | B32: 0.2 | C32: 예상단가 차율 허용범위(20%=0.2)

Sheet 02_대상물건입력
A1: 대상물건 입력
A3: 항목 | B3: 입력값 | C3: 설명 | D3: 비고
A4: 평가서명 | B4: 서울특별시 서초구 서초동 1620-20 | C4: 입력
A5: 시군구 키워드 | B5: 서울특별시 서초구 서초동 | C5: 자동필터용 | D5: 예: 서울특별시 송파구
A6: 법정동 키워드 | B6: 서초동 | C6: 자동필터용 | D6: 예: 가락동
A7: 소재지 | B7: 서울특별시 서초구 서초동 1620-20 | C7: 입력
A8: 건물명 | B8: 서초동롯데캐슬리버티 101동 | C8: 입력
A9: 동·호 | B9: 604호 | C9: 입력
A10: 층 | B10: 6 | C10: 입력
A11: 전유면적(㎡) | B11: 125.79 | C11: 입력
A12: 공용면적(㎡) | B12: =1.49+18.69+6.73 | C12: 입력
A13: 대지권면적(㎡) | B13: 64.18 | C13: 입력
A14: 사용승인일자 | B14: 38434 | C14: 입력
A15: 도로명 키워드 | B15: 사임당로10길 | C15: 자동필터용 | D15: 도로명 일부 가능
A16: 용도 | B16: 아파트 | C16: 입력
A17: 기타요인 계수 | B17: 1 | C17: 입력 | D17: 특이사항 있을 때만 조정
A18: 비고 | B18: 예시 데이터가 입력되어 있습니다. 실제 대상물건으로 덮어쓰면 전체 시트가 연동됩니다. | C18: 입력
A19: 예상단가(원/㎡) | B19: 16000000 | C19: 입력 | D19: 사례선정 가중치 반영용 (미입력 시 제외)
A21: 자동 계산
A22: 건축년도 | B22: =IFERROR(YEAR(B14),"") | C22: 자동
A23: 분양면적(㎡) | B23: =IFERROR(B11+B12,"") | C23: 자동
A24: 전유율 | B24: =IFERROR(B11/B23,"") | C24: 자동
A25: 대지권 기준금액(원) | B25: =IFERROR(B13*'01_설정'!B26,"") | C25: 토지단가 × 대지권면적
A26: 건물 기준금액(원) | B26: =IFERROR(B11*'01_설정'!B27*'01_설정'!B28,"") | C26: 재조달원가 × 전유면적 × 잔존율
A27: 원가기준 토지비율 | B27: =IFERROR(MIN(MAX(B25/(B25+B26),'01_설정'!B29),'01_설정'!B30),"") | C27: 배분비율
A28: 원가기준 건물비율 | B28: =IFERROR(1-B27,"") | C28: 배분비율

Sheet 03_가치형성요인기준
A1: 가치형성요인 기준표
A3: 자동 보정 로직(기본 프록시)
A4: 구분 | B4: 기준 | C4: 자동값 | D4: 설명 | E4: 실무 Override
A5: 사정보정 | B5: 특이 거래 여부 | C5: ='01_설정'!B18 | D5: 기본 1.00, 특이 거래면 06시트에서 직접 수정 | E5: 06시트 G열
A6: 시점수정 | B6: 기준시점 대비 계약일 경과 | C6: =(1+연율)^(경과일수/365) | D6: 기준시점 이후로 환산 | E6: 보통 자동 사용
A7: 외부요인 | B7: 법정동/도로명 일치 여부 | C7: 동일 법정동이면 1.00, 타동이면 0.98, 동일도로명이면 +1.01 | D7: 역세권/상권 차이는 수동 검토 권장 | E7: 06시트 J열
A8: 내부요인 | B8: 동일건물/건축연차 | C8: 동일건물 1.02, 건축연차 우열 1.01 또는 0.99 | D8: 브랜드/세대수/관리상태는 수동 검토 권장 | E8: 06시트 L열
A9: 호별요인 | B9: 층차 | C9: 층이 높으면 0.99~0.98, 낮으면 1.01~1.02 | D9: 향·조망은 필요 시 Override | E9: 06시트 N열
A10: 기타요인 | B10: 특이 개별요인 | C10: ='02_대상물건입력'!B17 | D10: 특별한 권리관계/리모델링 등 | E10: 06시트 P열
A11: 대지권/건물 배분 | B11: 원가배분 방식 | C11: 토지기준금액 / (토지기준금액 + 건물기준금액) | D11: 비율 하한/상한 적용 | E11: 01/07시트

Sheet 04A_국토부원자료
A1: 국토부 실거래가 원자료 붙여넣기
A2: ※ 5행부터 값만 붙여넣으세요. 4행 헤더는 NO, 시군구, 번지, 본번, 부번, 단지명, 전용면적(㎡), 계약년월, 계약일, 거래금액(만원), 동, 층, 매수자, 매도자, 건축년도, 도로명, 해제사유발생일, 거래유형, 중개사소재지, 등기일자, 주택유형 순서입니다.
A4: NO | B4: 시군구 | C4: 번지 | D4: 본번 | E4: 부번 | F4: 단지명 | G4: 전용면적(㎡) | H4: 계약년월 | I4: 계약일 | J4: 거래금액(만원) | K4: 동 | L4: 층 | M4: 매수자 | N4: 매도자 | O4: 건축년도 | P4: 도로명 | Q4: 해제사유발생일 | R4: 거래유형 | S4: 중개사소재지 | T4: 등기일자 | U4: 주택유형
A5: 1 | B5: 서울특별시 서초구 서초동 | C5: 1330 | D5: 1330 | E5: 0000 | F5: 서초동삼성쉐르빌2 | G5: 35.1700 | H5: 202404 | I5: 09 | J5: 32,900 | K5: - | L5: 21 | M5: 개인 | N5: 개인 | O5: 2002 | P5: 강남대로53길 11 | Q5: - | R5: 중개거래 | S5: 서울 서초구 | T5: 24.06.18 | U5: 아파트
A6: 2 | B6: 서울특별시 서초구 서초동 | C6: 1671-5 | D6: 1671 | E6: 0005 | F6: 대림서초리시온 | G6: 45.7200 | H6: 202404 | I6: 09 | J6: 45,000 | K6: - | L6: 9 | M6: 개인 | N6: 개인 | O6: 2003 | P6: 서초중앙로22길 25 | Q6: - | R6: 중개거래 | S6: 서울 서초구 | T6: 24.06.12 | U6: 아파트
A7: 3 | B7: 서울특별시 서초구 서초동 | C7: 1344-13 | D7: 1344 | E7: 0013 | F7: 서초트라팰리스 | G7: 95.5800 | H7: 202404 | I7: 09 | J7: 187,500 | K7: A | L7: 14 | M7: 개인 | N7: 개인 | O7: 2005 | P7: 효령로72길 57 | Q7: - | R7: 중개거래 | S7: 서울 서초구 | T7: 24.06.28 | U7: 아파트
A8: 4 | B8: 서울특별시 서초구 서초동 | C8: 1326-17 | D8: 1326 | E8: 0017 | F8: 우성아파트 | G8: 59.9300 | H8: 202404 | I8: 08 | J8: 153,000 | K8: 501 | L8: 20 | M8: 개인 | N8: 개인 | O8: 1998 | P8: 서초대로74길 30 | Q8: - | R8: 중개거래 | S8: 서울 서초구 | T8: 24.07.25 | U8: 아파트
A9: 5 | B9: 서울특별시 서초구 서초동 | C9: 1316-31 | D9: 1316 | E9: 0031 | F9: 밀라텔쉐르빌 | G9: 50.2800 | H9: 202404 | I9: 08 | J9: 72,000 | K9: - | L9: 10 | M9: 개인 | N9: 개인 | O9: 2001 | P9: 강남대로61길 17 | Q9: - | R9: 중개거래 | S9: 서울 서초구 | T9: 24.07.02 | U9: 아파트
A10: 6 | B10: 서울특별시 서초구 서초동 | C10: 1467-97 | D10: 1467 | E10: 0097 | F10: 서초금호어울림 | G10: 146.1300 | H10: 202404 | I10: 08 | J10: 172,000 | K10: 101 | L10: 3 | M10: 개인 | N10: 개인 | O10: 2001 | P10: 명달로 10 | Q10: - | R10: 중개거래 | S10: 서울 서초구 | T10: 24.11.25 | U10: 아파트
A11: 7 | B11: 서울특별시 서초구 서초동 | C11: 1344-13 | D11: 1344 | E11: 0013 | F11: 서초트라팰리스 | G11: 117.9800 | H11: 202404 | I11: 08 | J11: 189,500 | K11: B | L11: 5 | M11: 개인 | N11: 개인 | O11: 2005 | P11: 효령로72길 57 | Q11: - | R11: 중개거래 | S11: 서울 서초구 | T11: 24.07.15 | U11: 아파트
A12: 8 | B12: 서울특별시 서초구 서초동 | C12: 1757 | D12: 1757 | E12: 0000 | F12: 서초그랑자이 | G12: 84.5100 | H12: 202404 | I12: 08 | J12: 305,000 | K12: 102동 | L12: 27 | M12: 개인 | N12: 개인 | O12: 2021 | P12: 효령로 391 | Q12: - | R12: 중개거래 | S12: 서울 서초구 | T12: 24.07.12 | U12: 아파트
A13: 9 | B13: 서울특별시 서초구 서초동 | C13: 1350-13 | D13: 1350 | E13: 0013 | F13: 동원베네스트아파트 | G13: 84.9000 | H13: 202404 | I13: 08 | J13: 155,000 | K13: 102 | L13: 8 | M13: 개인 | N13: 개인 | O13: 2002 | P13: 서운로9길 63 | Q13: - | R13: 중개거래 | S13: 서울 서초구 | T13: 24.07.02 | U13: 아파트
A14: 10 | B14: 서울특별시 서초구 서초동 | C14: 1326-17 | D14: 1326 | E14: 0017 | F14: 우성아파트 | G14: 59.9300 | H14: 202404 | I14: 08 | J14: 154,500 | K14: 501 | L14: 2 | M14: 개인 | N14: 개인 | O14: 1998 | P14: 서초대로74길 30 | Q14: - | R14: 중개거래 | S14: 서울 서초구 | T14: 24.05.28 | U14: 아파트
A15: 11 | B15: 서울특별시 서초구 서초동 | C15: 1593-7 | D15: 1593 | E15: 0007 | F15: 서초이오빌 | G15: 45.9600 | H15: 202404 | I15: 07 | J15: 40,900 | K15: - | L15: 18 | M15: 개인 | N15: 개인 | O15: 2003 | P15: 효령로53길 45 | Q15: - | R15: 중개거래 | S15: 서울 서초구 | T15: 24.05.31 | U15: 아파트
A16: 12 | B16: 서울특별시 서초구 서초동 | C16: 1332-13 | D16: 1332 | E16: 0013 | F16: 래미안서초에스티지 | G16: 139.9900 | H16: 202404 | I16: 07 | J16: 350,000 | K16: 101동 | L16: 17 | M16: 개인 | N16: 개인 | O16: 2016 | P16: 서운로 107 | Q16: - | R16: 중개거래 | S16: 서울 서초구 | T16: 24.07.19 | U16: 아파트
... A2402: 743 | B2402: 서울특별시 서초구 서초동 | C2402: 1445-4 | D2402: 1445 | E2402: 0004 | F2402: 래미안서초유니빌 | G2402: 45.2550 | H2402: 202504 | I2402: 10 | J2402: 49,000 | K2402: 래미안 서초유니빌 | L2402: 13 | M2402: 개인 | N2402: 개인 | O2402: 2003 | P2402: 서초중앙로 26 | Q2402: - | R2402: 중개거래 | S2402: 서울 서초구 | T2402: 25.07.03 | U2402: 아파트

Sheet 04B_정규화_자동필터
A1: 정규화·1차필터·유사도 랭킹
A3: 원본행 | B3: 시군구 | C3: 번지 | D3: 단지명 | E3: 전용면적(㎡) | F3: 계약일 | G3: 거래금액(만원) | H3: 거래금액 (원) | I3: 단가 (원/㎡) | J3: 층 | K3: 건축년도 | L3: 도로명 | M3: 거래유형 | N3: 동일시군구 | O3: 동일법정동 | P3: 동일도로명 | Q3: 동일건물 | R3: 면적차율 | S3: 층차 | T3: 경과일수 | U3: 건축연차차 | V3: 1차통과 | W3: 유사도점수 | X3: 순위 | Y3: 예상단가차율 | Z3: 예상단가점수
A4: =IF(INDEX('04A_국토부원자료'!$A:$A,ROW()+1)="","",ROW()-3) | B4: =IFERROR(INDEX('04A_국토부원자료'!$A:$T,ROW()+1,MATCH("시군구",'04A_국토부원자료'!$A$4:$T$4,0)),"") | C4: =IF(B4="","",IFERROR(INDEX('04A_국토부원자료'!$A:$T,ROW()+1,MATCH("번지",'04A_국토부원자료'!$A$4:$T$4,0)),"")) | D4: =IF(B4="","",IF(Q4=1,'02_대상물건입력'!$B$8,IFERROR(INDEX('04A_국토부원자료'!$A:$T,ROW()+1,MATCH("단지명",'04A_국토부원자료'!$A$4:$T$4,0)),""))) | E4: =IFERROR(VALUE(SUBSTITUTE(INDEX('04A_국토부원자료'!$A:$T,ROW()+1,MATCH("전용면적(㎡)",'04A_국토부원자료'!$A$4:$T$4,0)),",","")),"") | F4: =IFERROR(IF(AND(INDEX('04A_국토부원자료'!$A:$T,ROW()+1,MATCH("계약년월",'04A_국토부원자료'!$A$4:$T$4,0))<>"",INDEX('04A_국토부원자료'!$A:$T,ROW()+1,MATCH("계약일",'04A_국토부원자료'!$A$4:$T$4,0))<>""),DATE(INT(VALUE(SUBSTITUTE(INDEX('04A_국토부원자료'!$A:$T,ROW()+1,MATCH("계약년월",'04A_국토부원자료'!$A$4:$T$4,0)),",",""))/100),MOD(VALUE(SUBSTITUTE(INDEX('04A_국토부원자료'!$A:$T,ROW()+1,MATCH("계약년월",'04A_국토부원자료'!$A$4:$T$4,0)),",","")),100),VALUE(SUBSTITUTE(INDEX('04A_국토부원자료'!$A:$T,ROW()+1,MATCH("계약일",'04A_국토부원자료'!$A$4:$T$4,0)),",",""))),""),"") | G4: =IFERROR(VALUE(SUBSTITUTE(INDEX('04A_국토부원자료'!$A:$T,ROW()+1,MATCH("거래금액(만원)",'04A_국토부원자료'!$A$4:$T$4,0)),",","")),"") | H4: =IF(G4="","",G4*10000) | I4: =IFERROR(IF(AND(H4>0,E4>0),H4/E4,""),"") | J4: =IFERROR(VALUE(SUBSTITUTE(INDEX('04A_국토부원자료'!$A:$T,ROW()+1,MATCH("층",'04A_국토부원자료'!$A$4:$T$4,0)),",","")),"") | K4: =IFERROR(VALUE(SUBSTITUTE(INDEX('04A_국토부원자료'!$A:$T,ROW()+1,MATCH("건축년도",'04A_국토부원자료'!$A$4:$T$4,0)),",","")),"") | L4: =IFERROR(INDEX('04A_국토부원자료'!$A:$T,ROW()+1,MATCH("도로명",'04A_국토부원자료'!$A$4:$T$4,0)),"") | M4: =IFERROR(INDEX('04A_국토부원자료'!$A:$T,ROW()+1,MATCH("거래유형",'04A_국토부원자료'!$A$4:$T$4,0)),"") | N4: =IF(B4="","",IF('02_대상물건입력'!B5="",1,IF(ISNUMBER(SEARCH('02_대상물건입력'!B5,B4)),1,0))) | O4: =IF(B4="","",IF('02_대상물건입력'!B6="",1,IF(ISNUMBER(SEARCH('02_대상물건입력'!B6,B4)),1,0))) | P4: =IF(L4="","",IF('02_대상물건입력'!B15="",0,IF(ISNUMBER(SEARCH('02_대상물건입력'!B15,L4)),1,0))) | Q4: =IF(OR(C4="",L4=""),0,IF(AND(TRIM(C4)=TRIM(RIGHT(SUBSTITUTE(TRIM('02_대상물건입력'!$B$7)," ",REPT(" ",99)),99)),IF('02_대상물건입력'!B15="",TRUE(),ISNUMBER(SEARCH('02_대상물건입력'!B15,L4)))),1,0)) | R4: =IFERROR(ABS(E4-'02_대상물건입력'!B11)/'02_대상물건입력'!B11,"") | S4: =IFERROR(ABS(J4-'02_대상물건입력'!B10),"") | T4: =IFERROR(ABS('01_설정'!B4-F4),"") | U4: =IFERROR(ABS(K4-YEAR('02_대상물건입력'!B14)),"") | V4: =IF(B4="","",IF(AND(E4>0,F4>0,H4>0,OR(IFERROR(INDEX('04A_국토부원자료'!$A:$T,ROW()+1,MATCH("해제사유발생일",'04A_국토부원자료'!$A$4:$T$4,0)),"")="",IFERROR(INDEX('04A_국토부원자료'!$A:$T,ROW()+1,MATCH("해제사유발생일",'04A_국토부원자료'!$A$4:$T$4,0)),"")="-"),IF('01_설정'!B10=1,N4=1,TRUE()),R4<='01_설정'!B5,S4<='01_설정'!B6,T4<='01_설정'!B7,U4<='01_설정'!B8),"Y","")) | W4: =IF(V4<>"Y","",MAX(0,(1-R4/'01_설정'!B5))*'01_설정'!B14+MAX(0,(1-S4/'01_설정'!B6))*'01_설정'!B15+MAX(0,(1-T4/'01_설정'!B7))*'01_설정'!B16+MAX(0,(1-U4/'01_설정'!B8))*'01_설정'!B17+O4*'01_설정'!B11+Q4*'01_설정'!B12+P4*'01_설정'!B13+IF(Z4="",0,Z4)) | X4: =IF(W4="","",1+COUNTIFS($W$4:$W$3003,">"&W4)+COUNTIFS($W$4:W4,W4)-1) | Y4: =IF(OR(I4="",'02_대상물건입력'!B19="",'02_대상물건입력'!B19<=0),"",ABS(I4-'02_대상물건입력'!B19)/'02_대상물건입력'!B19) | Z4: =IF(OR(Y4="",'01_설정'!B31="",'01_설정'!B31<=0,'01_설정'!B32="",'01_설정'!B32<=0),"",MAX(0,(1-Y4/'01_설정'!B32))*'01_설정'!B31)
A5: =IF(INDEX('04A_국토부원자료'!$A:$A,ROW()+1)="","",ROW()-3) | B5: =IFERROR(INDEX('04A_국토부원자료'!$A:$T,ROW()+1,MATCH("시군구",'04A_국토부원자료'!$A$4:$T$4,0)),"") | C5: =IF(B5="","",IFERROR(INDEX('04A_국토부원자료'!$A:$T,ROW()+1,MATCH("번지",'04A_국토부원자료'!$A$4:$T$4,0)),"")) | D5: =IF(B5="","",IF(Q5=1,'02_대상물건입력'!$B$8,IFERROR(INDEX('04A_국토부원자료'!$A:$T,ROW()+1,MATCH("단지명",'04A_국토부원자료'!$A$4:$T$4,0)),""))) | E5: =IFERROR(VALUE(SUBSTITUTE(INDEX('04A_국토부원자료'!$A:$T,ROW()+1,MATCH("전용면적(㎡)",'04A_국토부원자료'!$A$4:$T$4,0)),",","")),"") | F5: =IFERROR(IF(AND(INDEX('04A_국토부원자료'!$A:$T,ROW()+1,MATCH("계약년월",'04A_국토부원자료'!$A$4:$T$4,0))<>"",INDEX('04A_국토부원자료'!$A:$T,ROW()+1,MATCH("계약일",'04A_국토부원자료'!$A$4:$T$4,0))<>""),DATE(INT(VALUE(SUBSTITUTE(INDEX('04A_국토부원자료'!$A:$T,ROW()+1,MATCH("계약년월",'04A_국토부원자료'!$A$4:$T$4,0)),",",""))/100),MOD(VALUE(SUBSTITUTE(INDEX('04A_국토부원자료'!$A:$T,ROW()+1,MATCH("계약년월",'04A_국토부원자료'!$A$4:$T$4,0)),",","")),100),VALUE(SUBSTITUTE(INDEX('04A_국토부원자료'!$A:$T,ROW()+1,MATCH("계약일",'04A_국토부원자료'!$A$4:$T$4,0)),",",""))),""),"") | G5: =IFERROR(VALUE(SUBSTITUTE(INDEX('04A_국토부원자료'!$A:$T,ROW()+1,MATCH("거래금액(만원)",'04A_국토부원자료'!$A$4:$T$4,0)),",","")),"") | H5: =IF(G5="","",G5*10000) | I5: =IFERROR(IF(AND(H5>0,E5>0),H5/E5,""),"") | J5: =IFERROR(VALUE(SUBSTITUTE(INDEX('04A_국토부원자료'!$A:$T,ROW()+1,MATCH("층",'04A_국토부원자료'!$A$4:$T$4,0)),",","")),"") | K5: =IFERROR(VALUE(SUBSTITUTE(INDEX('04A_국토부원자료'!$A:$T,ROW()+1,MATCH("건축년도",'04A_국토부원자료'!$A$4:$T$4,0)),",","")),"") | L5: =IFERROR(INDEX('04A_국토부원자료'!$A:$T,ROW()+1,MATCH("도로명",'04A_국토부원자료'!$A$4:$T$4,0)),"") | M5: =IFERROR(INDEX('04A_국토부원자료'!$A:$T,ROW()+1,MATCH("거래유형",'04A_국토부원자료'!$A$4:$T$4,0)),"") | N5: =IF(B5="","",IF('02_대상물건입력'!B5="",1,IF(ISNUMBER(SEARCH('02_대상물건입력'!B5,B5)),1,0))) | O5: =IF(B5="","",IF('02_대상물건입력'!B6="",1,IF(ISNUMBER(SEARCH('02_대상물건입력'!B6,B5)),1,0))) | P5: =IF(L5="","",IF('02_대상물건입력'!B15="",0,IF(ISNUMBER(SEARCH('02_대상물건입력'!B15,L5)),1,0))) | Q5: =IF(OR(C5="",L5=""),0,IF(AND(TRIM(C5)=TRIM(RIGHT(SUBSTITUTE(TRIM('02_대상물건입력'!$B$7)," ",REPT(" ",99)),99)),IF('02_대상물건입력'!B15="",TRUE(),ISNUMBER(SEARCH('02_대상물건입력'!B15,L5)))),1,0)) | R5: =IFERROR(ABS(E5-'02_대상물건입력'!B11)/'02_대상물건입력'!B11,"") | S5: =IFERROR(ABS(J5-'02_대상물건입력'!B10),"") | T5: =IFERROR(ABS('01_설정'!B4-F5),"") | U5: =IFERROR(ABS(K5-YEAR('02_대상물건입력'!B14)),"") | V5: =IF(B5="","",IF(AND(E5>0,F5>0,H5>0,OR(IFERROR(INDEX('04A_국토부원자료'!$A:$T,ROW()+1,MATCH("해제사유발생일",'04A_국토부원자료'!$A$4:$T$4,0)),"")="",IFERROR(INDEX('04A_국토부원자료'!$A:$T,ROW()+1,MATCH("해제사유발생일",'04A_국토부원자료'!$A$4:$T$4,0)),"")="-"),IF('01_설정'!B10=1,N5=1,TRUE()),R5<='01_설정'!B5,S5<='01_설정'!B6,T5<='01_설정'!B7,U5<='01_설정'!B8),"Y","")) | W5: =IF(V5<>"Y","",MAX(0,(1-R5/'01_설정'!B5))*'01_설정'!B14+MAX(0,(1-S5/'01_설정'!B6))*'01_설정'!B15+MAX(0,(1-T5/'01_설정'!B7))*'01_설정'!B16+MAX(0,(1-U5/'01_설정'!B8))*'01_설정'!B17+O5*'01_설정'!B11+Q5*'01_설정'!B12+P5*'01_설정'!B13+IF(Z5="",0,Z5)) | X5: =IF(W5="","",1+COUNTIFS($W$4:$W$3003,">"&W5)+COUNTIFS($W$4:W5,W5)-1) | Y5: =IF(OR(I5="",'02_대상물건입력'!B19="",'02_대상물건입력'!B19<=0),"",ABS(I5-'02_대상물건입력'!B19)/'02_대상물건입력'!B19) | Z5: =IF(OR(Y5="",'01_설정'!B31="",'01_설정'!B31<=0,'01_설정'!B32="",'01_설정'!B32<=0),"",MAX(0,(1-Y5/'01_설정'!B32))*'01_설정'!B31)
A6: =IF(INDEX('04A_국토부원자료'!$A:$A,ROW()+1)="","",ROW()-3) | B6: =IFERROR(INDEX('04A_국토부원자료'!$A:$T,ROW()+1,MATCH("시군구",'04A_국토부원자료'!$A$4:$T$4,0)),"") | C6: =IF(B6="","",IFERROR(INDEX('04A_국토부원자료'!$A:$T,ROW()+1,MATCH("번지",'04A_국토부원자료'!$A$4:$T$4,0)),"")) | D6: =IF(B6="","",IF(Q6=1,'02_대상물건입력'!$B$8,IFERROR(INDEX('04A_국토부원자료'!$A:$T,ROW()+1,MATCH("단지명",'04A_국토부원자료'!$A$4:$T$4,0)),""))) | E6: =IFERROR(VALUE(SUBSTITUTE(INDEX('04A_국토부원자료'!$A:$T,ROW()+1,MATCH("전용면적(㎡)",'04A_국토부원자료'!$A$4:$T$4,0)),",","")),"") | F6: =IFERROR(IF(AND(INDEX('04A_국토부원자료'!$A:$T,ROW()+1,MATCH("계약년월",'04A_국토부원자료'!$A$4:$T$4,0))<>"",INDEX('04A_국토부원자료'!$A:$T,ROW()+1,MATCH("계약일",'04A_국토부원자료'!$A$4:$T$4,0))<>""),DATE(INT(VALUE(SUBSTITUTE(INDEX('04A_국토부원자료'!$A:$T,ROW()+1,MATCH("계약년월",'04A_국토부원자료'!$A$4:$T$4,0)),",",""))/100),MOD(VALUE(SUBSTITUTE(INDEX('04A_국토부원자료'!$A:$T,ROW()+1,MATCH("계약년월",'04A_국토부원자료'!$A$4:$T$4,0)),",","")),100),VALUE(SUBSTITUTE(INDEX('04A_국토부원자료'!$A:$T,ROW()+1,MATCH("계약일",'04A_국토부원자료'!$A$4:$T$4,0)),",",""))),""),"") | G6: =IFERROR(VALUE(SUBSTITUTE(INDEX('04A_국토부원자료'!$A:$T,ROW()+1,MATCH("거래금액(만원)",'04A_국토부원자료'!$A$4:$T$4,0)),",","")),"") | H6: =IF(G6="","",G6*10000) | I6: =IFERROR(IF(AND(H6>0,E6>0),H6/E6,""),"") | J6: =IFERROR(VALUE(SUBSTITUTE(INDEX('04A_국토부원자료'!$A:$T,ROW()+1,MATCH("층",'04A_국토부원자료'!$A$4:$T$4,0)),",","")),"") | K6: =IFERROR(VALUE(SUBSTITUTE(INDEX('04A_국토부원자료'!$A:$T,ROW()+1,MATCH("건축년도",'04A_국토부원자료'!$A$4:$T$4,0)),",","")),"") | L6: =IFERROR(INDEX('04A_국토부원자료'!$A:$T,ROW()+1,MATCH("도로명",'04A_국토부원자료'!$A$4:$T$4,0)),"") | M6: =IFERROR(INDEX('04A_국토부원자료'!$A:$T,ROW()+1,MATCH("거래유형",'04A_국토부원자료'!$A$4:$T$4,0)),"") | N6: =IF(B6="","",IF('02_대상물건입력'!B5="",1,IF(ISNUMBER(SEARCH('02_대상물건입력'!B5,B6)),1,0))) | O6: =IF(B6="","",IF('02_대상물건입력'!B6="",1,IF(ISNUMBER(SEARCH('02_대상물건입력'!B6,B6)),1,0))) | P6: =IF(L6="","",IF('02_대상물건입력'!B15="",0,IF(ISNUMBER(SEARCH('02_대상물건입력'!B15,L6)),1,0))) | Q6: =IF(OR(C6="",L6=""),0,IF(AND(TRIM(C6)=TRIM(RIGHT(SUBSTITUTE(TRIM('02_대상물건입력'!$B$7)," ",REPT(" ",99)),99)),IF('02_대상물건입력'!B15="",TRUE(),ISNUMBER(SEARCH('02_대상물건입력'!B15,L6)))),1,0)) | R6: =IFERROR(ABS(E6-'02_대상물건입력'!B11)/'02_대상물건입력'!B11,"") | S6: =IFERROR(ABS(J6-'02_대상물건입력'!B10),"") | T6: =IFERROR(ABS('01_설정'!B4-F6),"") | U6: =IFERROR(ABS(K6-YEAR('02_대상물건입력'!B14)),"") | V6: =IF(B6="","",IF(AND(E6>0,F6>0,H6>0,OR(IFERROR(INDEX('04A_국토부원자료'!$A:$T,ROW()+1,MATCH("해제사유발생일",'04A_국토부원자료'!$A$4:$T$4,0)),"")="",IFERROR(INDEX('04A_국토부원자료'!$A:$T,ROW()+1,MATCH("해제사유발생일",'04A_국토부원자료'!$A$4:$T$4,0)),"")="-"),IF('01_설정'!B10=1,N6=1,TRUE()),R6<='01_설정'!B5,S6<='01_설정'!B6,T6<='01_설정'!B7,U6<='01_설정'!B8),"Y","")) | W6: =IF(V6<>"Y","",MAX(0,(1-R6/'01_설정'!B5))*'01_설정'!B14+MAX(0,(1-S6/'01_설정'!B6))*'01_설정'!B15+MAX(0,(1-T6/'01_설정'!B7))*'01_설정'!B16+MAX(0,(1-U6/'01_설정'!B8))*'01_설정'!B17+O6*'01_설정'!B11+Q6*'01_설정'!B12+P6*'01_설정'!B13+IF(Z6="",0,Z6)) | X6: =IF(W6="","",1+COUNTIFS($W$4:$W$3003,">"&W6)+COUNTIFS($W$4:W6,W6)-1) | Y6: =IF(OR(I6="",'02_대상물건입력'!B19="",'02_대상물건입력'!B19<=0),"",ABS(I6-'02_대상물건입력'!B19)/'02_대상물건입력'!B19) | Z6: =IF(OR(Y6="",'01_설정'!B31="",'01_설정'!B31<=0,'01_설정'!B32="",'01_설정'!B32<=0),"",MAX(0,(1-Y6/'01_설정'!B32))*'01_설정'!B31)
A7: =IF(INDEX('04A_국토부원자료'!$A:$A,ROW()+1)="","",ROW()-3) | B7: =IFERROR(INDEX('04A_국토부원자료'!$A:$T,ROW()+1,MATCH("시군구",'04A_국토부원자료'!$A$4:$T$4,0)),"") | C7: =IF(B7="","",IFERROR(INDEX('04A_국토부원자료'!$A:$T,ROW()+1,MATCH("번지",'04A_국토부원자료'!$A$4:$T$4,0)),"")) | D7: =IF(B7="","",IF(Q7=1,'02_대상물건입력'!$B$8,IFERROR(INDEX('04A_국토부원자료'!$A:$T,ROW()+1,MATCH("단지명",'04A_국토부원자료'!$A$4:$T$4,0)),""))) | E7: =IFERROR(VALUE(SUBSTITUTE(INDEX('04A_국토부원자료'!$A:$T,ROW()+1,MATCH("전용면적(㎡)",'04A_국토부원자료'!$A$4:$T$4,0)),",","")),"") | F7: =IFERROR(IF(AND(INDEX('04A_국토부원자료'!$A:$T,ROW()+1,MATCH("계약년월",'04A_국토부원자료'!$A$4:$T$4,0))<>"",INDEX('04A_국토부원자료'!$A:$T,ROW()+1,MATCH("계약일",'04A_국토부원자료'!$A$4:$T$4,0))<>""),DATE(INT(VALUE(SUBSTITUTE(INDEX('04A_국토부원자료'!$A:$T,ROW()+1,MATCH("계약년월",'04A_국토부원자료'!$A$4:$T$4,0)),",",""))/100),MOD(VALUE(SUBSTITUTE(INDEX('04A_국토부원자료'!$A:$T,ROW()+1,MATCH("계약년월",'04A_국토부원자료'!$A$4:$T$4,0)),",","")),100),VALUE(SUBSTITUTE(INDEX('04A_국토부원자료'!$A:$T,ROW()+1,MATCH("계약일",'04A_국토부원자료'!$A$4:$T$4,0)),",",""))),""),"") | G7: =IFERROR(VALUE(SUBSTITUTE(INDEX('04A_국토부원자료'!$A:$T,ROW()+1,MATCH("거래금액(만원)",'04A_국토부원자료'!$A$4:$T$4,0)),",","")),"") | H7: =IF(G7="","",G7*10000) | I7: =IFERROR(IF(AND(H7>0,E7>0),H7/E7,""),"") | J7: =IFERROR(VALUE(SUBSTITUTE(INDEX('04A_국토부원자료'!$A:$T,ROW()+1,MATCH("층",'04A_국토부원자료'!$A$4:$T$4,0)),",","")),"") | K7: =IFERROR(VALUE(SUBSTITUTE(INDEX('04A_국토부원자료'!$A:$T,ROW()+1,MATCH("건축년도",'04A_국토부원자료'!$A$4:$T$4,0)),",","")),"") | L7: =IFERROR(INDEX('04A_국토부원자료'!$A:$T,ROW()+1,MATCH("도로명",'04A_국토부원자료'!$A$4:$T$4,0)),"") | M7: =IFERROR(INDEX('04A_국토부원자료'!$A:$T,ROW()+1,MATCH("거래유형",'04A_국토부원자료'!$A$4:$T$4,0)),"") | N7: =IF(B7="","",IF('02_대상물건입력'!B5="",1,IF(ISNUMBER(SEARCH('02_대상물건입력'!B5,B7)),1,0))) | O7: =IF(B7="","",IF('02_대상물건입력'!B6="",1,IF(ISNUMBER(SEARCH('02_대상물건입력'!B6,B7)),1,0))) | P7: =IF(L7="","",IF('02_대상물건입력'!B15="",0,IF(ISNUMBER(SEARCH('02_대상물건입력'!B15,L7)),1,0))) | Q7: =IF(OR(C7="",L7=""),0,IF(AND(TRIM(C7)=TRIM(RIGHT(SUBSTITUTE(TRIM('02_대상물건입력'!$B$7)," ",REPT(" ",99)),99)),IF('02_대상물건입력'!B15="",TRUE(),ISNUMBER(SEARCH('02_대상물건입력'!B15,L7)))),1,0)) | R7: =IFERROR(ABS(E7-'02_대상물건입력'!B11)/'02_대상물건입력'!B11,"") | S7: =IFERROR(ABS(J7-'02_대상물건입력'!B10),"") | T7: =IFERROR(ABS('01_설정'!B4-F7),"") | U7: =IFERROR(ABS(K7-YEAR('02_대상물건입력'!B14)),"") | V7: =IF(B7="","",IF(AND(E7>0,F7>0,H7>0,OR(IFERROR(INDEX('04A_국토부원자료'!$A:$T,ROW()+1,MATCH("해제사유발생일",'04A_국토부원자료'!$A$4:$T$4,0)),"")="",IFERROR(INDEX('04A_국토부원자료'!$A:$T,ROW()+1,MATCH("해제사유발생일",'04A_국토부원자료'!$A$4:$T$4,0)),"")="-"),IF('01_설정'!B10=1,N7=1,TRUE()),R7<='01_설정'!B5,S7<='01_설정'!B6,T7<='01_설정'!B7,U7<='01_설정'!B8),"Y","")) | W7: =IF(V7<>"Y","",MAX(0,(1-R7/'01_설정'!B5))*'01_설정'!B14+MAX(0,(1-S7/'01_설정'!B6))*'01_설정'!B15+MAX(0,(1-T7/'01_설정'!B7))*'01_설정'!B16+MAX(0,(1-U7/'01_설정'!B8))*'01_설정'!B17+O7*'01_설정'!B11+Q7*'01_설정'!B12+P7*'01_설정'!B13+IF(Z7="",0,Z7)) | X7: =IF(W7="","",1+COUNTIFS($W$4:$W$3003,">"&W7)+COUNTIFS($W$4:W7,W7)-1) | Y7: =IF(OR(I7="",'02_대상물건입력'!B19="",'02_대상물건입력'!B19<=0),"",ABS(I7-'02_대상물건입력'!B19)/'02_대상물건입력'!B19) | Z7: =IF(OR(Y7="",'01_설정'!B31="",'01_설정'!B31<=0,'01_설정'!B32="",'01_설정'!B32<=0),"",MAX(0,(1-Y7/'01_설정'!B32))*'01_설정'!B31)
A8: =IF(INDEX('04A_국토부원자료'!$A:$A,ROW()+1)="","",ROW()-3) | B8: =IFERROR(INDEX('04A_국토부원자료'!$A:$T,ROW()+1,MATCH("시군구",'04A_국토부원자료'!$A$4:$T$4,0)),"") | C8: =IF(B8="","",IFERROR(INDEX('04A_국토부원자료'!$A:$T,ROW()+1,MATCH("번지",'04A_국토부원자료'!$A$4:$T$4,0)),"")) | D8: =IF(B8="","",IF(Q8=1,'02_대상물건입력'!$B$8,IFERROR(INDEX('04A_국토부원자료'!$A:$T,ROW()+1,MATCH("단지명",'04A_국토부원자료'!$A$4:$T$4,0)),""))) | E8: =IFERROR(VALUE(SUBSTITUTE(INDEX('04A_국토부원자료'!$A:$T,ROW()+1,MATCH("전용면적(㎡)",'04A_국토부원자료'!$A$4:$T$4,0)),",","")),"") | F8: =IFERROR(IF(AND(INDEX('04A_국토부원자료'!$A:$T,ROW()+1,MATCH("계약년월",'04A_국토부원자료'!$A$4:$T$4,0))<>"",INDEX('04A_국토부원자료'!$A:$T,ROW()+1,MATCH("계약일",'04A_국토부원자료'!$A$4:$T$4,0))<>""),DATE(INT(VALUE(SUBSTITUTE(INDEX('04A_국토부원자료'!$A:$T,ROW()+1,MATCH("계약년월",'04A_국토부원자료'!$A$4:$T$4,0)),",",""))/100),MOD(VALUE(SUBSTITUTE(INDEX('04A_국토부원자료'!$A:$T,ROW()+1,MATCH("계약년월",'04A_국토부원자료'!$A$4:$T$4,0)),",","")),100),VALUE(SUBSTITUTE(INDEX('04A_국토부원자료'!$A:$T,ROW()+1,MATCH("계약일",'04A_국토부원자료'!$A$4:$T$4,0)),",",""))),""),"") | G8: =IFERROR(VALUE(SUBSTITUTE(INDEX('04A_국토부원자료'!$A:$T,ROW()+1,MATCH("거래금액(만원)",'04A_국토부원자료'!$A$4:$T$4,0)),",","")),"") | H8: =IF(G8="","",G8*10000) | I8: =IFERROR(IF(AND(H8>0,E8>0),H8/E8,""),"") | J8: =IFERROR(VALUE(SUBSTITUTE(INDEX('04A_국토부원자료'!$A:$T,ROW()+1,MATCH("층",'04A_국토부원자료'!$A$4:$T$4,0)),",","")),"") | K8: =IFERROR(VALUE(SUBSTITUTE(INDEX('04A_국토부원자료'!$A:$T,ROW()+1,MATCH("건축년도",'04A_국토부원자료'!$A$4:$T$4,0)),",","")),"") | L8: =IFERROR(INDEX('04A_국토부원자료'!$A:$T,ROW()+1,MATCH("도로명",'04A_국토부원자료'!$A$4:$T$4,0)),"") | M8: =IFERROR(INDEX('04A_국토부원자료'!$A:$T,ROW()+1,MATCH("거래유형",'04A_국토부원자료'!$A$4:$T$4,0)),"") | N8: =IF(B8="","",IF('02_대상물건입력'!B5="",1,IF(ISNUMBER(SEARCH('02_대상물건입력'!B5,B8)),1,0))) | O8: =IF(B8="","",IF('02_대상물건입력'!B6="",1,IF(ISNUMBER(SEARCH('02_대상물건입력'!B6,B8)),1,0))) | P8: =IF(L8="","",IF('02_대상물건입력'!B15="",0,IF(ISNUMBER(SEARCH('02_대상물건입력'!B15,L8)),1,0))) | Q8: =IF(OR(C8="",L8=""),0,IF(AND(TRIM(C8)=TRIM(RIGHT(SUBSTITUTE(TRIM('02_대상물건입력'!$B$7)," ",REPT(" ",99)),99)),IF('02_대상물건입력'!B15="",TRUE(),ISNUMBER(SEARCH('02_대상물건입력'!B15,L8)))),1,0)) | R8: =IFERROR(ABS(E8-'02_대상물건입력'!B11)/'02_대상물건입력'!B11,"") | S8: =IFERROR(ABS(J8-'02_대상물건입력'!B10),"") | T8: =IFERROR(ABS('01_설정'!B4-F8),"") | U8: =IFERROR(ABS(K8-YEAR('02_대상물건입력'!B14)),"") | V8: =IF(B8="","",IF(AND(E8>0,F8>0,H8>0,OR(IFERROR(INDEX('04A_국토부원자료'!$A:$T,ROW()+1,MATCH("해제사유발생일",'04A_국토부원자료'!$A$4:$T$4,0)),"")="",IFERROR(INDEX('04A_국토부원자료'!$A:$T,ROW()+1,MATCH("해제사유발생일",'04A_국토부원자료'!$A$4:$T$4,0)),"")="-"),IF('01_설정'!B10=1,N8=1,TRUE()),R8<='01_설정'!B5,S8<='01_설정'!B6,T8<='01_설정'!B7,U8<='01_설정'!B8),"Y","")) | W8: =IF(V8<>"Y","",MAX(0,(1-R8/'01_설정'!B5))*'01_설정'!B14+MAX(0,(1-S8/'01_설정'!B6))*'01_설정'!B15+MAX(0,(1-T8/'01_설정'!B7))*'01_설정'!B16+MAX(0,(1-U8/'01_설정'!B8))*'01_설정'!B17+O8*'01_설정'!B11+Q8*'01_설정'!B12+P8*'01_설정'!B13+IF(Z8="",0,Z8)) | X8: =IF(W8="","",1+COUNTIFS($W$4:$W$3003,">"&W8)+COUNTIFS($W$4:W8,W8)-1) | Y8: =IF(OR(I8="",'02_대상물건입력'!B19="",'02_대상물건입력'!B19<=0),"",ABS(I8-'02_대상물건입력'!B19)/'02_대상물건입력'!B19) | Z8: =IF(OR(Y8="",'01_설정'!B31="",'01_설정'!B31<=0,'01_설정'!B32="",'01_설정'!B32<=0),"",MAX(0,(1-Y8/'01_설정'!B32))*'01_설정'!B31)
A9: =IF(INDEX('04A_국토부원자료'!$A:$A,ROW()+1)="","",ROW()-3) | B9: =IFERROR(INDEX('04A_국토부원자료'!$A:$T,ROW()+1,MATCH("시군구",'04A_국토부원자료'!$A$4:$T$4,0)),"") | C9: =IF(B9="","",IFERROR(INDEX('04A_국토부원자료'!$A:$T,ROW()+1,MATCH("번지",'04A_국토부원자료'!$A$4:$T$4,0)),"")) | D9: =IF(B9="","",IF(Q9=1,'02_대상물건입력'!$B$8,IFERROR(INDEX('04A_국토부원자료'!$A:$T,ROW()+1,MATCH("단지명",'04A_국토부원자료'!$A$4:$T$4,0)),""))) | E9: =IFERROR(VALUE(SUBSTITUTE(INDEX('04A_국토부원자료'!$A:$T,ROW()+1,MATCH("전용면적(㎡)",'04A_국토부원자료'!$A$4:$T$4,0)),",","")),"") | F9: =IFERROR(IF(AND(INDEX('04A_국토부원자료'!$A:$T,ROW()+1,MATCH("계약년월",'04A_국토부원자료'!$A$4:$T$4,0))<>"",INDEX('04A_국토부원자료'!$A:$T,ROW()+1,MATCH("계약일",'04A_국토부원자료'!$A$4:$T$4,0))<>""),DATE(INT(VALUE(SUBSTITUTE(INDEX('04A_국토부원자료'!$A:$T,ROW()+1,MATCH("계약년월",'04A_국토부원자료'!$A$4:$T$4,0)),",",""))/100),MOD(VALUE(SUBSTITUTE(INDEX('04A_국토부원자료'!$A:$T,ROW()+1,MATCH("계약년월",'04A_국토부원자료'!$A$4:$T$4,0)),",","")),100),VALUE(SUBSTITUTE(INDEX('04A_국토부원자료'!$A:$T,ROW()+1,MATCH("계약일",'04A_국토부원자료'!$A$4:$T$4,0)),",",""))),""),"") | G9: =IFERROR(VALUE(SUBSTITUTE(INDEX('04A_국토부원자료'!$A:$T,ROW()+1,MATCH("거래금액(만원)",'04A_국토부원자료'!$A$4:$T$4,0)),",","")),"") | H9: =IF(G9="","",G9*10000) | I9: =IFERROR(IF(AND(H9>0,E9>0),H9/E9,""),"") | J9: =IFERROR(VALUE(SUBSTITUTE(INDEX('04A_국토부원자료'!$A:$T,ROW()+1,MATCH("층",'04A_국토부원자료'!$A$4:$T$4,0)),",","")),"") | K9: =IFERROR(VALUE(SUBSTITUTE(INDEX('04A_국토부원자료'!$A:$T,ROW()+1,MATCH("건축년도",'04A_국토부원자료'!$A$4:$T$4,0)),",","")),"") | L9: =IFERROR(INDEX('04A_국토부원자료'!$A:$T,ROW()+1,MATCH("도로명",'04A_국토부원자료'!$A$4:$T$4,0)),"") | M9: =IFERROR(INDEX('04A_국토부원자료'!$A:$T,ROW()+1,MATCH("거래유형",'04A_국토부원자료'!$A$4:$T$4,0)),"") | N9: =IF(B9="","",IF('02_대상물건입력'!B5="",1,IF(ISNUMBER(SEARCH('02_대상물건입력'!B5,B9)),1,0))) | O9: =IF(B9="","",IF('02_대상물건입력'!B6="",1,IF(ISNUMBER(SEARCH('02_대상물건입력'!B6,B9)),1,0))) | P9: =IF(L9="","",IF('02_대상물건입력'!B15="",0,IF(ISNUMBER(SEARCH('02_대상물건입력'!B15,L9)),1,0))) | Q9: =IF(OR(C9="",L9=""),0,IF(AND(TRIM(C9)=TRIM(RIGHT(SUBSTITUTE(TRIM('02_대상물건입력'!$B$7)," ",REPT(" ",99)),99)),IF('02_대상물건입력'!B15="",TRUE(),ISNUMBER(SEARCH('02_대상물건입력'!B15,L9)))),1,0)) | R9: =IFERROR(ABS(E9-'02_대상물건입력'!B11)/'02_대상물건입력'!B11,"") | S9: =IFERROR(ABS(J9-'02_대상물건입력'!B10),"") | T9: =IFERROR(ABS('01_설정'!B4-F9),"") | U9: =IFERROR(ABS(K9-YEAR('02_대상물건입력'!B14)),"") | V9: =IF(B9="","",IF(AND(E9>0,F9>0,H9>0,OR(IFERROR(INDEX('04A_국토부원자료'!$A:$T,ROW()+1,MATCH("해제사유발생일",'04A_국토부원자료'!$A$4:$T$4,0)),"")="",IFERROR(INDEX('04A_국토부원자료'!$A:$T,ROW()+1,MATCH("해제사유발생일",'04A_국토부원자료'!$A$4:$T$4,0)),"")="-"),IF('01_설정'!B10=1,N9=1,TRUE()),R9<='01_설정'!B5,S9<='01_설정'!B6,T9<='01_설정'!B7,U9<='01_설정'!B8),"Y","")) | W9: =IF(V9<>"Y","",MAX(0,(1-R9/'01_설정'!B5))*'01_설정'!B14+MAX(0,(1-S9/'01_설정'!B6))*'01_설정'!B15+MAX(0,(1-T9/'01_설정'!B7))*'01_설정'!B16+MAX(0,(1-U9/'01_설정'!B8))*'01_설정'!B17+O9*'01_설정'!B11+Q9*'01_설정'!B12+P9*'01_설정'!B13+IF(Z9="",0,Z9)) | X9: =IF(W9="","",1+COUNTIFS($W$4:$W$3003,">"&W9)+COUNTIFS($W$4:W9,W9)-1) | Y9: =IF(OR(I9="",'02_대상물건입력'!B19="",'02_대상물건입력'!B19<=0),"",ABS(I9-'02_대상물건입력'!B19)/'02_대상물건입력'!B19) | Z9: =IF(OR(Y9="",'01_설정'!B31="",'01_설정'!B31<=0,'01_설정'!B32="",'01_설정'!B32<=0),"",MAX(0,(1-Y9/'01_설정'!B32))*'01_설정'!B31)
A10: =IF(INDEX('04A_국토부원자료'!$A:$A,ROW()+1)="","",ROW()-3) | B10: =IFERROR(INDEX('04A_국토부원자료'!$A:$T,ROW()+1,MATCH("시군구",'04A_국토부원자료'!$A$4:$T$4,0)),"") | C10: =IF(B10="","",IFERROR(INDEX('04A_국토부원자료'!$A:$T,ROW()+1,MATCH("번지",'04A_국토부원자료'!$A$4:$T$4,0)),"")) | D10: =IF(B10="","",IF(Q10=1,'02_대상물건입력'!$B$8,IFERROR(INDEX('04A_국토부원자료'!$A:$T,ROW()+1,MATCH("단지명",'04A_국토부원자료'!$A$4:$T$4,0)),""))) | E10: =IFERROR(VALUE(SUBSTITUTE(INDEX('04A_국토부원자료'!$A:$T,ROW()+1,MATCH("전용면적(㎡)",'04A_국토부원자료'!$A$4:$T$4,0)),",","")),"") | F10: =IFERROR(IF(AND(INDEX('04A_국토부원자료'!$A:$T,ROW()+1,MATCH("계약년월",'04A_국토부원자료'!$A$4:$T$4,0))<>"",INDEX('04A_국토부원자료'!$A:$T,ROW()+1,MATCH("계약일",'04A_국토부원자료'!$A$4:$T$4,0))<>""),DATE(INT(VALUE(SUBSTITUTE(INDEX('04A_국토부원자료'!$A:$T,ROW()+1,MATCH("계약년월",'04A_국토부원자료'!$A$4:$T$4,0)),",",""))/100),MOD(VALUE(SUBSTITUTE(INDEX('04A_국토부원자료'!$A:$T,ROW()+1,MATCH("계약년월",'04A_국토부원자료'!$A$4:$T$4,0)),",","")),100),VALUE(SUBSTITUTE(INDEX('04A_국토부원자료'!$A:$T,ROW()+1,MATCH("계약일",'04A_국토부원자료'!$A$4:$T$4,0)),",",""))),""),"") | G10: =IFERROR(VALUE(SUBSTITUTE(INDEX('04A_국토부원자료'!$A:$T,ROW()+1,MATCH("거래금액(만원)",'04A_국토부원자료'!$A$4:$T$4,0)),",","")),"") | H10: =IF(G10="","",G10*10000) | I10: =IFERROR(IF(AND(H10>0,E10>0),H10/E10,""),"") | J10: =IFERROR(VALUE(SUBSTITUTE(INDEX('04A_국토부원자료'!$A:$T,ROW()+1,MATCH("층",'04A_국토부원자료'!$A$4:$T$4,0)),",","")),"") | K10: =IFERROR(VALUE(SUBSTITUTE(INDEX('04A_국토부원자료'!$A:$T,ROW()+1,MATCH("건축년도",'04A_국토부원자료'!$A$4:$T$4,0)),",","")),"") | L10: =IFERROR(INDEX('04A_국토부원자료'!$A:$T,ROW()+1,MATCH("도로명",'04A_국토부원자료'!$A$4:$T$4,0)),"") | M10: =IFERROR(INDEX('04A_국토부원자료'!$A:$T,ROW()+1,MATCH("거래유형",'04A_국토부원자료'!$A$4:$T$4,0)),"") | N10: =IF(B10="","",IF('02_대상물건입력'!B5="",1,IF(ISNUMBER(SEARCH('02_대상물건입력'!B5,B10)),1,0))) | O10: =IF(B10="","",IF('02_대상물건입력'!B6="",1,IF(ISNUMBER(SEARCH('02_대상물건입력'!B6,B10)),1,0))) | P10: =IF(L10="","",IF('02_대상물건입력'!B15="",0,IF(ISNUMBER(SEARCH('02_대상물건입력'!B15,L10)),1,0))) | Q10: =IF(OR(C10="",L10=""),0,IF(AND(TRIM(C10)=TRIM(RIGHT(SUBSTITUTE(TRIM('02_대상물건입력'!$B$7)," ",REPT(" ",99)),99)),IF('02_대상물건입력'!B15="",TRUE(),ISNUMBER(SEARCH('02_대상물건입력'!B15,L10)))),1,0)) | R10: =IFERROR(ABS(E10-'02_대상물건입력'!B11)/'02_대상물건입력'!B11,"") | S10: =IFERROR(ABS(J10-'02_대상물건입력'!B10),"") | T10: =IFERROR(ABS('01_설정'!B4-F10),"") | U10: =IFERROR(ABS(K10-YEAR('02_대상물건입력'!B14)),"") | V10: =IF(B10="","",IF(AND(E10>0,F10>0,H10>0,OR(IFERROR(INDEX('04A_국토부원자료'!$A:$T,ROW()+1,MATCH("해제사유발생일",'04A_국토부원자료'!$A$4:$T$4,0)),"")="",IFERROR(INDEX('04A_국토부원자료'!$A:$T,ROW()+1,MATCH("해제사유발생일",'04A_국토부원자료'!$A$4:$T$4,0)),"")="-"),IF('01_설정'!B10=1,N10=1,TRUE()),R10<='01_설정'!B5,S10<='01_설정'!B6,T10<='01_설정'!B7,U10<='01_설정'!B8),"Y","")) | W10: =IF(V10<>"Y","",MAX(0,(1-R10/'01_설정'!B5))*'01_설정'!B14+MAX(0,(1-S10/'01_설정'!B6))*'01_설정'!B15+MAX(0,(1-T10/'01_설정'!B7))*'01_설정'!B16+MAX(0,(1-U10/'01_설정'!B8))*'01_설정'!B17+O10*'01_설정'!B11+Q10*'01_설정'!B12+P10*'01_설정'!B13+IF(Z10="",0,Z10)) | X10: =IF(W10="","",1+COUNTIFS($W$4:$W$3003,">"&W10)+COUNTIFS($W$4:W10,W10)-1) | Y10: =IF(OR(I10="",'02_대상물건입력'!B19="",'02_대상물건입력'!B19<=0),"",ABS(I10-'02_대상물건입력'!B19)/'02_대상물건입력'!B19) | Z10: =IF(OR(Y10="",'01_설정'!B31="",'01_설정'!B31<=0,'01_설정'!B32="",'01_설정'!B32<=0),"",MAX(0,(1-Y10/'01_설정'!B32))*'01_설정'!B31)
A11: =IF(INDEX('04A_국토부원자료'!$A:$A,ROW()+1)="","",ROW()-3) | B11: =IFERROR(INDEX('04A_국토부원자료'!$A:$T,ROW()+1,MATCH("시군구",'04A_국토부원자료'!$A$4:$T$4,0)),"") | C11: =IF(B11="","",IFERROR(INDEX('04A_국토부원자료'!$A:$T,ROW()+1,MATCH("번지",'04A_국토부원자료'!$A$4:$T$4,0)),"")) | D11: =IF(B11="","",IF(Q11=1,'02_대상물건입력'!$B$8,IFERROR(INDEX('04A_국토부원자료'!$A:$T,ROW()+1,MATCH("단지명",'04A_국토부원자료'!$A$4:$T$4,0)),""))) | E11: =IFERROR(VALUE(SUBSTITUTE(INDEX('04A_국토부원자료'!$A:$T,ROW()+1,MATCH("전용면적(㎡)",'04A_국토부원자료'!$A$4:$T$4,0)),",","")),"") | F11: =IFERROR(IF(AND(INDEX('04A_국토부원자료'!$A:$T,ROW()+1,MATCH("계약년월",'04A_국토부원자료'!$A$4:$T$4,0))<>"",INDEX('04A_국토부원자료'!$A:$T,ROW()+1,MATCH("계약일",'04A_국토부원자료'!$A$4:$T$4,0))<>""),DATE(INT(VALUE(SUBSTITUTE(INDEX('04A_국토부원자료'!$A:$T,ROW()+1,MATCH("계약년월",'04A_국토부원자료'!$A$4:$T$4,0)),",",""))/100),MOD(VALUE(SUBSTITUTE(INDEX('04A_국토부원자료'!$A:$T,ROW()+1,MATCH("계약년월",'04A_국토부원자료'!$A$4:$T$4,0)),",","")),100),VALUE(SUBSTITUTE(INDEX('04A_국토부원자료'!$A:$T,ROW()+1,MATCH("계약일",'04A_국토부원자료'!$A$4:$T$4,0)),",",""))),""),"") | G11: =IFERROR(VALUE(SUBSTITUTE(INDEX('04A_국토부원자료'!$A:$T,ROW()+1,MATCH("거래금액(만원)",'04A_국토부원자료'!$A$4:$T$4,0)),",","")),"") | H11: =IF(G11="","",G11*10000) | I11: =IFERROR(IF(AND(H11>0,E11>0),H11/E11,""),"") | J11: =IFERROR(VALUE(SUBSTITUTE(INDEX('04A_국토부원자료'!$A:$T,ROW()+1,MATCH("층",'04A_국토부원자료'!$A$4:$T$4,0)),",","")),"") | K11: =IFERROR(VALUE(SUBSTITUTE(INDEX('04A_국토부원자료'!$A:$T,ROW()+1,MATCH("건축년도",'04A_국토부원자료'!$A$4:$T$4,0)),",","")),"") | L11: =IFERROR(INDEX('04A_국토부원자료'!$A:$T,ROW()+1,MATCH("도로명",'04A_국토부원자료'!$A$4:$T$4,0)),"") | M11: =IFERROR(INDEX('04A_국토부원자료'!$A:$T,ROW()+1,MATCH("거래유형",'04A_국토부원자료'!$A$4:$T$4,0)),"") | N11: =IF(B11="","",IF('02_대상물건입력'!B5="",1,IF(ISNUMBER(SEARCH('02_대상물건입력'!B5,B11)),1,0))) | O11: =IF(B11="","",IF('02_대상물건입력'!B6="",1,IF(ISNUMBER(SEARCH('02_대상물건입력'!B6,B11)),1,0))) | P11: =IF(L11="","",IF('02_대상물건입력'!B15="",0,IF(ISNUMBER(SEARCH('02_대상물건입력'!B15,L11)),1,0))) | Q11: =IF(OR(C11="",L11=""),0,IF(AND(TRIM(C11)=TRIM(RIGHT(SUBSTITUTE(TRIM('02_대상물건입력'!$B$7)," ",REPT(" ",99)),99)),IF('02_대상물건입력'!B15="",TRUE(),ISNUMBER(SEARCH('02_대상물건입력'!B15,L11)))),1,0)) | R11: =IFERROR(ABS(E11-'02_대상물건입력'!B11)/'02_대상물건입력'!B11,"") | S11: =IFERROR(ABS(J11-'02_대상물건입력'!B10),"") | T11: =IFERROR(ABS('01_설정'!B4-F11),"") | U11: =IFERROR(ABS(K11-YEAR('02_대상물건입력'!B14)),"") | V11: =IF(B11="","",IF(AND(E11>0,F11>0,H11>0,OR(IFERROR(INDEX('04A_국토부원자료'!$A:$T,ROW()+1,MATCH("해제사유발생일",'04A_국토부원자료'!$A$4:$T$4,0)),"")="",IFERROR(INDEX('04A_국토부원자료'!$A:$T,ROW()+1,MATCH("해제사유발생일",'04A_국토부원자료'!$A$4:$T$4,0)),"")="-"),IF('01_설정'!B10=1,N11=1,TRUE()),R11<='01_설정'!B5,S11<='01_설정'!B6,T11<='01_설정'!B7,U11<='01_설정'!B8),"Y","")) | W11: =IF(V11<>"Y","",MAX(0,(1-R11/'01_설정'!B5))*'01_설정'!B14+MAX(0,(1-S11/'01_설정'!B6))*'01_설정'!B15+MAX(0,(1-T11/'01_설정'!B7))*'01_설정'!B16+MAX(0,(1-U11/'01_설정'!B8))*'01_설정'!B17+O11*'01_설정'!B11+Q11*'01_설정'!B12+P11*'01_설정'!B13+IF(Z11="",0,Z11)) | X11: =IF(W11="","",1+COUNTIFS($W$4:$W$3003,">"&W11)+COUNTIFS($W$4:W11,W11)-1) | Y11: =IF(OR(I11="",'02_대상물건입력'!B19="",'02_대상물건입력'!B19<=0),"",ABS(I11-'02_대상물건입력'!B19)/'02_대상물건입력'!B19) | Z11: =IF(OR(Y11="",'01_설정'!B31="",'01_설정'!B31<=0,'01_설정'!B32="",'01_설정'!B32<=0),"",MAX(0,(1-Y11/'01_설정'!B32))*'01_설정'!B31)
A12: =IF(INDEX('04A_국토부원자료'!$A:$A,ROW()+1)="","",ROW()-3) | B12: =IFERROR(INDEX('04A_국토부원자료'!$A:$T,ROW()+1,MATCH("시군구",'04A_국토부원자료'!$A$4:$T$4,0)),"") | C12: =IF(B12="","",IFERROR(INDEX('04A_국토부원자료'!$A:$T,ROW()+1,MATCH("번지",'04A_국토부원자료'!$A$4:$T$4,0)),"")) | D12: =IF(B12="","",IF(Q12=1,'02_대상물건입력'!$B$8,IFERROR(INDEX('04A_국토부원자료'!$A:$T,ROW()+1,MATCH("단지명",'04A_국토부원자료'!$A$4:$T$4,0)),""))) | E12: =IFERROR(VALUE(SUBSTITUTE(INDEX('04A_국토부원자료'!$A:$T,ROW()+1,MATCH("전용면적(㎡)",'04A_국토부원자료'!$A$4:$T$4,0)),",","")),"") | F12: =IFERROR(IF(AND(INDEX('04A_국토부원자료'!$A:$T,ROW()+1,MATCH("계약년월",'04A_국토부원자료'!$A$4:$T$4,0))<>"",INDEX('04A_국토부원자료'!$A:$T,ROW()+1,MATCH("계약일",'04A_국토부원자료'!$A$4:$T$4,0))<>""),DATE(INT(VALUE(SUBSTITUTE(INDEX('04A_국토부원자료'!$A:$T,ROW()+1,MATCH("계약년월",'04A_국토부원자료'!$A$4:$T$4,0)),",",""))/100),MOD(VALUE(SUBSTITUTE(INDEX('04A_국토부원자료'!$A:$T,ROW()+1,MATCH("계약년월",'04A_국토부원자료'!$A$4:$T$4,0)),",","")),100),VALUE(SUBSTITUTE(INDEX('04A_국토부원자료'!$A:$T,ROW()+1,MATCH("계약일",'04A_국토부원자료'!$A$4:$T$4,0)),",",""))),""),"") | G12: =IFERROR(VALUE(SUBSTITUTE(INDEX('04A_국토부원자료'!$A:$T,ROW()+1,MATCH("거래금액(만원)",'04A_국토부원자료'!$A$4:$T$4,0)),",","")),"") | H12: =IF(G12="","",G12*10000) | I12: =IFERROR(IF(AND(H12>0,E12>0),H12/E12,""),"") | J12: =IFERROR(VALUE(SUBSTITUTE(INDEX('04A_국토부원자료'!$A:$T,ROW()+1,MATCH("층",'04A_국토부원자료'!$A$4:$T$4,0)),",","")),"") | K12: =IFERROR(VALUE(SUBSTITUTE(INDEX('04A_국토부원자료'!$A:$T,ROW()+1,MATCH("건축년도",'04A_국토부원자료'!$A$4:$T$4,0)),",","")),"") | L12: =IFERROR(INDEX('04A_국토부원자료'!$A:$T,ROW()+1,MATCH("도로명",'04A_국토부원자료'!$A$4:$T$4,0)),"") | M12: =IFERROR(INDEX('04A_국토부원자료'!$A:$T,ROW()+1,MATCH("거래유형",'04A_국토부원자료'!$A$4:$T$4,0)),"") | N12: =IF(B12="","",IF('02_대상물건입력'!B5="",1,IF(ISNUMBER(SEARCH('02_대상물건입력'!B5,B12)),1,0))) | O12: =IF(B12="","",IF('02_대상물건입력'!B6="",1,IF(ISNUMBER(SEARCH('02_대상물건입력'!B6,B12)),1,0))) | P12: =IF(L12="","",IF('02_대상물건입력'!B15="",0,IF(ISNUMBER(SEARCH('02_대상물건입력'!B15,L12)),1,0))) | Q12: =IF(OR(C12="",L12=""),0,IF(AND(TRIM(C12)=TRIM(RIGHT(SUBSTITUTE(TRIM('02_대상물건입력'!$B$7)," ",REPT(" ",99)),99)),IF('02_대상물건입력'!B15="",TRUE(),ISNUMBER(SEARCH('02_대상물건입력'!B15,L12)))),1,0)) | R12: =IFERROR(ABS(E12-'02_대상물건입력'!B11)/'02_대상물건입력'!B11,"") | S12: =IFERROR(ABS(J12-'02_대상물건입력'!B10),"") | T12: =IFERROR(ABS('01_설정'!B4-F12),"") | U12: =IFERROR(ABS(K12-YEAR('02_대상물건입력'!B14)),"") | V12: =IF(B12="","",IF(AND(E12>0,F12>0,H12>0,OR(IFERROR(INDEX('04A_국토부원자료'!$A:$T,ROW()+1,MATCH("해제사유발생일",'04A_국토부원자료'!$A$4:$T$4,0)),"")="",IFERROR(INDEX('04A_국토부원자료'!$A:$T,ROW()+1,MATCH("해제사유발생일",'04A_국토부원자료'!$A$4:$T$4,0)),"")="-"),IF('01_설정'!B10=1,N12=1,TRUE()),R12<='01_설정'!B5,S12<='01_설정'!B6,T12<='01_설정'!B7,U12<='01_설정'!B8),"Y","")) | W12: =IF(V12<>"Y","",MAX(0,(1-R12/'01_설정'!B5))*'01_설정'!B14+MAX(0,(1-S12/'01_설정'!B6))*'01_설정'!B15+MAX(0,(1-T12/'01_설정'!B7))*'01_설정'!B16+MAX(0,(1-U12/'01_설정'!B8))*'01_설정'!B17+O12*'01_설정'!B11+Q12*'01_설정'!B12+P12*'01_설정'!B13+IF(Z12="",0,Z12)) | X12: =IF(W12="","",1+COUNTIFS($W$4:$W$3003,">"&W12)+COUNTIFS($W$4:W12,W12)-1) | Y12: =IF(OR(I12="",'02_대상물건입력'!B19="",'02_대상물건입력'!B19<=0),"",ABS(I12-'02_대상물건입력'!B19)/'02_대상물건입력'!B19) | Z12: =IF(OR(Y12="",'01_설정'!B31="",'01_설정'!B31<=0,'01_설정'!B32="",'01_설정'!B32<=0),"",MAX(0,(1-Y12/'01_설정'!B32))*'01_설정'!B31)
A13: =IF(INDEX('04A_국토부원자료'!$A:$A,ROW()+1)="","",ROW()-3) | B13: =IFERROR(INDEX('04A_국토부원자료'!$A:$T,ROW()+1,MATCH("시군구",'04A_국토부원자료'!$A$4:$T$4,0)),"") | C13: =IF(B13="","",IFERROR(INDEX('04A_국토부원자료'!$A:$T,ROW()+1,MATCH("번지",'04A_국토부원자료'!$A$4:$T$4,0)),"")) | D13: =IF(B13="","",IF(Q13=1,'02_대상물건입력'!$B$8,IFERROR(INDEX('04A_국토부원자료'!$A:$T,ROW()+1,MATCH("단지명",'04A_국토부원자료'!$A$4:$T$4,0)),""))) | E13: =IFERROR(VALUE(SUBSTITUTE(INDEX('04A_국토부원자료'!$A:$T,ROW()+1,MATCH("전용면적(㎡)",'04A_국토부원자료'!$A$4:$T$4,0)),",","")),"") | F13: =IFERROR(IF(AND(INDEX('04A_국토부원자료'!$A:$T,ROW()+1,MATCH("계약년월",'04A_국토부원자료'!$A$4:$T$4,0))<>"",INDEX('04A_국토부원자료'!$A:$T,ROW()+1,MATCH("계약일",'04A_국토부원자료'!$A$4:$T$4,0))<>""),DATE(INT(VALUE(SUBSTITUTE(INDEX('04A_국토부원자료'!$A:$T,ROW()+1,MATCH("계약년월",'04A_국토부원자료'!$A$4:$T$4,0)),",",""))/100),MOD(VALUE(SUBSTITUTE(INDEX('04A_국토부원자료'!$A:$T,ROW()+1,MATCH("계약년월",'04A_국토부원자료'!$A$4:$T$4,0)),",","")),100),VALUE(SUBSTITUTE(INDEX('04A_국토부원자료'!$A:$T,ROW()+1,MATCH("계약일",'04A_국토부원자료'!$A$4:$T$4,0)),",",""))),""),"") | G13: =IFERROR(VALUE(SUBSTITUTE(INDEX('04A_국토부원자료'!$A:$T,ROW()+1,MATCH("거래금액(만원)",'04A_국토부원자료'!$A$4:$T$4,0)),",","")),"") | H13: =IF(G13="","",G13*10000) | I13: =IFERROR(IF(AND(H13>0,E13>0),H13/E13,""),"") | J13: =IFERROR(VALUE(SUBSTITUTE(INDEX('04A_국토부원자료'!$A:$T,ROW()+1,MATCH("층",'04A_국토부원자료'!$A$4:$T$4,0)),",","")),"") | K13: =IFERROR(VALUE(SUBSTITUTE(INDEX('04A_국토부원자료'!$A:$T,ROW()+1,MATCH("건축년도",'04A_국토부원자료'!$A$4:$T$4,0)),",","")),"") | L13: =IFERROR(INDEX('04A_국토부원자료'!$A:$T,ROW()+1,MATCH("도로명",'04A_국토부원자료'!$A$4:$T$4,0)),"") | M13: =IFERROR(INDEX('04A_국토부원자료'!$A:$T,ROW()+1,MATCH("거래유형",'04A_국토부원자료'!$A$4:$T$4,0)),"") | N13: =IF(B13="","",IF('02_대상물건입력'!B5="",1,IF(ISNUMBER(SEARCH('02_대상물건입력'!B5,B13)),1,0))) | O13: =IF(B13="","",IF('02_대상물건입력'!B6="",1,IF(ISNUMBER(SEARCH('02_대상물건입력'!B6,B13)),1,0))) | P13: =IF(L13="","",IF('02_대상물건입력'!B15="",0,IF(ISNUMBER(SEARCH('02_대상물건입력'!B15,L13)),1,0))) | Q13: =IF(OR(C13="",L13=""),0,IF(AND(TRIM(C13)=TRIM(RIGHT(SUBSTITUTE(TRIM('02_대상물건입력'!$B$7)," ",REPT(" ",99)),99)),IF('02_대상물건입력'!B15="",TRUE(),ISNUMBER(SEARCH('02_대상물건입력'!B15,L13)))),1,0)) | R13: =IFERROR(ABS(E13-'02_대상물건입력'!B11)/'02_대상물건입력'!B11,"") | S13: =IFERROR(ABS(J13-'02_대상물건입력'!B10),"") | T13: =IFERROR(ABS('01_설정'!B4-F13),"") | U13: =IFERROR(ABS(K13-YEAR('02_대상물건입력'!B14)),"") | V13: =IF(B13="","",IF(AND(E13>0,F13>0,H13>0,OR(IFERROR(INDEX('04A_국토부원자료'!$A:$T,ROW()+1,MATCH("해제사유발생일",'04A_국토부원자료'!$A$4:$T$4,0)),"")="",IFERROR(INDEX('04A_국토부원자료'!$A:$T,ROW()+1,MATCH("해제사유발생일",'04A_국토부원자료'!$A$4:$T$4,0)),"")="-"),IF('01_설정'!B10=1,N13=1,TRUE()),R13<='01_설정'!B5,S13<='01_설정'!B6,T13<='01_설정'!B7,U13<='01_설정'!B8),"Y","")) | W13: =IF(V13<>"Y","",MAX(0,(1-R13/'01_설정'!B5))*'01_설정'!B14+MAX(0,(1-S13/'01_설정'!B6))*'01_설정'!B15+MAX(0,(1-T13/'01_설정'!B7))*'01_설정'!B16+MAX(0,(1-U13/'01_설정'!B8))*'01_설정'!B17+O13*'01_설정'!B11+Q13*'01_설정'!B12+P13*'01_설정'!B13+IF(Z13="",0,Z13)) | X13: =IF(W13="","",1+COUNTIFS($W$4:$W$3003,">"&W13)+COUNTIFS($W$4:W13,W13)-1) | Y13: =IF(OR(I13="",'02_대상물건입력'!B19="",'02_대상물건입력'!B19<=0),"",ABS(I13-'02_대상물건입력'!B19)/'02_대상물건입력'!B19) | Z13: =IF(OR(Y13="",'01_설정'!B31="",'01_설정'!B31<=0,'01_설정'!B32="",'01_설정'!B32<=0),"",MAX(0,(1-Y13/'01_설정'!B32))*'01_설정'!B31)
A14: =IF(INDEX('04A_국토부원자료'!$A:$A,ROW()+1)="","",ROW()-3) | B14: =IFERROR(INDEX('04A_국토부원자료'!$A:$T,ROW()+1,MATCH("시군구",'04A_국토부원자료'!$A$4:$T$4,0)),"") | C14: =IF(B14="","",IFERROR(INDEX('04A_국토부원자료'!$A:$T,ROW()+1,MATCH("번지",'04A_국토부원자료'!$A$4:$T$4,0)),"")) | D14: =IF(B14="","",IF(Q14=1,'02_대상물건입력'!$B$8,IFERROR(INDEX('04A_국토부원자료'!$A:$T,ROW()+1,MATCH("단지명",'04A_국토부원자료'!$A$4:$T$4,0)),""))) | E14: =IFERROR(VALUE(SUBSTITUTE(INDEX('04A_국토부원자료'!$A:$T,ROW()+1,MATCH("전용면적(㎡)",'04A_국토부원자료'!$A$4:$T$4,0)),",","")),"") | F14: =IFERROR(IF(AND(INDEX('04A_국토부원자료'!$A:$T,ROW()+1,MATCH("계약년월",'04A_국토부원자료'!$A$4:$T$4,0))<>"",INDEX('04A_국토부원자료'!$A:$T,ROW()+1,MATCH("계약일",'04A_국토부원자료'!$A$4:$T$4,0))<>""),DATE(INT(VALUE(SUBSTITUTE(INDEX('04A_국토부원자료'!$A:$T,ROW()+1,MATCH("계약년월",'04A_국토부원자료'!$A$4:$T$4,0)),",",""))/100),MOD(VALUE(SUBSTITUTE(INDEX('04A_국토부원자료'!$A:$T,ROW()+1,MATCH("계약년월",'04A_국토부원자료'!$A$4:$T$4,0)),",","")),100),VALUE(SUBSTITUTE(INDEX('04A_국토부원자료'!$A:$T,ROW()+1,MATCH("계약일",'04A_국토부원자료'!$A$4:$T$4,0)),",",""))),""),"") | G14: =IFERROR(VALUE(SUBSTITUTE(INDEX('04A_국토부원자료'!$A:$T,ROW()+1,MATCH("거래금액(만원)",'04A_국토부원자료'!$A$4:$T$4,0)),",","")),"") | H14: =IF(G14="","",G14*10000) | I14: =IFERROR(IF(AND(H14>0,E14>0),H14/E14,""),"") | J14: =IFERROR(VALUE(SUBSTITUTE(INDEX('04A_국토부원자료'!$A:$T,ROW()+1,MATCH("층",'04A_국토부원자료'!$A$4:$T$4,0)),",","")),"") | K14: =IFERROR(VALUE(SUBSTITUTE(INDEX('04A_국토부원자료'!$A:$T,ROW()+1,MATCH("건축년도",'04A_국토부원자료'!$A$4:$T$4,0)),",","")),"") | L14: =IFERROR(INDEX('04A_국토부원자료'!$A:$T,ROW()+1,MATCH("도로명",'04A_국토부원자료'!$A$4:$T$4,0)),"") | M14: =IFERROR(INDEX('04A_국토부원자료'!$A:$T,ROW()+1,MATCH("거래유형",'04A_국토부원자료'!$A$4:$T$4,0)),"") | N14: =IF(B14="","",IF('02_대상물건입력'!B5="",1,IF(ISNUMBER(SEARCH('02_대상물건입력'!B5,B14)),1,0))) | O14: =IF(B14="","",IF('02_대상물건입력'!B6="",1,IF(ISNUMBER(SEARCH('02_대상물건입력'!B6,B14)),1,0))) | P14: =IF(L14="","",IF('02_대상물건입력'!B15="",0,IF(ISNUMBER(SEARCH('02_대상물건입력'!B15,L14)),1,0))) | Q14: =IF(OR(C14="",L14=""),0,IF(AND(TRIM(C14)=TRIM(RIGHT(SUBSTITUTE(TRIM('02_대상물건입력'!$B$7)," ",REPT(" ",99)),99)),IF('02_대상물건입력'!B15="",TRUE(),ISNUMBER(SEARCH('02_대상물건입력'!B15,L14)))),1,0)) | R14: =IFERROR(ABS(E14-'02_대상물건입력'!B11)/'02_대상물건입력'!B11,"") | S14: =IFERROR(ABS(J14-'02_대상물건입력'!B10),"") | T14: =IFERROR(ABS('01_설정'!B4-F14),"") | U14: =IFERROR(ABS(K14-YEAR('02_대상물건입력'!B14)),"") | V14: =IF(B14="","",IF(AND(E14>0,F14>0,H14>0,OR(IFERROR(INDEX('04A_국토부원자료'!$A:$T,ROW()+1,MATCH("해제사유발생일",'04A_국토부원자료'!$A$4:$T$4,0)),"")="",IFERROR(INDEX('04A_국토부원자료'!$A:$T,ROW()+1,MATCH("해제사유발생일",'04A_국토부원자료'!$A$4:$T$4,0)),"")="-"),IF('01_설정'!B10=1,N14=1,TRUE()),R14<='01_설정'!B5,S14<='01_설정'!B6,T14<='01_설정'!B7,U14<='01_설정'!B8),"Y","")) | W14: =IF(V14<>"Y","",MAX(0,(1-R14/'01_설정'!B5))*'01_설정'!B14+MAX(0,(1-S14/'01_설정'!B6))*'01_설정'!B15+MAX(0,(1-T14/'01_설정'!B7))*'01_설정'!B16+MAX(0,(1-U14/'01_설정'!B8))*'01_설정'!B17+O14*'01_설정'!B11+Q14*'01_설정'!B12+P14*'01_설정'!B13+IF(Z14="",0,Z14)) | X14: =IF(W14="","",1+COUNTIFS($W$4:$W$3003,">"&W14)+COUNTIFS($W$4:W14,W14)-1) | Y14: =IF(OR(I14="",'02_대상물건입력'!B19="",'02_대상물건입력'!B19<=0),"",ABS(I14-'02_대상물건입력'!B19)/'02_대상물건입력'!B19) | Z14: =IF(OR(Y14="",'01_설정'!B31="",'01_설정'!B31<=0,'01_설정'!B32="",'01_설정'!B32<=0),"",MAX(0,(1-Y14/'01_설정'!B32))*'01_설정'!B31)
A15: =IF(INDEX('04A_국토부원자료'!$A:$A,ROW()+1)="","",ROW()-3) | B15: =IFERROR(INDEX('04A_국토부원자료'!$A:$T,ROW()+1,MATCH("시군구",'04A_국토부원자료'!$A$4:$T$4,0)),"") | C15: =IF(B15="","",IFERROR(INDEX('04A_국토부원자료'!$A:$T,ROW()+1,MATCH("번지",'04A_국토부원자료'!$A$4:$T$4,0)),"")) | D15: =IF(B15="","",IF(Q15=1,'02_대상물건입력'!$B$8,IFERROR(INDEX('04A_국토부원자료'!$A:$T,ROW()+1,MATCH("단지명",'04A_국토부원자료'!$A$4:$T$4,0)),""))) | E15: =IFERROR(VALUE(SUBSTITUTE(INDEX('04A_국토부원자료'!$A:$T,ROW()+1,MATCH("전용면적(㎡)",'04A_국토부원자료'!$A$4:$T$4,0)),",","")),"") | F15: =IFERROR(IF(AND(INDEX('04A_국토부원자료'!$A:$T,ROW()+1,MATCH("계약년월",'04A_국토부원자료'!$A$4:$T$4,0))<>"",INDEX('04A_국토부원자료'!$A:$T,ROW()+1,MATCH("계약일",'04A_국토부원자료'!$A$4:$T$4,0))<>""),DATE(INT(VALUE(SUBSTITUTE(INDEX('04A_국토부원자료'!$A:$T,ROW()+1,MATCH("계약년월",'04A_국토부원자료'!$A$4:$T$4,0)),",",""))/100),MOD(VALUE(SUBSTITUTE(INDEX('04A_국토부원자료'!$A:$T,ROW()+1,MATCH("계약년월",'04A_국토부원자료'!$A$4:$T$4,0)),",","")),100),VALUE(SUBSTITUTE(INDEX('04A_국토부원자료'!$A:$T,ROW()+1,MATCH("계약일",'04A_국토부원자료'!$A$4:$T$4,0)),",",""))),""),"") | G15: =IFERROR(VALUE(SUBSTITUTE(INDEX('04A_국토부원자료'!$A:$T,ROW()+1,MATCH("거래금액(만원)",'04A_국토부원자료'!$A$4:$T$4,0)),",","")),"") | H15: =IF(G15="","",G15*10000) | I15: =IFERROR(IF(AND(H15>0,E15>0),H15/E15,""),"") | J15: =IFERROR(VALUE(SUBSTITUTE(INDEX('04A_국토부원자료'!$A:$T,ROW()+1,MATCH("층",'04A_국토부원자료'!$A$4:$T$4,0)),",","")),"") | K15: =IFERROR(VALUE(SUBSTITUTE(INDEX('04A_국토부원자료'!$A:$T,ROW()+1,MATCH("건축년도",'04A_국토부원자료'!$A$4:$T$4,0)),",","")),"") | L15: =IFERROR(INDEX('04A_국토부원자료'!$A:$T,ROW()+1,MATCH("도로명",'04A_국토부원자료'!$A$4:$T$4,0)),"") | M15: =IFERROR(INDEX('04A_국토부원자료'!$A:$T,ROW()+1,MATCH("거래유형",'04A_국토부원자료'!$A$4:$T$4,0)),"") | N15: =IF(B15="","",IF('02_대상물건입력'!B5="",1,IF(ISNUMBER(SEARCH('02_대상물건입력'!B5,B15)),1,0))) | O15: =IF(B15="","",IF('02_대상물건입력'!B6="",1,IF(ISNUMBER(SEARCH('02_대상물건입력'!B6,B15)),1,0))) | P15: =IF(L15="","",IF('02_대상물건입력'!B15="",0,IF(ISNUMBER(SEARCH('02_대상물건입력'!B15,L15)),1,0))) | Q15: =IF(OR(C15="",L15=""),0,IF(AND(TRIM(C15)=TRIM(RIGHT(SUBSTITUTE(TRIM('02_대상물건입력'!$B$7)," ",REPT(" ",99)),99)),IF('02_대상물건입력'!B15="",TRUE(),ISNUMBER(SEARCH('02_대상물건입력'!B15,L15)))),1,0)) | R15: =IFERROR(ABS(E15-'02_대상물건입력'!B11)/'02_대상물건입력'!B11,"") | S15: =IFERROR(ABS(J15-'02_대상물건입력'!B10),"") | T15: =IFERROR(ABS('01_설정'!B4-F15),"") | U15: =IFERROR(ABS(K15-YEAR('02_대상물건입력'!B14)),"") | V15: =IF(B15="","",IF(AND(E15>0,F15>0,H15>0,OR(IFERROR(INDEX('04A_국토부원자료'!$A:$T,ROW()+1,MATCH("해제사유발생일",'04A_국토부원자료'!$A$4:$T$4,0)),"")="",IFERROR(INDEX('04A_국토부원자료'!$A:$T,ROW()+1,MATCH("해제사유발생일",'04A_국토부원자료'!$A$4:$T$4,0)),"")="-"),IF('01_설정'!B10=1,N15=1,TRUE()),R15<='01_설정'!B5,S15<='01_설정'!B6,T15<='01_설정'!B7,U15<='01_설정'!B8),"Y","")) | W15: =IF(V15<>"Y","",MAX(0,(1-R15/'01_설정'!B5))*'01_설정'!B14+MAX(0,(1-S15/'01_설정'!B6))*'01_설정'!B15+MAX(0,(1-T15/'01_설정'!B7))*'01_설정'!B16+MAX(0,(1-U15/'01_설정'!B8))*'01_설정'!B17+O15*'01_설정'!B11+Q15*'01_설정'!B12+P15*'01_설정'!B13+IF(Z15="",0,Z15)) | X15: =IF(W15="","",1+COUNTIFS($W$4:$W$3003,">"&W15)+COUNTIFS($W$4:W15,W15)-1) | Y15: =IF(OR(I15="",'02_대상물건입력'!B19="",'02_대상물건입력'!B19<=0),"",ABS(I15-'02_대상물건입력'!B19)/'02_대상물건입력'!B19) | Z15: =IF(OR(Y15="",'01_설정'!B31="",'01_설정'!B31<=0,'01_설정'!B32="",'01_설정'!B32<=0),"",MAX(0,(1-Y15/'01_설정'!B32))*'01_설정'!B31)
A16: =IF(INDEX('04A_국토부원자료'!$A:$A,ROW()+1)="","",ROW()-3) | B16: =IFERROR(INDEX('04A_국토부원자료'!$A:$T,ROW()+1,MATCH("시군구",'04A_국토부원자료'!$A$4:$T$4,0)),"") | C16: =IF(B16="","",IFERROR(INDEX('04A_국토부원자료'!$A:$T,ROW()+1,MATCH("번지",'04A_국토부원자료'!$A$4:$T$4,0)),"")) | D16: =IF(B16="","",IF(Q16=1,'02_대상물건입력'!$B$8,IFERROR(INDEX('04A_국토부원자료'!$A:$T,ROW()+1,MATCH("단지명",'04A_국토부원자료'!$A$4:$T$4,0)),""))) | E16: =IFERROR(VALUE(SUBSTITUTE(INDEX('04A_국토부원자료'!$A:$T,ROW()+1,MATCH("전용면적(㎡)",'04A_국토부원자료'!$A$4:$T$4,0)),",","")),"") | F16: =IFERROR(IF(AND(INDEX('04A_국토부원자료'!$A:$T,ROW()+1,MATCH("계약년월",'04A_국토부원자료'!$A$4:$T$4,0))<>"",INDEX('04A_국토부원자료'!$A:$T,ROW()+1,MATCH("계약일",'04A_국토부원자료'!$A$4:$T$4,0))<>""),DATE(INT(VALUE(SUBSTITUTE(INDEX('04A_국토부원자료'!$A:$T,ROW()+1,MATCH("계약년월",'04A_국토부원자료'!$A$4:$T$4,0)),",",""))/100),MOD(VALUE(SUBSTITUTE(INDEX('04A_국토부원자료'!$A:$T,ROW()+1,MATCH("계약년월",'04A_국토부원자료'!$A$4:$T$4,0)),",","")),100),VALUE(SUBSTITUTE(INDEX('04A_국토부원자료'!$A:$T,ROW()+1,MATCH("계약일",'04A_국토부원자료'!$A$4:$T$4,0)),",",""))),""),"") | G16: =IFERROR(VALUE(SUBSTITUTE(INDEX('04A_국토부원자료'!$A:$T,ROW()+1,MATCH("거래금액(만원)",'04A_국토부원자료'!$A$4:$T$4,0)),",","")),"") | H16: =IF(G16="","",G16*10000) | I16: =IFERROR(IF(AND(H16>0,E16>0),H16/E16,""),"") | J16: =IFERROR(VALUE(SUBSTITUTE(INDEX('04A_국토부원자료'!$A:$T,ROW()+1,MATCH("층",'04A_국토부원자료'!$A$4:$T$4,0)),",","")),"") | K16: =IFERROR(VALUE(SUBSTITUTE(INDEX('04A_국토부원자료'!$A:$T,ROW()+1,MATCH("건축년도",'04A_국토부원자료'!$A$4:$T$4,0)),",","")),"") | L16: =IFERROR(INDEX('04A_국토부원자료'!$A:$T,ROW()+1,MATCH("도로명",'04A_국토부원자료'!$A$4:$T$4,0)),"") | M16: =IFERROR(INDEX('04A_국토부원자료'!$A:$T,ROW()+1,MATCH("거래유형",'04A_국토부원자료'!$A$4:$T$4,0)),"") | N16: =IF(B16="","",IF('02_대상물건입력'!B5="",1,IF(ISNUMBER(SEARCH('02_대상물건입력'!B5,B16)),1,0))) | O16: =IF(B16="","",IF('02_대상물건입력'!B6="",1,IF(ISNUMBER(SEARCH('02_대상물건입력'!B6,B16)),1,0))) | P16: =IF(L16="","",IF('02_대상물건입력'!B15="",0,IF(ISNUMBER(SEARCH('02_대상물건입력'!B15,L16)),1,0))) | Q16: =IF(OR(C16="",L16=""),0,IF(AND(TRIM(C16)=TRIM(RIGHT(SUBSTITUTE(TRIM('02_대상물건입력'!$B$7)," ",REPT(" ",99)),99)),IF('02_대상물건입력'!B15="",TRUE(),ISNUMBER(SEARCH('02_대상물건입력'!B15,L16)))),1,0)) | R16: =IFERROR(ABS(E16-'02_대상물건입력'!B11)/'02_대상물건입력'!B11,"") | S16: =IFERROR(ABS(J16-'02_대상물건입력'!B10),"") | T16: =IFERROR(ABS('01_설정'!B4-F16),"") | U16: =IFERROR(ABS(K16-YEAR('02_대상물건입력'!B14)),"") | V16: =IF(B16="","",IF(AND(E16>0,F16>0,H16>0,OR(IFERROR(INDEX('04A_국토부원자료'!$A:$T,ROW()+1,MATCH("해제사유발생일",'04A_국토부원자료'!$A$4:$T$4,0)),"")="",IFERROR(INDEX('04A_국토부원자료'!$A:$T,ROW()+1,MATCH("해제사유발생일",'04A_국토부원자료'!$A$4:$T$4,0)),"")="-"),IF('01_설정'!B10=1,N16=1,TRUE()),R16<='01_설정'!B5,S16<='01_설정'!B6,T16<='01_설정'!B7,U16<='01_설정'!B8),"Y","")) | W16: =IF(V16<>"Y","",MAX(0,(1-R16/'01_설정'!B5))*'01_설정'!B14+MAX(0,(1-S16/'01_설정'!B6))*'01_설정'!B15+MAX(0,(1-T16/'01_설정'!B7))*'01_설정'!B16+MAX(0,(1-U16/'01_설정'!B8))*'01_설정'!B17+O16*'01_설정'!B11+Q16*'01_설정'!B12+P16*'01_설정'!B13+IF(Z16="",0,Z16)) | X16: =IF(W16="","",1+COUNTIFS($W$4:$W$3003,">"&W16)+COUNTIFS($W$4:W16,W16)-1) | Y16: =IF(OR(I16="",'02_대상물건입력'!B19="",'02_대상물건입력'!B19<=0),"",ABS(I16-'02_대상물건입력'!B19)/'02_대상물건입력'!B19) | Z16: =IF(OR(Y16="",'01_설정'!B31="",'01_설정'!B31<=0,'01_설정'!B32="",'01_설정'!B32<=0),"",MAX(0,(1-Y16/'01_설정'!B32))*'01_설정'!B31)
A17: =IF(INDEX('04A_국토부원자료'!$A:$A,ROW()+1)="","",ROW()-3) | B17: =IFERROR(INDEX('04A_국토부원자료'!$A:$T,ROW()+1,MATCH("시군구",'04A_국토부원자료'!$A$4:$T$4,0)),"") | C17: =IF(B17="","",IFERROR(INDEX('04A_국토부원자료'!$A:$T,ROW()+1,MATCH("번지",'04A_국토부원자료'!$A$4:$T$4,0)),"")) | D17: =IF(B17="","",IF(Q17=1,'02_대상물건입력'!$B$8,IFERROR(INDEX('04A_국토부원자료'!$A:$T,ROW()+1,MATCH("단지명",'04A_국토부원자료'!$A$4:$T$4,0)),""))) | E17: =IFERROR(VALUE(SUBSTITUTE(INDEX('04A_국토부원자료'!$A:$T,ROW()+1,MATCH("전용면적(㎡)",'04A_국토부원자료'!$A$4:$T$4,0)),",","")),"") | F17: =IFERROR(IF(AND(INDEX('04A_국토부원자료'!$A:$T,ROW()+1,MATCH("계약년월",'04A_국토부원자료'!$A$4:$T$4,0))<>"",INDEX('04A_국토부원자료'!$A:$T,ROW()+1,MATCH("계약일",'04A_국토부원자료'!$A$4:$T$4,0))<>""),DATE(INT(VALUE(SUBSTITUTE(INDEX('04A_국토부원자료'!$A:$T,ROW()+1,MATCH("계약년월",'04A_국토부원자료'!$A$4:$T$4,0)),",",""))/100),MOD(VALUE(SUBSTITUTE(INDEX('04A_국토부원자료'!$A:$T,ROW()+1,MATCH("계약년월",'04A_국토부원자료'!$A$4:$T$4,0)),",","")),100),VALUE(SUBSTITUTE(INDEX('04A_국토부원자료'!$A:$T,ROW()+1,MATCH("계약일",'04A_국토부원자료'!$A$4:$T$4,0)),",",""))),""),"") | G17: =IFERROR(VALUE(SUBSTITUTE(INDEX('04A_국토부원자료'!$A:$T,ROW()+1,MATCH("거래금액(만원)",'04A_국토부원자료'!$A$4:$T$4,0)),",","")),"") | H17: =IF(G17="","",G17*10000) | I17: =IFERROR(IF(AND(H17>0,E17>0),H17/E17,""),"") | J17: =IFERROR(VALUE(SUBSTITUTE(INDEX('04A_국토부원자료'!$A:$T,ROW()+1,MATCH("층",'04A_국토부원자료'!$A$4:$T$4,0)),",","")),"") | K17: =IFERROR(VALUE(SUBSTITUTE(INDEX('04A_국토부원자료'!$A:$T,ROW()+1,MATCH("건축년도",'04A_국토부원자료'!$A$4:$T$4,0)),",","")),"") | L17: =IFERROR(INDEX('04A_국토부원자료'!$A:$T,ROW()+1,MATCH("도로명",'04A_국토부원자료'!$A$4:$T$4,0)),"") | M17: =IFERROR(INDEX('04A_국토부원자료'!$A:$T,ROW()+1,MATCH("거래유형",'04A_국토부원자료'!$A$4:$T$4,0)),"") | N17: =IF(B17="","",IF('02_대상물건입력'!B5="",1,IF(ISNUMBER(SEARCH('02_대상물건입력'!B5,B17)),1,0))) | O17: =IF(B17="","",IF('02_대상물건입력'!B6="",1,IF(ISNUMBER(SEARCH('02_대상물건입력'!B6,B17)),1,0))) | P17: =IF(L17="","",IF('02_대상물건입력'!B15="",0,IF(ISNUMBER(SEARCH('02_대상물건입력'!B15,L17)),1,0))) | Q17: =IF(OR(C17="",L17=""),0,IF(AND(TRIM(C17)=TRIM(RIGHT(SUBSTITUTE(TRIM('02_대상물건입력'!$B$7)," ",REPT(" ",99)),99)),IF('02_대상물건입력'!B15="",TRUE(),ISNUMBER(SEARCH('02_대상물건입력'!B15,L17)))),1,0)) | R17: =IFERROR(ABS(E17-'02_대상물건입력'!B11)/'02_대상물건입력'!B11,"") | S17: =IFERROR(ABS(J17-'02_대상물건입력'!B10),"") | T17: =IFERROR(ABS('01_설정'!B4-F17),"") | U17: =IFERROR(ABS(K17-YEAR('02_대상물건입력'!B14)),"") | V17: =IF(B17="","",IF(AND(E17>0,F17>0,H17>0,OR(IFERROR(INDEX('04A_국토부원자료'!$A:$T,ROW()+1,MATCH("해제사유발생일",'04A_국토부원자료'!$A$4:$T$4,0)),"")="",IFERROR(INDEX('04A_국토부원자료'!$A:$T,ROW()+1,MATCH("해제사유발생일",'04A_국토부원자료'!$A$4:$T$4,0)),"")="-"),IF('01_설정'!B10=1,N17=1,TRUE()),R17<='01_설정'!B5,S17<='01_설정'!B6,T17<='01_설정'!B7,U17<='01_설정'!B8),"Y","")) | W17: =IF(V17<>"Y","",MAX(0,(1-R17/'01_설정'!B5))*'01_설정'!B14+MAX(0,(1-S17/'01_설정'!B6))*'01_설정'!B15+MAX(0,(1-T17/'01_설정'!B7))*'01_설정'!B16+MAX(0,(1-U17/'01_설정'!B8))*'01_설정'!B17+O17*'01_설정'!B11+Q17*'01_설정'!B12+P17*'01_설정'!B13+IF(Z17="",0,Z17)) | X17: =IF(W17="","",1+COUNTIFS($W$4:$W$3003,">"&W17)+COUNTIFS($W$4:W17,W17)-1) | Y17: =IF(OR(I17="",'02_대상물건입력'!B19="",'02_대상물건입력'!B19<=0),"",ABS(I17-'02_대상물건입력'!B19)/'02_대상물건입력'!B19) | Z17: =IF(OR(Y17="",'01_설정'!B31="",'01_설정'!B31<=0,'01_설정'!B32="",'01_설정'!B32<=0),"",MAX(0,(1-Y17/'01_설정'!B32))*'01_설정'!B31)
A18: =IF(INDEX('04A_국토부원자료'!$A:$A,ROW()+1)="","",ROW()-3) | B18: =IFERROR(INDEX('04A_국토부원자료'!$A:$T,ROW()+1,MATCH("시군구",'04A_국토부원자료'!$A$4:$T$4,0)),"") | C18: =IF(B18="","",IFERROR(INDEX('04A_국토부원자료'!$A:$T,ROW()+1,MATCH("번지",'04A_국토부원자료'!$A$4:$T$4,0)),"")) | D18: =IF(B18="","",IF(Q18=1,'02_대상물건입력'!$B$8,IFERROR(INDEX('04A_국토부원자료'!$A:$T,ROW()+1,MATCH("단지명",'04A_국토부원자료'!$A$4:$T$4,0)),""))) | E18: =IFERROR(VALUE(SUBSTITUTE(INDEX('04A_국토부원자료'!$A:$T,ROW()+1,MATCH("전용면적(㎡)",'04A_국토부원자료'!$A$4:$T$4,0)),",","")),"") | F18: =IFERROR(IF(AND(INDEX('04A_국토부원자료'!$A:$T,ROW()+1,MATCH("계약년월",'04A_국토부원자료'!$A$4:$T$4,0))<>"",INDEX('04A_국토부원자료'!$A:$T,ROW()+1,MATCH("계약일",'04A_국토부원자료'!$A$4:$T$4,0))<>""),DATE(INT(VALUE(SUBSTITUTE(INDEX('04A_국토부원자료'!$A:$T,ROW()+1,MATCH("계약년월",'04A_국토부원자료'!$A$4:$T$4,0)),",",""))/100),MOD(VALUE(SUBSTITUTE(INDEX('04A_국토부원자료'!$A:$T,ROW()+1,MATCH("계약년월",'04A_국토부원자료'!$A$4:$T$4,0)),",","")),100),VALUE(SUBSTITUTE(INDEX('04A_국토부원자료'!$A:$T,ROW()+1,MATCH("계약일",'04A_국토부원자료'!$A$4:$T$4,0)),",",""))),""),"") | G18: =IFERROR(VALUE(SUBSTITUTE(INDEX('04A_국토부원자료'!$A:$T,ROW()+1,MATCH("거래금액(만원)",'04A_국토부원자료'!$A$4:$T$4,0)),",","")),"") | H18: =IF(G18="","",G18*10000) | I18: =IFERROR(IF(AND(H18>0,E18>0),H18/E18,""),"") | J18: =IFERROR(VALUE(SUBSTITUTE(INDEX('04A_국토부원자료'!$A:$T,ROW()+1,MATCH("층",'04A_국토부원자료'!$A$4:$T$4,0)),",","")),"") | K18: =IFERROR(VALUE(SUBSTITUTE(INDEX('04A_국토부원자료'!$A:$T,ROW()+1,MATCH("건축년도",'04A_국토부원자료'!$A$4:$T$4,0)),",","")),"") | L18: =IFERROR(INDEX('04A_국토부원자료'!$A:$T,ROW()+1,MATCH("도로명",'04A_국토부원자료'!$A$4:$T$4,0)),"") | M18: =IFERROR(INDEX('04A_국토부원자료'!$A:$T,ROW()+1,MATCH("거래유형",'04A_국토부원자료'!$A$4:$T$4,0)),"") | N18: =IF(B18="","",IF('02_대상물건입력'!B5="",1,IF(ISNUMBER(SEARCH('02_대상물건입력'!B5,B18)),1,0))) | O18: =IF(B18="","",IF('02_대상물건입력'!B6="",1,IF(ISNUMBER(SEARCH('02_대상물건입력'!B6,B18)),1,0))) | P18: =IF(L18="","",IF('02_대상물건입력'!B15="",0,IF(ISNUMBER(SEARCH('02_대상물건입력'!B15,L18)),1,0))) | Q18: =IF(OR(C18="",L18=""),0,IF(AND(TRIM(C18)=TRIM(RIGHT(SUBSTITUTE(TRIM('02_대상물건입력'!$B$7)," ",REPT(" ",99)),99)),IF('02_대상물건입력'!B15="",TRUE(),ISNUMBER(SEARCH('02_대상물건입력'!B15,L18)))),1,0)) | R18: =IFERROR(ABS(E18-'02_대상물건입력'!B11)/'02_대상물건입력'!B11,"") | S18: =IFERROR(ABS(J18-'02_대상물건입력'!B10),"") | T18: =IFERROR(ABS('01_설정'!B4-F18),"") | U18: =IFERROR(ABS(K18-YEAR('02_대상물건입력'!B14)),"") | V18: =IF(B18="","",IF(AND(E18>0,F18>0,H18>0,OR(IFERROR(INDEX('04A_국토부원자료'!$A:$T,ROW()+1,MATCH("해제사유발생일",'04A_국토부원자료'!$A$4:$T$4,0)),"")="",IFERROR(INDEX('04A_국토부원자료'!$A:$T,ROW()+1,MATCH("해제사유발생일",'04A_국토부원자료'!$A$4:$T$4,0)),"")="-"),IF('01_설정'!B10=1,N18=1,TRUE()),R18<='01_설정'!B5,S18<='01_설정'!B6,T18<='01_설정'!B7,U18<='01_설정'!B8),"Y","")) | W18: =IF(V18<>"Y","",MAX(0,(1-R18/'01_설정'!B5))*'01_설정'!B14+MAX(0,(1-S18/'01_설정'!B6))*'01_설정'!B15+MAX(0,(1-T18/'01_설정'!B7))*'01_설정'!B16+MAX(0,(1-U18/'01_설정'!B8))*'01_설정'!B17+O18*'01_설정'!B11+Q18*'01_설정'!B12+P18*'01_설정'!B13+IF(Z18="",0,Z18)) | X18: =IF(W18="","",1+COUNTIFS($W$4:$W$3003,">"&W18)+COUNTIFS($W$4:W18,W18)-1) | Y18: =IF(OR(I18="",'02_대상물건입력'!B19="",'02_대상물건입력'!B19<=0),"",ABS(I18-'02_대상물건입력'!B19)/'02_대상물건입력'!B19) | Z18: =IF(OR(Y18="",'01_설정'!B31="",'01_설정'!B31<=0,'01_설정'!B32="",'01_설정'!B32<=0),"",MAX(0,(1-Y18/'01_설정'!B32))*'01_설정'!B31)
A19: =IF(INDEX('04A_국토부원자료'!$A:$A,ROW()+1)="","",ROW()-3) | B19: =IFERROR(INDEX('04A_국토부원자료'!$A:$T,ROW()+1,MATCH("시군구",'04A_국토부원자료'!$A$4:$T$4,0)),"") | C19: =IF(B19="","",IFERROR(INDEX('04A_국토부원자료'!$A:$T,ROW()+1,MATCH("번지",'04A_국토부원자료'!$A$4:$T$4,0)),"")) | D19: =IF(B19="","",IF(Q19=1,'02_대상물건입력'!$B$8,IFERROR(INDEX('04A_국토부원자료'!$A:$T,ROW()+1,MATCH("단지명",'04A_국토부원자료'!$A$4:$T$4,0)),""))) | E19: =IFERROR(VALUE(SUBSTITUTE(INDEX('04A_국토부원자료'!$A:$T,ROW()+1,MATCH("전용면적(㎡)",'04A_국토부원자료'!$A$4:$T$4,0)),",","")),"") | F19: =IFERROR(IF(AND(INDEX('04A_국토부원자료'!$A:$T,ROW()+1,MATCH("계약년월",'04A_국토부원자료'!$A$4:$T$4,0))<>"",INDEX('04A_국토부원자료'!$A:$T,ROW()+1,MATCH("계약일",'04A_국토부원자료'!$A$4:$T$4,0))<>""),DATE(INT(VALUE(SUBSTITUTE(INDEX('04A_국토부원자료'!$A:$T,ROW()+1,MATCH("계약년월",'04A_국토부원자료'!$A$4:$T$4,0)),",",""))/100),MOD(VALUE(SUBSTITUTE(INDEX('04A_국토부원자료'!$A:$T,ROW()+1,MATCH("계약년월",'04A_국토부원자료'!$A$4:$T$4,0)),",","")),100),VALUE(SUBSTITUTE(INDEX('04A_국토부원자료'!$A:$T,ROW()+1,MATCH("계약일",'04A_국토부원자료'!$A$4:$T$4,0)),",",""))),""),"") | G19: =IFERROR(VALUE(SUBSTITUTE(INDEX('04A_국토부원자료'!$A:$T,ROW()+1,MATCH("거래금액(만원)",'04A_국토부원자료'!$A$4:$T$4,0)),",","")),"") | H19: =IF(G19="","",G19*10000) | I19: =IFERROR(IF(AND(H19>0,E19>0),H19/E19,""),"") | J19: =IFERROR(VALUE(SUBSTITUTE(INDEX('04A_국토부원자료'!$A:$T,ROW()+1,MATCH("층",'04A_국토부원자료'!$A$4:$T$4,0)),",","")),"") | K19: =IFERROR(VALUE(SUBSTITUTE(INDEX('04A_국토부원자료'!$A:$T,ROW()+1,MATCH("건축년도",'04A_국토부원자료'!$A$4:$T$4,0)),",","")),"") | L19: =IFERROR(INDEX('04A_국토부원자료'!$A:$T,ROW()+1,MATCH("도로명",'04A_국토부원자료'!$A$4:$T$4,0)),"") | M19: =IFERROR(INDEX('04A_국토부원자료'!$A:$T,ROW()+1,MATCH("거래유형",'04A_국토부원자료'!$A$4:$T$4,0)),"") | N19: =IF(B19="","",IF('02_대상물건입력'!B5="",1,IF(ISNUMBER(SEARCH('02_대상물건입력'!B5,B19)),1,0))) | O19: =IF(B19="","",IF('02_대상물건입력'!B6="",1,IF(ISNUMBER(SEARCH('02_대상물건입력'!B6,B19)),1,0))) | P19: =IF(L19="","",IF('02_대상물건입력'!B15="",0,IF(ISNUMBER(SEARCH('02_대상물건입력'!B15,L19)),1,0))) | Q19: =IF(OR(C19="",L19=""),0,IF(AND(TRIM(C19)=TRIM(RIGHT(SUBSTITUTE(TRIM('02_대상물건입력'!$B$7)," ",REPT(" ",99)),99)),IF('02_대상물건입력'!B15="",TRUE(),ISNUMBER(SEARCH('02_대상물건입력'!B15,L19)))),1,0)) | R19: =IFERROR(ABS(E19-'02_대상물건입력'!B11)/'02_대상물건입력'!B11,"") | S19: =IFERROR(ABS(J19-'02_대상물건입력'!B10),"") | T19: =IFERROR(ABS('01_설정'!B4-F19),"") | U19: =IFERROR(ABS(K19-YEAR('02_대상물건입력'!B14)),"") | V19: =IF(B19="","",IF(AND(E19>0,F19>0,H19>0,OR(IFERROR(INDEX('04A_국토부원자료'!$A:$T,ROW()+1,MATCH("해제사유발생일",'04A_국토부원자료'!$A$4:$T$4,0)),"")="",IFERROR(INDEX('04A_국토부원자료'!$A:$T,ROW()+1,MATCH("해제사유발생일",'04A_국토부원자료'!$A$4:$T$4,0)),"")="-"),IF('01_설정'!B10=1,N19=1,TRUE()),R19<='01_설정'!B5,S19<='01_설정'!B6,T19<='01_설정'!B7,U19<='01_설정'!B8),"Y","")) | W19: =IF(V19<>"Y","",MAX(0,(1-R19/'01_설정'!B5))*'01_설정'!B14+MAX(0,(1-S19/'01_설정'!B6))*'01_설정'!B15+MAX(0,(1-T19/'01_설정'!B7))*'01_설정'!B16+MAX(0,(1-U19/'01_설정'!B8))*'01_설정'!B17+O19*'01_설정'!B11+Q19*'01_설정'!B12+P19*'01_설정'!B13+IF(Z19="",0,Z19)) | X19: =IF(W19="","",1+COUNTIFS($W$4:$W$3003,">"&W19)+COUNTIFS($W$4:W19,W19)-1) | Y19: =IF(OR(I19="",'02_대상물건입력'!B19="",'02_대상물건입력'!B19<=0),"",ABS(I19-'02_대상물건입력'!B19)/'02_대상물건입력'!B19) | Z19: =IF(OR(Y19="",'01_설정'!B31="",'01_설정'!B31<=0,'01_설정'!B32="",'01_설정'!B32<=0),"",MAX(0,(1-Y19/'01_설정'!B32))*'01_설정'!B31)
